Process A [NEW] (arrival time 9 ms) 16 CPU bursts
Process B [NEW] (arrival time 18 ms) 21 CPU bursts
Process C [NEW] (arrival time 42 ms) 4 CPU bursts
Process D [NEW] (arrival time 156 ms) 11 CPU bursts
Process E [NEW] (arrival time 134 ms) 55 CPU bursts
Process F [NEW] (arrival time 106 ms) 34 CPU bursts
Process G [NEW] (arrival time 65 ms) 80 CPU bursts
Process H [NEW] (arrival time 11 ms) 83 CPU bursts
Process I [NEW] (arrival time 68 ms) 77 CPU bursts
Process J [NEW] (arrival time 0 ms) 10 CPU bursts
Process K [NEW] (arrival time 7 ms) 13 CPU bursts
Process L [NEW] (arrival time 189 ms) 7 CPU bursts
Process M [NEW] (arrival time 16 ms) 48 CPU bursts
Process N [NEW] (arrival time 122 ms) 31 CPU bursts
Process O [NEW] (arrival time 29 ms) 31 CPU bursts
Process P [NEW] (arrival time 159 ms) 16 CPU bursts
time 0ms: Simulator started for RR [Q <empty>]
time 0ms: Process J arrived; added to ready queue [Q J]
time 2ms: Process J started using the CPU for 40ms burst [Q <empty>]
time 7ms: Process K arrived; added to ready queue [Q K]
time 9ms: Process A arrived; added to ready queue [Q K A]
time 11ms: Process H arrived; added to ready queue [Q K A H]
time 16ms: Process M arrived; added to ready queue [Q K A H M]
time 18ms: Process B arrived; added to ready queue [Q K A H M B]
time 29ms: Process O arrived; added to ready queue [Q K A H M B O]
time 42ms: Process J completed a CPU burst; 9 bursts to go [Q K A H M B O]
time 42ms: Process J switching out of CPU; will block on I/O until time 47ms [Q K A H M B O]
time 42ms: Process C arrived; added to ready queue [Q K A H M B O C]
time 46ms: Process K started using the CPU for 64ms burst [Q A H M B O C]
time 47ms: Process J completed I/O; added to ready queue [Q A H M B O C J]
time 65ms: Process G arrived; added to ready queue [Q A H M B O C J G]
time 68ms: Process I arrived; added to ready queue [Q A H M B O C J G I]
time 106ms: Process F arrived; added to ready queue [Q A H M B O C J G I F]
time 110ms: Process K completed a CPU burst; 12 bursts to go [Q A H M B O C J G I F]
time 110ms: Process K switching out of CPU; will block on I/O until time 208ms [Q A H M B O C J G I F]
time 114ms: Process A started using the CPU for 56ms burst [Q H M B O C J G I F]
time 122ms: Process N arrived; added to ready queue [Q H M B O C J G I F N]
time 134ms: Process E arrived; added to ready queue [Q H M B O C J G I F N E]
time 156ms: Process D arrived; added to ready queue [Q H M B O C J G I F N E D]
time 159ms: Process P arrived; added to ready queue [Q H M B O C J G I F N E D P]
time 170ms: Process A completed a CPU burst; 15 bursts to go [Q H M B O C J G I F N E D P]
time 170ms: Process A switching out of CPU; will block on I/O until time 195ms [Q H M B O C J G I F N E D P]
time 174ms: Process H started using the CPU for 96ms burst [Q M B O C J G I F N E D P]
time 189ms: Process L arrived; added to ready queue [Q M B O C J G I F N E D P L]
time 195ms: Process A completed I/O; added to ready queue [Q M B O C J G I F N E D P L A]
time 208ms: Process K completed I/O; added to ready queue [Q M B O C J G I F N E D P L A K]
time 270ms: Process H completed a CPU burst; 82 bursts to go [Q M B O C J G I F N E D P L A K]
time 270ms: Process H switching out of CPU; will block on I/O until time 339ms [Q M B O C J G I F N E D P L A K]
time 274ms: Process M started using the CPU for 22ms burst [Q B O C J G I F N E D P L A K]
time 296ms: Process M completed a CPU burst; 47 bursts to go [Q B O C J G I F N E D P L A K]
time 296ms: Process M switching out of CPU; will block on I/O until time 315ms [Q B O C J G I F N E D P L A K]
time 300ms: Process B started using the CPU for 106ms burst [Q O C J G I F N E D P L A K]
time 315ms: Process M completed I/O; added to ready queue [Q O C J G I F N E D P L A K M]
time 339ms: Process H completed I/O; added to ready queue [Q O C J G I F N E D P L A K M H]
time 406ms: Process B completed a CPU burst; 20 bursts to go [Q O C J G I F N E D P L A K M H]
time 406ms: Process B switching out of CPU; will block on I/O until time 564ms [Q O C J G I F N E D P L A K M H]
time 410ms: Process O started using the CPU for 156ms burst [Q C J G I F N E D P L A K M H]
time 538ms: Time slice expired; process O preempted with 28ms to go [Q C J G I F N E D P L A K M H]
time 542ms: Process C started using the CPU for 94ms burst [Q J G I F N E D P L A K M H O]
time 564ms: Process B completed I/O; added to ready queue [Q J G I F N E D P L A K M H O B]
time 636ms: Process C completed a CPU burst; 3 bursts to go [Q J G I F N E D P L A K M H O B]
time 636ms: Process C switching out of CPU; will block on I/O until time 796ms [Q J G I F N E D P L A K M H O B]
time 640ms: Process J started using the CPU for 204ms burst [Q G I F N E D P L A K M H O B]
time 768ms: Time slice expired; process J preempted with 76ms to go [Q G I F N E D P L A K M H O B]
time 772ms: Process G started using the CPU for 70ms burst [Q I F N E D P L A K M H O B J]
time 796ms: Process C completed I/O; added to ready queue [Q I F N E D P L A K M H O B J C]
time 842ms: Process G completed a CPU burst; 79 bursts to go [Q I F N E D P L A K M H O B J C]
time 842ms: Process G switching out of CPU; will block on I/O until time 875ms [Q I F N E D P L A K M H O B J C]
time 846ms: Process I started using the CPU for 220ms burst [Q F N E D P L A K M H O B J C]
time 875ms: Process G completed I/O; added to ready queue [Q F N E D P L A K M H O B J C G]
time 974ms: Time slice expired; process I preempted with 92ms to go [Q F N E D P L A K M H O B J C G]
time 978ms: Process F started using the CPU for 129ms burst [Q N E D P L A K M H O B J C G I]
time 1106ms: Time slice expired; process F preempted with 1ms to go [Q N E D P L A K M H O B J C G I]
time 1110ms: Process N started using the CPU for 213ms burst [Q E D P L A K M H O B J C G I F]
time 1238ms: Time slice expired; process N preempted with 85ms to go [Q E D P L A K M H O B J C G I F]
time 1242ms: Process E started using the CPU for 152ms burst [Q D P L A K M H O B J C G I F N]
time 1370ms: Time slice expired; process E preempted with 24ms to go [Q D P L A K M H O B J C G I F N]
time 1374ms: Process D started using the CPU for 148ms burst [Q P L A K M H O B J C G I F N E]
time 1502ms: Time slice expired; process D preempted with 20ms to go [Q P L A K M H O B J C G I F N E]
time 1506ms: Process P started using the CPU for 4ms burst [Q L A K M H O B J C G I F N E D]
time 1510ms: Process P completed a CPU burst; 15 bursts to go [Q L A K M H O B J C G I F N E D]
time 1510ms: Process P switching out of CPU; will block on I/O until time 1697ms [Q L A K M H O B J C G I F N E D]
time 1514ms: Process L started using the CPU for 135ms burst [Q A K M H O B J C G I F N E D]
time 1642ms: Time slice expired; process L preempted with 7ms to go [Q A K M H O B J C G I F N E D]
time 1646ms: Process A started using the CPU for 60ms burst [Q K M H O B J C G I F N E D L]
time 1697ms: Process P completed I/O; added to ready queue [Q K M H O B J C G I F N E D L P]
time 1706ms: Process A completed a CPU burst; 14 bursts to go [Q K M H O B J C G I F N E D L P]
time 1706ms: Process A switching out of CPU; will block on I/O until time 1861ms [Q K M H O B J C G I F N E D L P]
time 1710ms: Process K started using the CPU for 56ms burst [Q M H O B J C G I F N E D L P]
time 1766ms: Process K completed a CPU burst; 11 bursts to go [Q M H O B J C G I F N E D L P]
time 1766ms: Process K switching out of CPU; will block on I/O until time 1841ms [Q M H O B J C G I F N E D L P]
time 1770ms: Process M started using the CPU for 93ms burst [Q H O B J C G I F N E D L P]
time 1841ms: Process K completed I/O; added to ready queue [Q H O B J C G I F N E D L P K]
time 1861ms: Process A completed I/O; added to ready queue [Q H O B J C G I F N E D L P K A]
time 1863ms: Process M completed a CPU burst; 46 bursts to go [Q H O B J C G I F N E D L P K A]
time 1863ms: Process M switching out of CPU; will block on I/O until time 1907ms [Q H O B J C G I F N E D L P K A]
time 1867ms: Process H started using the CPU for 48ms burst [Q O B J C G I F N E D L P K A]
time 1907ms: Process M completed I/O; added to ready queue [Q O B J C G I F N E D L P K A M]
time 1915ms: Process H completed a CPU burst; 81 bursts to go [Q O B J C G I F N E D L P K A M]
time 1915ms: Process H switching out of CPU; will block on I/O until time 1939ms [Q O B J C G I F N E D L P K A M]
time 1919ms: Process O started using the CPU with 28ms burst remaining [Q B J C G I F N E D L P K A M]
time 1939ms: Process H completed I/O; added to ready queue [Q B J C G I F N E D L P K A M H]
time 1947ms: Process O completed a CPU burst; 30 bursts to go [Q B J C G I F N E D L P K A M H]
time 1947ms: Process O switching out of CPU; will block on I/O until time 2016ms [Q B J C G I F N E D L P K A M H]
time 1951ms: Process B started using the CPU for 198ms burst [Q J C G I F N E D L P K A M H]
time 2016ms: Process O completed I/O; added to ready queue [Q J C G I F N E D L P K A M H O]
time 2079ms: Time slice expired; process B preempted with 70ms to go [Q J C G I F N E D L P K A M H O]
time 2083ms: Process J started using the CPU with 76ms burst remaining [Q C G I F N E D L P K A M H O B]
time 2159ms: Process J completed a CPU burst; 8 bursts to go [Q C G I F N E D L P K A M H O B]
time 2159ms: Process J switching out of CPU; will block on I/O until time 2231ms [Q C G I F N E D L P K A M H O B]
time 2163ms: Process C started using the CPU for 117ms burst [Q G I F N E D L P K A M H O B]
time 2231ms: Process J completed I/O; added to ready queue [Q G I F N E D L P K A M H O B J]
time 2280ms: Process C completed a CPU burst; 2 bursts to go [Q G I F N E D L P K A M H O B J]
time 2280ms: Process C switching out of CPU; will block on I/O until time 2299ms [Q G I F N E D L P K A M H O B J]
time 2284ms: Process G started using the CPU for 40ms burst [Q I F N E D L P K A M H O B J]
time 2299ms: Process C completed I/O; added to ready queue [Q I F N E D L P K A M H O B J C]
time 2324ms: Process G completed a CPU burst; 78 bursts to go [Q I F N E D L P K A M H O B J C]
time 2324ms: Process G switching out of CPU; will block on I/O until time 2332ms [Q I F N E D L P K A M H O B J C]
time 2328ms: Process I started using the CPU with 92ms burst remaining [Q F N E D L P K A M H O B J C]
time 2332ms: Process G completed I/O; added to ready queue [Q F N E D L P K A M H O B J C G]
time 2420ms: Process I completed a CPU burst; 76 bursts to go [Q F N E D L P K A M H O B J C G]
time 2420ms: Process I switching out of CPU; will block on I/O until time 2441ms [Q F N E D L P K A M H O B J C G]
time 2424ms: Process F started using the CPU with 1ms burst remaining [Q N E D L P K A M H O B J C G]
time 2425ms: Process F completed a CPU burst; 33 bursts to go [Q N E D L P K A M H O B J C G]
time 2425ms: Process F switching out of CPU; will block on I/O until time 2484ms [Q N E D L P K A M H O B J C G]
time 2429ms: Process N started using the CPU with 85ms burst remaining [Q E D L P K A M H O B J C G]
time 2441ms: Process I completed I/O; added to ready queue [Q E D L P K A M H O B J C G I]
time 2484ms: Process F completed I/O; added to ready queue [Q E D L P K A M H O B J C G I F]
time 2514ms: Process N completed a CPU burst; 30 bursts to go [Q E D L P K A M H O B J C G I F]
time 2514ms: Process N switching out of CPU; will block on I/O until time 2531ms [Q E D L P K A M H O B J C G I F]
time 2518ms: Process E started using the CPU with 24ms burst remaining [Q D L P K A M H O B J C G I F]
time 2531ms: Process N completed I/O; added to ready queue [Q D L P K A M H O B J C G I F N]
time 2542ms: Process E completed a CPU burst; 54 bursts to go [Q D L P K A M H O B J C G I F N]
time 2542ms: Process E switching out of CPU; will block on I/O until time 2590ms [Q D L P K A M H O B J C G I F N]
time 2546ms: Process D started using the CPU with 20ms burst remaining [Q L P K A M H O B J C G I F N]
time 2566ms: Process D completed a CPU burst; 10 bursts to go [Q L P K A M H O B J C G I F N]
time 2566ms: Process D switching out of CPU; will block on I/O until time 2570ms [Q L P K A M H O B J C G I F N]
time 2570ms: Process L started using the CPU with 7ms burst remaining [Q P K A M H O B J C G I F N]
time 2570ms: Process D completed I/O; added to ready queue [Q P K A M H O B J C G I F N D]
time 2577ms: Process L completed a CPU burst; 6 bursts to go [Q P K A M H O B J C G I F N D]
time 2577ms: Process L switching out of CPU; will block on I/O until time 2653ms [Q P K A M H O B J C G I F N D]
time 2581ms: Process P started using the CPU for 52ms burst [Q K A M H O B J C G I F N D]
time 2590ms: Process E completed I/O; added to ready queue [Q K A M H O B J C G I F N D E]
time 2633ms: Process P completed a CPU burst; 14 bursts to go [Q K A M H O B J C G I F N D E]
time 2633ms: Process P switching out of CPU; will block on I/O until time 2744ms [Q K A M H O B J C G I F N D E]
time 2637ms: Process K started using the CPU for 6ms burst [Q A M H O B J C G I F N D E]
time 2643ms: Process K completed a CPU burst; 10 bursts to go [Q A M H O B J C G I F N D E]
time 2643ms: Process K switching out of CPU; will block on I/O until time 2715ms [Q A M H O B J C G I F N D E]
time 2647ms: Process A started using the CPU for 39ms burst [Q M H O B J C G I F N D E]
time 2653ms: Process L completed I/O; added to ready queue [Q M H O B J C G I F N D E L]
time 2686ms: Process A completed a CPU burst; 13 bursts to go [Q M H O B J C G I F N D E L]
time 2686ms: Process A switching out of CPU; will block on I/O until time 2738ms [Q M H O B J C G I F N D E L]
time 2690ms: Process M started using the CPU for 79ms burst [Q H O B J C G I F N D E L]
time 2715ms: Process K completed I/O; added to ready queue [Q H O B J C G I F N D E L K]
time 2738ms: Process A completed I/O; added to ready queue [Q H O B J C G I F N D E L K A]
time 2744ms: Process P completed I/O; added to ready queue [Q H O B J C G I F N D E L K A P]
time 2769ms: Process M completed a CPU burst; 45 bursts to go [Q H O B J C G I F N D E L K A P]
time 2769ms: Process M switching out of CPU; will block on I/O until time 2885ms [Q H O B J C G I F N D E L K A P]
time 2773ms: Process H started using the CPU for 72ms burst [Q O B J C G I F N D E L K A P]
time 2845ms: Process H completed a CPU burst; 80 bursts to go [Q O B J C G I F N D E L K A P]
time 2845ms: Process H switching out of CPU; will block on I/O until time 2889ms [Q O B J C G I F N D E L K A P]
time 2849ms: Process O started using the CPU for 106ms burst [Q B J C G I F N D E L K A P]
time 2885ms: Process M completed I/O; added to ready queue [Q B J C G I F N D E L K A P M]
time 2889ms: Process H completed I/O; added to ready queue [Q B J C G I F N D E L K A P M H]
time 2955ms: Process O completed a CPU burst; 29 bursts to go [Q B J C G I F N D E L K A P M H]
time 2955ms: Process O switching out of CPU; will block on I/O until time 3206ms [Q B J C G I F N D E L K A P M H]
time 2959ms: Process B started using the CPU with 70ms burst remaining [Q J C G I F N D E L K A P M H]
time 3029ms: Process B completed a CPU burst; 19 bursts to go [Q J C G I F N D E L K A P M H]
time 3029ms: Process B switching out of CPU; will block on I/O until time 3144ms [Q J C G I F N D E L K A P M H]
time 3033ms: Process J started using the CPU for 28ms burst [Q C G I F N D E L K A P M H]
time 3061ms: Process J completed a CPU burst; 7 bursts to go [Q C G I F N D E L K A P M H]
time 3061ms: Process J switching out of CPU; will block on I/O until time 3085ms [Q C G I F N D E L K A P M H]
time 3065ms: Process C started using the CPU for 85ms burst [Q G I F N D E L K A P M H]
time 3085ms: Process J completed I/O; added to ready queue [Q G I F N D E L K A P M H J]
time 3144ms: Process B completed I/O; added to ready queue [Q G I F N D E L K A P M H J B]
time 3150ms: Process C completed a CPU burst; 1 burst to go [Q G I F N D E L K A P M H J B]
time 3150ms: Process C switching out of CPU; will block on I/O until time 3173ms [Q G I F N D E L K A P M H J B]
time 3154ms: Process G started using the CPU for 65ms burst [Q I F N D E L K A P M H J B]
time 3173ms: Process C completed I/O; added to ready queue [Q I F N D E L K A P M H J B C]
time 3206ms: Process O completed I/O; added to ready queue [Q I F N D E L K A P M H J B C O]
time 3219ms: Process G completed a CPU burst; 77 bursts to go [Q I F N D E L K A P M H J B C O]
time 3219ms: Process G switching out of CPU; will block on I/O until time 3265ms [Q I F N D E L K A P M H J B C O]
time 3223ms: Process I started using the CPU for 16ms burst [Q F N D E L K A P M H J B C O]
time 3239ms: Process I completed a CPU burst; 75 bursts to go [Q F N D E L K A P M H J B C O]
time 3239ms: Process I switching out of CPU; will block on I/O until time 3417ms [Q F N D E L K A P M H J B C O]
time 3243ms: Process F started using the CPU for 39ms burst [Q N D E L K A P M H J B C O]
time 3265ms: Process G completed I/O; added to ready queue [Q N D E L K A P M H J B C O G]
time 3282ms: Process F completed a CPU burst; 32 bursts to go [Q N D E L K A P M H J B C O G]
time 3282ms: Process F switching out of CPU; will block on I/O until time 3349ms [Q N D E L K A P M H J B C O G]
time 3286ms: Process N started using the CPU for 132ms burst [Q D E L K A P M H J B C O G]
time 3349ms: Process F completed I/O; added to ready queue [Q D E L K A P M H J B C O G F]
time 3414ms: Time slice expired; process N preempted with 4ms to go [Q D E L K A P M H J B C O G F]
time 3417ms: Process I completed I/O; added to ready queue [Q E L K A P M H J B C O G F N I]
time 3418ms: Process D started using the CPU for 211ms burst [Q E L K A P M H J B C O G F N I]
time 3546ms: Time slice expired; process D preempted with 83ms to go [Q E L K A P M H J B C O G F N I]
time 3550ms: Process E started using the CPU for 44ms burst [Q L K A P M H J B C O G F N I D]
time 3594ms: Process E completed a CPU burst; 53 bursts to go [Q L K A P M H J B C O G F N I D]
time 3594ms: Process E switching out of CPU; will block on I/O until time 3652ms [Q L K A P M H J B C O G F N I D]
time 3598ms: Process L started using the CPU for 4ms burst [Q K A P M H J B C O G F N I D]
time 3602ms: Process L completed a CPU burst; 5 bursts to go [Q K A P M H J B C O G F N I D]
time 3602ms: Process L switching out of CPU; will block on I/O until time 3646ms [Q K A P M H J B C O G F N I D]
time 3606ms: Process K started using the CPU for 6ms burst [Q A P M H J B C O G F N I D]
time 3612ms: Process K completed a CPU burst; 9 bursts to go [Q A P M H J B C O G F N I D]
time 3612ms: Process K switching out of CPU; will block on I/O until time 3689ms [Q A P M H J B C O G F N I D]
time 3616ms: Process A started using the CPU for 47ms burst [Q P M H J B C O G F N I D]
time 3646ms: Process L completed I/O; added to ready queue [Q P M H J B C O G F N I D L]
time 3652ms: Process E completed I/O; added to ready queue [Q P M H J B C O G F N I D L E]
time 3663ms: Process A completed a CPU burst; 12 bursts to go [Q P M H J B C O G F N I D L E]
time 3663ms: Process A switching out of CPU; will block on I/O until time 3667ms [Q P M H J B C O G F N I D L E]
time 3667ms: Process P started using the CPU for 56ms burst [Q M H J B C O G F N I D L E]
time 3667ms: Process A completed I/O; added to ready queue [Q M H J B C O G F N I D L E A]
time 3689ms: Process K completed I/O; added to ready queue [Q M H J B C O G F N I D L E A K]
time 3723ms: Process P completed a CPU burst; 13 bursts to go [Q M H J B C O G F N I D L E A K]
time 3723ms: Process P switching out of CPU; will block on I/O until time 3846ms [Q M H J B C O G F N I D L E A K]
time 3727ms: Process M started using the CPU for 18ms burst [Q H J B C O G F N I D L E A K]
time 3745ms: Process M completed a CPU burst; 44 bursts to go [Q H J B C O G F N I D L E A K]
time 3745ms: Process M switching out of CPU; will block on I/O until time 3944ms [Q H J B C O G F N I D L E A K]
time 3749ms: Process H started using the CPU for 12ms burst [Q J B C O G F N I D L E A K]
time 3761ms: Process H completed a CPU burst; 79 bursts to go [Q J B C O G F N I D L E A K]
time 3761ms: Process H switching out of CPU; will block on I/O until time 3776ms [Q J B C O G F N I D L E A K]
time 3765ms: Process J started using the CPU for 120ms burst [Q B C O G F N I D L E A K]
time 3776ms: Process H completed I/O; added to ready queue [Q B C O G F N I D L E A K H]
time 3846ms: Process P completed I/O; added to ready queue [Q B C O G F N I D L E A K H P]
time 3885ms: Process J completed a CPU burst; 6 bursts to go [Q B C O G F N I D L E A K H P]
time 3885ms: Process J switching out of CPU; will block on I/O until time 3943ms [Q B C O G F N I D L E A K H P]
time 3889ms: Process B started using the CPU for 208ms burst [Q C O G F N I D L E A K H P]
time 3943ms: Process J completed I/O; added to ready queue [Q C O G F N I D L E A K H P J]
time 3944ms: Process M completed I/O; added to ready queue [Q C O G F N I D L E A K H P J M]
time 4017ms: Time slice expired; process B preempted with 80ms to go [Q C O G F N I D L E A K H P J M]
time 4021ms: Process C started using the CPU for 79ms burst [Q O G F N I D L E A K H P J M B]
time 4100ms: Process C terminated [Q O G F N I D L E A K H P J M B]
time 4104ms: Process O started using the CPU for 57ms burst [Q G F N I D L E A K H P J M B]
time 4161ms: Process O completed a CPU burst; 28 bursts to go [Q G F N I D L E A K H P J M B]
time 4161ms: Process O switching out of CPU; will block on I/O until time 4200ms [Q G F N I D L E A K H P J M B]
time 4165ms: Process G started using the CPU for 13ms burst [Q F N I D L E A K H P J M B]
time 4178ms: Process G completed a CPU burst; 76 bursts to go [Q F N I D L E A K H P J M B]
time 4178ms: Process G switching out of CPU; will block on I/O until time 4218ms [Q F N I D L E A K H P J M B]
time 4182ms: Process F started using the CPU for 195ms burst [Q N I D L E A K H P J M B]
time 4200ms: Process O completed I/O; added to ready queue [Q N I D L E A K H P J M B O]
time 4218ms: Process G completed I/O; added to ready queue [Q N I D L E A K H P J M B O G]
time 4310ms: Time slice expired; process F preempted with 67ms to go [Q N I D L E A K H P J M B O G]
time 4314ms: Process N started using the CPU with 4ms burst remaining [Q I D L E A K H P J M B O G F]
time 4318ms: Process N completed a CPU burst; 29 bursts to go [Q I D L E A K H P J M B O G F]
time 4318ms: Process N switching out of CPU; will block on I/O until time 4480ms [Q I D L E A K H P J M B O G F]
time 4322ms: Process I started using the CPU for 26ms burst [Q D L E A K H P J M B O G F]
time 4348ms: Process I completed a CPU burst; 74 bursts to go [Q D L E A K H P J M B O G F]
time 4348ms: Process I switching out of CPU; will block on I/O until time 4413ms [Q D L E A K H P J M B O G F]
time 4352ms: Process D started using the CPU with 83ms burst remaining [Q L E A K H P J M B O G F]
time 4413ms: Process I completed I/O; added to ready queue [Q L E A K H P J M B O G F I]
time 4435ms: Process D completed a CPU burst; 9 bursts to go [Q L E A K H P J M B O G F I]
time 4435ms: Process D switching out of CPU; will block on I/O until time 4651ms [Q L E A K H P J M B O G F I]
time 4439ms: Process L started using the CPU for 69ms burst [Q E A K H P J M B O G F I]
time 4480ms: Process N completed I/O; added to ready queue [Q E A K H P J M B O G F I N]
time 4508ms: Process L completed a CPU burst; 4 bursts to go [Q E A K H P J M B O G F I N]
time 4508ms: Process L switching out of CPU; will block on I/O until time 4605ms [Q E A K H P J M B O G F I N]
time 4512ms: Process E started using the CPU for 2ms burst [Q A K H P J M B O G F I N]
time 4514ms: Process E completed a CPU burst; 52 bursts to go [Q A K H P J M B O G F I N]
time 4514ms: Process E switching out of CPU; will block on I/O until time 4541ms [Q A K H P J M B O G F I N]
time 4518ms: Process A started using the CPU for 137ms burst [Q K H P J M B O G F I N]
time 4541ms: Process E completed I/O; added to ready queue [Q K H P J M B O G F I N E]
time 4605ms: Process L completed I/O; added to ready queue [Q K H P J M B O G F I N E L]
time 4646ms: Time slice expired; process A preempted with 9ms to go [Q K H P J M B O G F I N E L]
time 4650ms: Process K started using the CPU for 157ms burst [Q H P J M B O G F I N E L A]
time 4651ms: Process D completed I/O; added to ready queue [Q H P J M B O G F I N E L A D]
time 4778ms: Time slice expired; process K preempted with 29ms to go [Q H P J M B O G F I N E L A D]
time 4782ms: Process H started using the CPU for 41ms burst [Q P J M B O G F I N E L A D K]
time 4823ms: Process H completed a CPU burst; 78 bursts to go [Q P J M B O G F I N E L A D K]
time 4823ms: Process H switching out of CPU; will block on I/O until time 4846ms [Q P J M B O G F I N E L A D K]
time 4827ms: Process P started using the CPU for 155ms burst [Q J M B O G F I N E L A D K]
time 4846ms: Process H completed I/O; added to ready queue [Q J M B O G F I N E L A D K H]
time 4955ms: Time slice expired; process P preempted with 27ms to go [Q J M B O G F I N E L A D K H]
time 4959ms: Process J started using the CPU for 31ms burst [Q M B O G F I N E L A D K H P]
time 4990ms: Process J completed a CPU burst; 5 bursts to go [Q M B O G F I N E L A D K H P]
time 4990ms: Process J switching out of CPU; will block on I/O until time 5078ms [Q M B O G F I N E L A D K H P]
time 4994ms: Process M started using the CPU for 66ms burst [Q B O G F I N E L A D K H P]
time 5060ms: Process M completed a CPU burst; 43 bursts to go [Q B O G F I N E L A D K H P]
time 5060ms: Process M switching out of CPU; will block on I/O until time 5243ms [Q B O G F I N E L A D K H P]
time 5064ms: Process B started using the CPU with 80ms burst remaining [Q O G F I N E L A D K H P]
time 5078ms: Process J completed I/O; added to ready queue [Q O G F I N E L A D K H P J]
time 5144ms: Process B completed a CPU burst; 18 bursts to go [Q O G F I N E L A D K H P J]
time 5144ms: Process B switching out of CPU; will block on I/O until time 5308ms [Q O G F I N E L A D K H P J]
time 5148ms: Process O started using the CPU for 13ms burst [Q G F I N E L A D K H P J]
time 5161ms: Process O completed a CPU burst; 27 bursts to go [Q G F I N E L A D K H P J]
time 5161ms: Process O switching out of CPU; will block on I/O until time 5296ms [Q G F I N E L A D K H P J]
time 5165ms: Process G started using the CPU for 128ms burst [Q F I N E L A D K H P J]
time 5243ms: Process M completed I/O; added to ready queue [Q F I N E L A D K H P J M]
time 5293ms: Process G completed a CPU burst; 75 bursts to go [Q F I N E L A D K H P J M]
time 5293ms: Process G switching out of CPU; will block on I/O until time 5517ms [Q F I N E L A D K H P J M]
time 5296ms: Process O completed I/O; added to ready queue [Q I N E L A D K H P J M O]
time 5297ms: Process F started using the CPU with 67ms burst remaining [Q I N E L A D K H P J M O]
time 5308ms: Process B completed I/O; added to ready queue [Q I N E L A D K H P J M O B]
time 5364ms: Process F completed a CPU burst; 31 bursts to go [Q I N E L A D K H P J M O B]
time 5364ms: Process F switching out of CPU; will block on I/O until time 5367ms [Q I N E L A D K H P J M O B]
time 5367ms: Process F completed I/O; added to ready queue [Q N E L A D K H P J M O B F]
time 5368ms: Process I started using the CPU for 45ms burst [Q N E L A D K H P J M O B F]
time 5413ms: Process I completed a CPU burst; 73 bursts to go [Q N E L A D K H P J M O B F]
time 5413ms: Process I switching out of CPU; will block on I/O until time 5445ms [Q N E L A D K H P J M O B F]
time 5417ms: Process N started using the CPU for 17ms burst [Q E L A D K H P J M O B F]
time 5434ms: Process N completed a CPU burst; 28 bursts to go [Q E L A D K H P J M O B F]
time 5434ms: Process N switching out of CPU; will block on I/O until time 5511ms [Q E L A D K H P J M O B F]
time 5438ms: Process E started using the CPU for 42ms burst [Q L A D K H P J M O B F]
time 5445ms: Process I completed I/O; added to ready queue [Q L A D K H P J M O B F I]
time 5480ms: Process E completed a CPU burst; 51 bursts to go [Q L A D K H P J M O B F I]
time 5480ms: Process E switching out of CPU; will block on I/O until time 5487ms [Q L A D K H P J M O B F I]
time 5484ms: Process L started using the CPU for 25ms burst [Q A D K H P J M O B F I]
time 5487ms: Process E completed I/O; added to ready queue [Q A D K H P J M O B F I E]
time 5509ms: Process L completed a CPU burst; 3 bursts to go [Q A D K H P J M O B F I E]
time 5509ms: Process L switching out of CPU; will block on I/O until time 5630ms [Q A D K H P J M O B F I E]
time 5511ms: Process N completed I/O; added to ready queue [Q A D K H P J M O B F I E N]
time 5513ms: Process A started using the CPU with 9ms burst remaining [Q D K H P J M O B F I E N]
time 5517ms: Process G completed I/O; added to ready queue [Q D K H P J M O B F I E N G]
time 5522ms: Process A completed a CPU burst; 11 bursts to go [Q D K H P J M O B F I E N G]
time 5522ms: Process A switching out of CPU; will block on I/O until time 5548ms [Q D K H P J M O B F I E N G]
time 5526ms: Process D started using the CPU for 9ms burst [Q K H P J M O B F I E N G]
time 5535ms: Process D completed a CPU burst; 8 bursts to go [Q K H P J M O B F I E N G]
time 5535ms: Process D switching out of CPU; will block on I/O until time 5575ms [Q K H P J M O B F I E N G]
time 5539ms: Process K started using the CPU with 29ms burst remaining [Q H P J M O B F I E N G]
time 5548ms: Process A completed I/O; added to ready queue [Q H P J M O B F I E N G A]
time 5568ms: Process K completed a CPU burst; 8 bursts to go [Q H P J M O B F I E N G A]
time 5568ms: Process K switching out of CPU; will block on I/O until time 5586ms [Q H P J M O B F I E N G A]
time 5572ms: Process H started using the CPU for 160ms burst [Q P J M O B F I E N G A]
time 5575ms: Process D completed I/O; added to ready queue [Q P J M O B F I E N G A D]
time 5586ms: Process K completed I/O; added to ready queue [Q P J M O B F I E N G A D K]
time 5630ms: Process L completed I/O; added to ready queue [Q P J M O B F I E N G A D K L]
time 5700ms: Time slice expired; process H preempted with 32ms to go [Q P J M O B F I E N G A D K L]
time 5704ms: Process P started using the CPU with 27ms burst remaining [Q J M O B F I E N G A D K L H]
time 5731ms: Process P completed a CPU burst; 12 bursts to go [Q J M O B F I E N G A D K L H]
time 5731ms: Process P switching out of CPU; will block on I/O until time 5851ms [Q J M O B F I E N G A D K L H]
time 5735ms: Process J started using the CPU for 32ms burst [Q M O B F I E N G A D K L H]
time 5767ms: Process J completed a CPU burst; 4 bursts to go [Q M O B F I E N G A D K L H]
time 5767ms: Process J switching out of CPU; will block on I/O until time 5782ms [Q M O B F I E N G A D K L H]
time 5771ms: Process M started using the CPU for 103ms burst [Q O B F I E N G A D K L H]
time 5782ms: Process J completed I/O; added to ready queue [Q O B F I E N G A D K L H J]
time 5851ms: Process P completed I/O; added to ready queue [Q O B F I E N G A D K L H J P]
time 5874ms: Process M completed a CPU burst; 42 bursts to go [Q O B F I E N G A D K L H J P]
time 5874ms: Process M switching out of CPU; will block on I/O until time 5916ms [Q O B F I E N G A D K L H J P]
time 5878ms: Process O started using the CPU for 130ms burst [Q B F I E N G A D K L H J P]
time 5916ms: Process M completed I/O; added to ready queue [Q B F I E N G A D K L H J P M]
time 6006ms: Time slice expired; process O preempted with 2ms to go [Q B F I E N G A D K L H J P M]
time 6010ms: Process B started using the CPU for 50ms burst [Q F I E N G A D K L H J P M O]
time 6060ms: Process B completed a CPU burst; 17 bursts to go [Q F I E N G A D K L H J P M O]
time 6060ms: Process B switching out of CPU; will block on I/O until time 6108ms [Q F I E N G A D K L H J P M O]
time 6064ms: Process F started using the CPU for 72ms burst [Q I E N G A D K L H J P M O]
time 6108ms: Process B completed I/O; added to ready queue [Q I E N G A D K L H J P M O B]
time 6136ms: Process F completed a CPU burst; 30 bursts to go [Q I E N G A D K L H J P M O B]
time 6136ms: Process F switching out of CPU; will block on I/O until time 6164ms [Q I E N G A D K L H J P M O B]
time 6140ms: Process I started using the CPU for 38ms burst [Q E N G A D K L H J P M O B]
time 6164ms: Process F completed I/O; added to ready queue [Q E N G A D K L H J P M O B F]
time 6178ms: Process I completed a CPU burst; 72 bursts to go [Q E N G A D K L H J P M O B F]
time 6178ms: Process I switching out of CPU; will block on I/O until time 6238ms [Q E N G A D K L H J P M O B F]
time 6182ms: Process E started using the CPU for 108ms burst [Q N G A D K L H J P M O B F]
time 6238ms: Process I completed I/O; added to ready queue [Q N G A D K L H J P M O B F I]
time 6290ms: Process E completed a CPU burst; 50 bursts to go [Q N G A D K L H J P M O B F I]
time 6290ms: Process E switching out of CPU; will block on I/O until time 6301ms [Q N G A D K L H J P M O B F I]
time 6294ms: Process N started using the CPU for 71ms burst [Q G A D K L H J P M O B F I]
time 6301ms: Process E completed I/O; added to ready queue [Q G A D K L H J P M O B F I E]
time 6365ms: Process N completed a CPU burst; 27 bursts to go [Q G A D K L H J P M O B F I E]
time 6365ms: Process N switching out of CPU; will block on I/O until time 6561ms [Q G A D K L H J P M O B F I E]
time 6369ms: Process G started using the CPU for 15ms burst [Q A D K L H J P M O B F I E]
time 6384ms: Process G completed a CPU burst; 74 bursts to go [Q A D K L H J P M O B F I E]
time 6384ms: Process G switching out of CPU; will block on I/O until time 6480ms [Q A D K L H J P M O B F I E]
time 6388ms: Process A started using the CPU for 64ms burst [Q D K L H J P M O B F I E]
time 6452ms: Process A completed a CPU burst; 10 bursts to go [Q D K L H J P M O B F I E]
time 6452ms: Process A switching out of CPU; will block on I/O until time 6469ms [Q D K L H J P M O B F I E]
time 6456ms: Process D started using the CPU for 4ms burst [Q K L H J P M O B F I E]
time 6460ms: Process D completed a CPU burst; 7 bursts to go [Q K L H J P M O B F I E]
time 6460ms: Process D switching out of CPU; will block on I/O until time 6510ms [Q K L H J P M O B F I E]
time 6464ms: Process K started using the CPU for 104ms burst [Q L H J P M O B F I E]
time 6469ms: Process A completed I/O; added to ready queue [Q L H J P M O B F I E A]
time 6480ms: Process G completed I/O; added to ready queue [Q L H J P M O B F I E A G]
time 6510ms: Process D completed I/O; added to ready queue [Q L H J P M O B F I E A G D]
time 6561ms: Process N completed I/O; added to ready queue [Q L H J P M O B F I E A G D N]
time 6568ms: Process K completed a CPU burst; 7 bursts to go [Q L H J P M O B F I E A G D N]
time 6568ms: Process K switching out of CPU; will block on I/O until time 6715ms [Q L H J P M O B F I E A G D N]
time 6572ms: Process L started using the CPU for 2ms burst [Q H J P M O B F I E A G D N]
time 6574ms: Process L completed a CPU burst; 2 bursts to go [Q H J P M O B F I E A G D N]
time 6574ms: Process L switching out of CPU; will block on I/O until time 6613ms [Q H J P M O B F I E A G D N]
time 6578ms: Process H started using the CPU with 32ms burst remaining [Q J P M O B F I E A G D N]
time 6610ms: Process H completed a CPU burst; 77 bursts to go [Q J P M O B F I E A G D N]
time 6610ms: Process H switching out of CPU; will block on I/O until time 6672ms [Q J P M O B F I E A G D N]
time 6613ms: Process L completed I/O; added to ready queue [Q P M O B F I E A G D N L]
time 6614ms: Process J started using the CPU for 23ms burst [Q P M O B F I E A G D N L]
time 6637ms: Process J completed a CPU burst; 3 bursts to go [Q P M O B F I E A G D N L]
time 6637ms: Process J switching out of CPU; will block on I/O until time 6655ms [Q P M O B F I E A G D N L]
time 6641ms: Process P started using the CPU for 4ms burst [Q M O B F I E A G D N L]
time 6645ms: Process P completed a CPU burst; 11 bursts to go [Q M O B F I E A G D N L]
time 6645ms: Process P switching out of CPU; will block on I/O until time 6826ms [Q M O B F I E A G D N L]
time 6649ms: Process M started using the CPU for 171ms burst [Q O B F I E A G D N L]
time 6655ms: Process J completed I/O; added to ready queue [Q O B F I E A G D N L J]
time 6672ms: Process H completed I/O; added to ready queue [Q O B F I E A G D N L J H]
time 6715ms: Process K completed I/O; added to ready queue [Q O B F I E A G D N L J H K]
time 6777ms: Time slice expired; process M preempted with 43ms to go [Q O B F I E A G D N L J H K]
time 6781ms: Process O started using the CPU with 2ms burst remaining [Q B F I E A G D N L J H K M]
time 6783ms: Process O completed a CPU burst; 26 bursts to go [Q B F I E A G D N L J H K M]
time 6783ms: Process O switching out of CPU; will block on I/O until time 6856ms [Q B F I E A G D N L J H K M]
time 6787ms: Process B started using the CPU for 82ms burst [Q F I E A G D N L J H K M]
time 6826ms: Process P completed I/O; added to ready queue [Q F I E A G D N L J H K M P]
time 6856ms: Process O completed I/O; added to ready queue [Q F I E A G D N L J H K M P O]
time 6869ms: Process B completed a CPU burst; 16 bursts to go [Q F I E A G D N L J H K M P O]
time 6869ms: Process B switching out of CPU; will block on I/O until time 6887ms [Q F I E A G D N L J H K M P O]
time 6873ms: Process F started using the CPU for 8ms burst [Q I E A G D N L J H K M P O]
time 6881ms: Process F completed a CPU burst; 29 bursts to go [Q I E A G D N L J H K M P O]
time 6881ms: Process F switching out of CPU; will block on I/O until time 6916ms [Q I E A G D N L J H K M P O]
time 6885ms: Process I started using the CPU for 79ms burst [Q E A G D N L J H K M P O]
time 6887ms: Process B completed I/O; added to ready queue [Q E A G D N L J H K M P O B]
time 6916ms: Process F completed I/O; added to ready queue [Q E A G D N L J H K M P O B F]
time 6964ms: Process I completed a CPU burst; 71 bursts to go [Q E A G D N L J H K M P O B F]
time 6964ms: Process I switching out of CPU; will block on I/O until time 7082ms [Q E A G D N L J H K M P O B F]
time 6968ms: Process E started using the CPU for 6ms burst [Q A G D N L J H K M P O B F]
time 6974ms: Process E completed a CPU burst; 49 bursts to go [Q A G D N L J H K M P O B F]
time 6974ms: Process E switching out of CPU; will block on I/O until time 7008ms [Q A G D N L J H K M P O B F]
time 6978ms: Process A started using the CPU for 68ms burst [Q G D N L J H K M P O B F]
time 7008ms: Process E completed I/O; added to ready queue [Q G D N L J H K M P O B F E]
time 7046ms: Process A completed a CPU burst; 9 bursts to go [Q G D N L J H K M P O B F E]
time 7046ms: Process A switching out of CPU; will block on I/O until time 7112ms [Q G D N L J H K M P O B F E]
time 7050ms: Process G started using the CPU for 112ms burst [Q D N L J H K M P O B F E]
time 7082ms: Process I completed I/O; added to ready queue [Q D N L J H K M P O B F E I]
time 7112ms: Process A completed I/O; added to ready queue [Q D N L J H K M P O B F E I A]
time 7162ms: Process G completed a CPU burst; 73 bursts to go [Q D N L J H K M P O B F E I A]
time 7162ms: Process G switching out of CPU; will block on I/O until time 7207ms [Q D N L J H K M P O B F E I A]
time 7166ms: Process D started using the CPU for 149ms burst [Q N L J H K M P O B F E I A]
time 7207ms: Process G completed I/O; added to ready queue [Q N L J H K M P O B F E I A G]
time 7294ms: Time slice expired; process D preempted with 21ms to go [Q N L J H K M P O B F E I A G]
time 7298ms: Process N started using the CPU for 27ms burst [Q L J H K M P O B F E I A G D]
time 7325ms: Process N completed a CPU burst; 26 bursts to go [Q L J H K M P O B F E I A G D]
time 7325ms: Process N switching out of CPU; will block on I/O until time 7354ms [Q L J H K M P O B F E I A G D]
time 7329ms: Process L started using the CPU for 164ms burst [Q J H K M P O B F E I A G D]
time 7354ms: Process N completed I/O; added to ready queue [Q J H K M P O B F E I A G D N]
time 7457ms: Time slice expired; process L preempted with 36ms to go [Q J H K M P O B F E I A G D N]
time 7461ms: Process J started using the CPU for 51ms burst [Q H K M P O B F E I A G D N L]
time 7512ms: Process J completed a CPU burst; 2 bursts to go [Q H K M P O B F E I A G D N L]
time 7512ms: Process J switching out of CPU; will block on I/O until time 7611ms [Q H K M P O B F E I A G D N L]
time 7516ms: Process H started using the CPU for 28ms burst [Q K M P O B F E I A G D N L]
time 7544ms: Process H completed a CPU burst; 76 bursts to go [Q K M P O B F E I A G D N L]
time 7544ms: Process H switching out of CPU; will block on I/O until time 7642ms [Q K M P O B F E I A G D N L]
time 7548ms: Process K started using the CPU for 86ms burst [Q M P O B F E I A G D N L]
time 7611ms: Process J completed I/O; added to ready queue [Q M P O B F E I A G D N L J]
time 7634ms: Process K completed a CPU burst; 6 bursts to go [Q M P O B F E I A G D N L J]
time 7634ms: Process K switching out of CPU; will block on I/O until time 7664ms [Q M P O B F E I A G D N L J]
time 7638ms: Process M started using the CPU with 43ms burst remaining [Q P O B F E I A G D N L J]
time 7642ms: Process H completed I/O; added to ready queue [Q P O B F E I A G D N L J H]
time 7664ms: Process K completed I/O; added to ready queue [Q P O B F E I A G D N L J H K]
time 7681ms: Process M completed a CPU burst; 41 bursts to go [Q P O B F E I A G D N L J H K]
time 7681ms: Process M switching out of CPU; will block on I/O until time 7704ms [Q P O B F E I A G D N L J H K]
time 7685ms: Process P started using the CPU for 105ms burst [Q O B F E I A G D N L J H K]
time 7704ms: Process M completed I/O; added to ready queue [Q O B F E I A G D N L J H K M]
time 7790ms: Process P completed a CPU burst; 10 bursts to go [Q O B F E I A G D N L J H K M]
time 7790ms: Process P switching out of CPU; will block on I/O until time 7851ms [Q O B F E I A G D N L J H K M]
time 7794ms: Process O started using the CPU for 68ms burst [Q B F E I A G D N L J H K M]
time 7851ms: Process P completed I/O; added to ready queue [Q B F E I A G D N L J H K M P]
time 7862ms: Process O completed a CPU burst; 25 bursts to go [Q B F E I A G D N L J H K M P]
time 7862ms: Process O switching out of CPU; will block on I/O until time 7981ms [Q B F E I A G D N L J H K M P]
time 7866ms: Process B started using the CPU for 7ms burst [Q F E I A G D N L J H K M P]
time 7873ms: Process B completed a CPU burst; 15 bursts to go [Q F E I A G D N L J H K M P]
time 7873ms: Process B switching out of CPU; will block on I/O until time 7905ms [Q F E I A G D N L J H K M P]
time 7877ms: Process F started using the CPU for 230ms burst [Q E I A G D N L J H K M P]
time 7905ms: Process B completed I/O; added to ready queue [Q E I A G D N L J H K M P B]
time 7981ms: Process O completed I/O; added to ready queue [Q E I A G D N L J H K M P B O]
time 8005ms: Time slice expired; process F preempted with 102ms to go [Q E I A G D N L J H K M P B O]
time 8009ms: Process E started using the CPU for 112ms burst [Q I A G D N L J H K M P B O F]
time 8121ms: Process E completed a CPU burst; 48 bursts to go [Q I A G D N L J H K M P B O F]
time 8121ms: Process E switching out of CPU; will block on I/O until time 8234ms [Q I A G D N L J H K M P B O F]
time 8125ms: Process I started using the CPU for 84ms burst [Q A G D N L J H K M P B O F]
time 8209ms: Process I completed a CPU burst; 70 bursts to go [Q A G D N L J H K M P B O F]
time 8209ms: Process I switching out of CPU; will block on I/O until time 8262ms [Q A G D N L J H K M P B O F]
time 8213ms: Process A started using the CPU for 113ms burst [Q G D N L J H K M P B O F]
time 8234ms: Process E completed I/O; added to ready queue [Q G D N L J H K M P B O F E]
time 8262ms: Process I completed I/O; added to ready queue [Q G D N L J H K M P B O F E I]
time 8326ms: Process A completed a CPU burst; 8 bursts to go [Q G D N L J H K M P B O F E I]
time 8326ms: Process A switching out of CPU; will block on I/O until time 8344ms [Q G D N L J H K M P B O F E I]
time 8330ms: Process G started using the CPU for 30ms burst [Q D N L J H K M P B O F E I]
time 8344ms: Process A completed I/O; added to ready queue [Q D N L J H K M P B O F E I A]
time 8360ms: Process G completed a CPU burst; 72 bursts to go [Q D N L J H K M P B O F E I A]
time 8360ms: Process G switching out of CPU; will block on I/O until time 8409ms [Q D N L J H K M P B O F E I A]
time 8364ms: Process D started using the CPU with 21ms burst remaining [Q N L J H K M P B O F E I A]
time 8385ms: Process D completed a CPU burst; 6 bursts to go [Q N L J H K M P B O F E I A]
time 8385ms: Process D switching out of CPU; will block on I/O until time 8468ms [Q N L J H K M P B O F E I A]
time 8389ms: Process N started using the CPU for 57ms burst [Q L J H K M P B O F E I A]
time 8409ms: Process G completed I/O; added to ready queue [Q L J H K M P B O F E I A G]
time 8446ms: Process N completed a CPU burst; 25 bursts to go [Q L J H K M P B O F E I A G]
time 8446ms: Process N switching out of CPU; will block on I/O until time 8458ms [Q L J H K M P B O F E I A G]
time 8450ms: Process L started using the CPU with 36ms burst remaining [Q J H K M P B O F E I A G]
time 8458ms: Process N completed I/O; added to ready queue [Q J H K M P B O F E I A G N]
time 8468ms: Process D completed I/O; added to ready queue [Q J H K M P B O F E I A G N D]
time 8486ms: Process L completed a CPU burst; 1 burst to go [Q J H K M P B O F E I A G N D]
time 8486ms: Process L switching out of CPU; will block on I/O until time 8538ms [Q J H K M P B O F E I A G N D]
time 8490ms: Process J started using the CPU for 216ms burst [Q H K M P B O F E I A G N D]
time 8538ms: Process L completed I/O; added to ready queue [Q H K M P B O F E I A G N D L]
time 8618ms: Time slice expired; process J preempted with 88ms to go [Q H K M P B O F E I A G N D L]
time 8622ms: Process H started using the CPU for 51ms burst [Q K M P B O F E I A G N D L J]
time 8673ms: Process H completed a CPU burst; 75 bursts to go [Q K M P B O F E I A G N D L J]
time 8673ms: Process H switching out of CPU; will block on I/O until time 8698ms [Q K M P B O F E I A G N D L J]
time 8677ms: Process K started using the CPU for 50ms burst [Q M P B O F E I A G N D L J]
time 8698ms: Process H completed I/O; added to ready queue [Q M P B O F E I A G N D L J H]
time 8727ms: Process K completed a CPU burst; 5 bursts to go [Q M P B O F E I A G N D L J H]
time 8727ms: Process K switching out of CPU; will block on I/O until time 8779ms [Q M P B O F E I A G N D L J H]
time 8731ms: Process M started using the CPU for 200ms burst [Q P B O F E I A G N D L J H]
time 8779ms: Process K completed I/O; added to ready queue [Q P B O F E I A G N D L J H K]
time 8859ms: Time slice expired; process M preempted with 72ms to go [Q P B O F E I A G N D L J H K]
time 8863ms: Process P started using the CPU for 16ms burst [Q B O F E I A G N D L J H K M]
time 8879ms: Process P completed a CPU burst; 9 bursts to go [Q B O F E I A G N D L J H K M]
time 8879ms: Process P switching out of CPU; will block on I/O until time 8946ms [Q B O F E I A G N D L J H K M]
time 8883ms: Process B started using the CPU for 52ms burst [Q O F E I A G N D L J H K M]
time 8935ms: Process B completed a CPU burst; 14 bursts to go [Q O F E I A G N D L J H K M]
time 8935ms: Process B switching out of CPU; will block on I/O until time 8949ms [Q O F E I A G N D L J H K M]
time 8939ms: Process O started using the CPU for 136ms burst [Q F E I A G N D L J H K M]
time 8946ms: Process P completed I/O; added to ready queue [Q F E I A G N D L J H K M P]
time 8949ms: Process B completed I/O; added to ready queue [Q F E I A G N D L J H K M P B]
time 9067ms: Time slice expired; process O preempted with 8ms to go [Q F E I A G N D L J H K M P B]
time 9071ms: Process F started using the CPU with 102ms burst remaining [Q E I A G N D L J H K M P B O]
time 9173ms: Process F completed a CPU burst; 28 bursts to go [Q E I A G N D L J H K M P B O]
time 9173ms: Process F switching out of CPU; will block on I/O until time 9178ms [Q E I A G N D L J H K M P B O]
time 9177ms: Process E started using the CPU for 12ms burst [Q I A G N D L J H K M P B O]
time 9178ms: Process F completed I/O; added to ready queue [Q I A G N D L J H K M P B O F]
time 9189ms: Process E completed a CPU burst; 47 bursts to go [Q I A G N D L J H K M P B O F]
time 9189ms: Process E switching out of CPU; will block on I/O until time 9236ms [Q I A G N D L J H K M P B O F]
time 9193ms: Process I started using the CPU for 27ms burst [Q A G N D L J H K M P B O F]
time 9220ms: Process I completed a CPU burst; 69 bursts to go [Q A G N D L J H K M P B O F]
time 9220ms: Process I switching out of CPU; will block on I/O until time 9412ms [Q A G N D L J H K M P B O F]
time 9224ms: Process A started using the CPU for 11ms burst [Q G N D L J H K M P B O F]
time 9235ms: Process A completed a CPU burst; 7 bursts to go [Q G N D L J H K M P B O F]
time 9235ms: Process A switching out of CPU; will block on I/O until time 9399ms [Q G N D L J H K M P B O F]
time 9236ms: Process E completed I/O; added to ready queue [Q G N D L J H K M P B O F E]
time 9239ms: Process G started using the CPU for 50ms burst [Q N D L J H K M P B O F E]
time 9289ms: Process G completed a CPU burst; 71 bursts to go [Q N D L J H K M P B O F E]
time 9289ms: Process G switching out of CPU; will block on I/O until time 9511ms [Q N D L J H K M P B O F E]
time 9293ms: Process N started using the CPU for 84ms burst [Q D L J H K M P B O F E]
time 9377ms: Process N completed a CPU burst; 24 bursts to go [Q D L J H K M P B O F E]
time 9377ms: Process N switching out of CPU; will block on I/O until time 9381ms [Q D L J H K M P B O F E]
time 9381ms: Process D started using the CPU for 52ms burst [Q L J H K M P B O F E]
time 9381ms: Process N completed I/O; added to ready queue [Q L J H K M P B O F E N]
time 9399ms: Process A completed I/O; added to ready queue [Q L J H K M P B O F E N A]
time 9412ms: Process I completed I/O; added to ready queue [Q L J H K M P B O F E N A I]
time 9433ms: Process D completed a CPU burst; 5 bursts to go [Q L J H K M P B O F E N A I]
time 9433ms: Process D switching out of CPU; will block on I/O until time 9438ms [Q L J H K M P B O F E N A I]
time 9437ms: Process L started using the CPU for 111ms burst [Q J H K M P B O F E N A I]
time 9438ms: Process D completed I/O; added to ready queue [Q J H K M P B O F E N A I D]
time 9511ms: Process G completed I/O; added to ready queue [Q J H K M P B O F E N A I D G]
time 9548ms: Process L terminated [Q J H K M P B O F E N A I D G]
time 9552ms: Process J started using the CPU with 88ms burst remaining [Q H K M P B O F E N A I D G]
time 9640ms: Process J completed a CPU burst; 1 burst to go [Q H K M P B O F E N A I D G]
time 9640ms: Process J switching out of CPU; will block on I/O until time 9650ms [Q H K M P B O F E N A I D G]
time 9644ms: Process H started using the CPU for 87ms burst [Q K M P B O F E N A I D G]
time 9650ms: Process J completed I/O; added to ready queue [Q K M P B O F E N A I D G J]
time 9731ms: Process H completed a CPU burst; 74 bursts to go [Q K M P B O F E N A I D G J]
time 9731ms: Process H switching out of CPU; will block on I/O until time 9790ms [Q K M P B O F E N A I D G J]
time 9735ms: Process K started using the CPU for 4ms burst [Q M P B O F E N A I D G J]
time 9739ms: Process K completed a CPU burst; 4 bursts to go [Q M P B O F E N A I D G J]
time 9739ms: Process K switching out of CPU; will block on I/O until time 9801ms [Q M P B O F E N A I D G J]
time 9743ms: Process M started using the CPU with 72ms burst remaining [Q P B O F E N A I D G J]
time 9790ms: Process H completed I/O; added to ready queue [Q P B O F E N A I D G J H]
time 9801ms: Process K completed I/O; added to ready queue [Q P B O F E N A I D G J H K]
time 9815ms: Process M completed a CPU burst; 40 bursts to go [Q P B O F E N A I D G J H K]
time 9815ms: Process M switching out of CPU; will block on I/O until time 9948ms [Q P B O F E N A I D G J H K]
time 9819ms: Process P started using the CPU for 219ms burst [Q B O F E N A I D G J H K]
time 9947ms: Time slice expired; process P preempted with 91ms to go [Q B O F E N A I D G J H K]
time 9948ms: Process M completed I/O; added to ready queue [Q B O F E N A I D G J H K M]
time 9951ms: Process B started using the CPU for 228ms burst [Q O F E N A I D G J H K M P]
time 10079ms: Time slice expired; process B preempted with 100ms to go [Q O F E N A I D G J H K M P]
time 10083ms: Process O started using the CPU with 8ms burst remaining [Q F E N A I D G J H K M P B]
time 10091ms: Process O completed a CPU burst; 24 bursts to go [Q F E N A I D G J H K M P B]
time 10091ms: Process O switching out of CPU; will block on I/O until time 10198ms [Q F E N A I D G J H K M P B]
time 10095ms: Process F started using the CPU for 33ms burst [Q E N A I D G J H K M P B]
time 10128ms: Process F completed a CPU burst; 27 bursts to go [Q E N A I D G J H K M P B]
time 10128ms: Process F switching out of CPU; will block on I/O until time 10186ms [Q E N A I D G J H K M P B]
time 10132ms: Process E started using the CPU for 9ms burst [Q N A I D G J H K M P B]
time 10141ms: Process E completed a CPU burst; 46 bursts to go [Q N A I D G J H K M P B]
time 10141ms: Process E switching out of CPU; will block on I/O until time 10210ms [Q N A I D G J H K M P B]
time 10145ms: Process N started using the CPU for 131ms burst [Q A I D G J H K M P B]
time 10186ms: Process F completed I/O; added to ready queue [Q A I D G J H K M P B F]
time 10198ms: Process O completed I/O; added to ready queue [Q A I D G J H K M P B F O]
time 10210ms: Process E completed I/O; added to ready queue [Q A I D G J H K M P B F O E]
time 10273ms: Time slice expired; process N preempted with 3ms to go [Q A I D G J H K M P B F O E]
time 10277ms: Process A started using the CPU for 24ms burst [Q I D G J H K M P B F O E N]
time 10301ms: Process A completed a CPU burst; 6 bursts to go [Q I D G J H K M P B F O E N]
time 10301ms: Process A switching out of CPU; will block on I/O until time 10420ms [Q I D G J H K M P B F O E N]
time 10305ms: Process I started using the CPU for 70ms burst [Q D G J H K M P B F O E N]
time 10375ms: Process I completed a CPU burst; 68 bursts to go [Q D G J H K M P B F O E N]
time 10375ms: Process I switching out of CPU; will block on I/O until time 10531ms [Q D G J H K M P B F O E N]
time 10379ms: Process D started using the CPU for 23ms burst [Q G J H K M P B F O E N]
time 10402ms: Process D completed a CPU burst; 4 bursts to go [Q G J H K M P B F O E N]
time 10402ms: Process D switching out of CPU; will block on I/O until time 10598ms [Q G J H K M P B F O E N]
time 10406ms: Process G started using the CPU for 5ms burst [Q J H K M P B F O E N]
time 10411ms: Process G completed a CPU burst; 70 bursts to go [Q J H K M P B F O E N]
time 10411ms: Process G switching out of CPU; will block on I/O until time 10611ms [Q J H K M P B F O E N]
time 10415ms: Process J started using the CPU for 7ms burst [Q H K M P B F O E N]
time 10420ms: Process A completed I/O; added to ready queue [Q H K M P B F O E N A]
time 10422ms: Process J terminated [Q H K M P B F O E N A]
time 10426ms: Process H started using the CPU for 156ms burst [Q K M P B F O E N A]
time 10531ms: Process I completed I/O; added to ready queue [Q K M P B F O E N A I]
time 10554ms: Time slice expired; process H preempted with 28ms to go [Q K M P B F O E N A I]
time 10558ms: Process K started using the CPU for 21ms burst [Q M P B F O E N A I H]
time 10579ms: Process K completed a CPU burst; 3 bursts to go [Q M P B F O E N A I H]
time 10579ms: Process K switching out of CPU; will block on I/O until time 10646ms [Q M P B F O E N A I H]
time 10583ms: Process M started using the CPU for 117ms burst [Q P B F O E N A I H]
time 10598ms: Process D completed I/O; added to ready queue [Q P B F O E N A I H D]
time 10611ms: Process G completed I/O; added to ready queue [Q P B F O E N A I H D G]
time 10646ms: Process K completed I/O; added to ready queue [Q P B F O E N A I H D G K]
time 10700ms: Process M completed a CPU burst; 39 bursts to go [Q P B F O E N A I H D G K]
time 10700ms: Process M switching out of CPU; will block on I/O until time 10836ms [Q P B F O E N A I H D G K]
time 10704ms: Process P started using the CPU with 91ms burst remaining [Q B F O E N A I H D G K]
time 10795ms: Process P completed a CPU burst; 8 bursts to go [Q B F O E N A I H D G K]
time 10795ms: Process P switching out of CPU; will block on I/O until time 11002ms [Q B F O E N A I H D G K]
time 10799ms: Process B started using the CPU with 100ms burst remaining [Q F O E N A I H D G K]
time 10836ms: Process M completed I/O; added to ready queue [Q F O E N A I H D G K M]
time 10899ms: Process B completed a CPU burst; 13 bursts to go [Q F O E N A I H D G K M]
time 10899ms: Process B switching out of CPU; will block on I/O until time 10978ms [Q F O E N A I H D G K M]
time 10903ms: Process F started using the CPU for 76ms burst [Q O E N A I H D G K M]
time 10978ms: Process B completed I/O; added to ready queue [Q O E N A I H D G K M B]
time 10979ms: Process F completed a CPU burst; 26 bursts to go [Q O E N A I H D G K M B]
time 10979ms: Process F switching out of CPU; will block on I/O until time 11019ms [Q O E N A I H D G K M B]
time 10983ms: Process O started using the CPU for 69ms burst [Q E N A I H D G K M B]
time 11002ms: Process P completed I/O; added to ready queue [Q E N A I H D G K M B P]
time 11019ms: Process F completed I/O; added to ready queue [Q E N A I H D G K M B P F]
time 11052ms: Process O completed a CPU burst; 23 bursts to go [Q E N A I H D G K M B P F]
time 11052ms: Process O switching out of CPU; will block on I/O until time 11129ms [Q E N A I H D G K M B P F]
time 11056ms: Process E started using the CPU for 62ms burst [Q N A I H D G K M B P F]
time 11118ms: Process E completed a CPU burst; 45 bursts to go [Q N A I H D G K M B P F]
time 11118ms: Process E switching out of CPU; will block on I/O until time 11180ms [Q N A I H D G K M B P F]
time 11122ms: Process N started using the CPU with 3ms burst remaining [Q A I H D G K M B P F]
time 11125ms: Process N completed a CPU burst; 23 bursts to go [Q A I H D G K M B P F]
time 11125ms: Process N switching out of CPU; will block on I/O until time 11150ms [Q A I H D G K M B P F]
time 11129ms: Process A started using the CPU for 76ms burst [Q I H D G K M B P F]
time 11129ms: Process O completed I/O; added to ready queue [Q I H D G K M B P F O]
time 11150ms: Process N completed I/O; added to ready queue [Q I H D G K M B P F O N]
time 11180ms: Process E completed I/O; added to ready queue [Q I H D G K M B P F O N E]
time 11205ms: Process A completed a CPU burst; 5 bursts to go [Q I H D G K M B P F O N E]
time 11205ms: Process A switching out of CPU; will block on I/O until time 11235ms [Q I H D G K M B P F O N E]
time 11209ms: Process I started using the CPU for 107ms burst [Q H D G K M B P F O N E]
time 11235ms: Process A completed I/O; added to ready queue [Q H D G K M B P F O N E A]
time 11316ms: Process I completed a CPU burst; 67 bursts to go [Q H D G K M B P F O N E A]
time 11316ms: Process I switching out of CPU; will block on I/O until time 11365ms [Q H D G K M B P F O N E A]
time 11320ms: Process H started using the CPU with 28ms burst remaining [Q D G K M B P F O N E A]
time 11348ms: Process H completed a CPU burst; 73 bursts to go [Q D G K M B P F O N E A]
time 11348ms: Process H switching out of CPU; will block on I/O until time 11406ms [Q D G K M B P F O N E A]
time 11352ms: Process D started using the CPU for 76ms burst [Q G K M B P F O N E A]
time 11365ms: Process I completed I/O; added to ready queue [Q G K M B P F O N E A I]
time 11406ms: Process H completed I/O; added to ready queue [Q G K M B P F O N E A I H]
time 11428ms: Process D completed a CPU burst; 3 bursts to go [Q G K M B P F O N E A I H]
time 11428ms: Process D switching out of CPU; will block on I/O until time 11503ms [Q G K M B P F O N E A I H]
time 11432ms: Process G started using the CPU for 122ms burst [Q K M B P F O N E A I H]
time 11503ms: Process D completed I/O; added to ready queue [Q K M B P F O N E A I H D]
time 11554ms: Process G completed a CPU burst; 69 bursts to go [Q K M B P F O N E A I H D]
time 11554ms: Process G switching out of CPU; will block on I/O until time 11591ms [Q K M B P F O N E A I H D]
time 11558ms: Process K started using the CPU for 120ms burst [Q M B P F O N E A I H D]
time 11591ms: Process G completed I/O; added to ready queue [Q M B P F O N E A I H D G]
time 11678ms: Process K completed a CPU burst; 2 bursts to go [Q M B P F O N E A I H D G]
time 11678ms: Process K switching out of CPU; will block on I/O until time 11749ms [Q M B P F O N E A I H D G]
time 11682ms: Process M started using the CPU for 6ms burst [Q B P F O N E A I H D G]
time 11688ms: Process M completed a CPU burst; 38 bursts to go [Q B P F O N E A I H D G]
time 11688ms: Process M switching out of CPU; will block on I/O until time 11723ms [Q B P F O N E A I H D G]
time 11692ms: Process B started using the CPU for 138ms burst [Q P F O N E A I H D G]
time 11723ms: Process M completed I/O; added to ready queue [Q P F O N E A I H D G M]
time 11749ms: Process K completed I/O; added to ready queue [Q P F O N E A I H D G M K]
time 11820ms: Time slice expired; process B preempted with 10ms to go [Q P F O N E A I H D G M K]
time 11824ms: Process P started using the CPU for 70ms burst [Q F O N E A I H D G M K B]
time 11894ms: Process P completed a CPU burst; 7 bursts to go [Q F O N E A I H D G M K B]
time 11894ms: Process P switching out of CPU; will block on I/O until time 12023ms [Q F O N E A I H D G M K B]
time 11898ms: Process F started using the CPU for 107ms burst [Q O N E A I H D G M K B]
time 12005ms: Process F completed a CPU burst; 25 bursts to go [Q O N E A I H D G M K B]
time 12005ms: Process F switching out of CPU; will block on I/O until time 12025ms [Q O N E A I H D G M K B]
time 12009ms: Process O started using the CPU for 6ms burst [Q N E A I H D G M K B]
time 12015ms: Process O completed a CPU burst; 22 bursts to go [Q N E A I H D G M K B]
time 12015ms: Process O switching out of CPU; will block on I/O until time 12181ms [Q N E A I H D G M K B]
time 12019ms: Process N started using the CPU for 222ms burst [Q E A I H D G M K B]
time 12023ms: Process P completed I/O; added to ready queue [Q E A I H D G M K B P]
time 12025ms: Process F completed I/O; added to ready queue [Q E A I H D G M K B P F]
time 12147ms: Time slice expired; process N preempted with 94ms to go [Q E A I H D G M K B P F]
time 12151ms: Process E started using the CPU for 213ms burst [Q A I H D G M K B P F N]
time 12181ms: Process O completed I/O; added to ready queue [Q A I H D G M K B P F N O]
time 12279ms: Time slice expired; process E preempted with 85ms to go [Q A I H D G M K B P F N O]
time 12283ms: Process A started using the CPU for 122ms burst [Q I H D G M K B P F N O E]
time 12405ms: Process A completed a CPU burst; 4 bursts to go [Q I H D G M K B P F N O E]
time 12405ms: Process A switching out of CPU; will block on I/O until time 12440ms [Q I H D G M K B P F N O E]
time 12409ms: Process I started using the CPU for 21ms burst [Q H D G M K B P F N O E]
time 12430ms: Process I completed a CPU burst; 66 bursts to go [Q H D G M K B P F N O E]
time 12430ms: Process I switching out of CPU; will block on I/O until time 12441ms [Q H D G M K B P F N O E]
time 12434ms: Process H started using the CPU for 184ms burst [Q D G M K B P F N O E]
time 12440ms: Process A completed I/O; added to ready queue [Q D G M K B P F N O E A]
time 12441ms: Process I completed I/O; added to ready queue [Q D G M K B P F N O E A I]
time 12562ms: Time slice expired; process H preempted with 56ms to go [Q D G M K B P F N O E A I]
time 12566ms: Process D started using the CPU for 50ms burst [Q G M K B P F N O E A I H]
time 12616ms: Process D completed a CPU burst; 2 bursts to go [Q G M K B P F N O E A I H]
time 12616ms: Process D switching out of CPU; will block on I/O until time 12630ms [Q G M K B P F N O E A I H]
time 12620ms: Process G started using the CPU for 31ms burst [Q M K B P F N O E A I H]
time 12630ms: Process D completed I/O; added to ready queue [Q M K B P F N O E A I H D]
time 12651ms: Process G completed a CPU burst; 68 bursts to go [Q M K B P F N O E A I H D]
time 12651ms: Process G switching out of CPU; will block on I/O until time 12660ms [Q M K B P F N O E A I H D]
time 12655ms: Process M started using the CPU for 141ms burst [Q K B P F N O E A I H D]
time 12660ms: Process G completed I/O; added to ready queue [Q K B P F N O E A I H D G]
time 12783ms: Time slice expired; process M preempted with 13ms to go [Q K B P F N O E A I H D G]
time 12787ms: Process K started using the CPU for 199ms burst [Q B P F N O E A I H D G M]
time 12915ms: Time slice expired; process K preempted with 71ms to go [Q B P F N O E A I H D G M]
time 12919ms: Process B started using the CPU with 10ms burst remaining [Q P F N O E A I H D G M K]
time 12929ms: Process B completed a CPU burst; 12 bursts to go [Q P F N O E A I H D G M K]
time 12929ms: Process B switching out of CPU; will block on I/O until time 13013ms [Q P F N O E A I H D G M K]
time 12933ms: Process P started using the CPU for 55ms burst [Q F N O E A I H D G M K]
time 12988ms: Process P completed a CPU burst; 6 bursts to go [Q F N O E A I H D G M K]
time 12988ms: Process P switching out of CPU; will block on I/O until time 13235ms [Q F N O E A I H D G M K]
time 12992ms: Process F started using the CPU for 89ms burst [Q N O E A I H D G M K]
time 13013ms: Process B completed I/O; added to ready queue [Q N O E A I H D G M K B]
time 13081ms: Process F completed a CPU burst; 24 bursts to go [Q N O E A I H D G M K B]
time 13081ms: Process F switching out of CPU; will block on I/O until time 13166ms [Q N O E A I H D G M K B]
time 13085ms: Process N started using the CPU with 94ms burst remaining [Q O E A I H D G M K B]
time 13166ms: Process F completed I/O; added to ready queue [Q O E A I H D G M K B F]
time 13179ms: Process N completed a CPU burst; 22 bursts to go [Q O E A I H D G M K B F]
time 13179ms: Process N switching out of CPU; will block on I/O until time 13186ms [Q O E A I H D G M K B F]
time 13183ms: Process O started using the CPU for 187ms burst [Q E A I H D G M K B F]
time 13186ms: Process N completed I/O; added to ready queue [Q E A I H D G M K B F N]
time 13235ms: Process P completed I/O; added to ready queue [Q E A I H D G M K B F N P]
time 13311ms: Time slice expired; process O preempted with 59ms to go [Q E A I H D G M K B F N P]
time 13315ms: Process E started using the CPU with 85ms burst remaining [Q A I H D G M K B F N P O]
time 13400ms: Process E completed a CPU burst; 44 bursts to go [Q A I H D G M K B F N P O]
time 13400ms: Process E switching out of CPU; will block on I/O until time 13595ms [Q A I H D G M K B F N P O]
time 13404ms: Process A started using the CPU for 9ms burst [Q I H D G M K B F N P O]
time 13413ms: Process A completed a CPU burst; 3 bursts to go [Q I H D G M K B F N P O]
time 13413ms: Process A switching out of CPU; will block on I/O until time 13483ms [Q I H D G M K B F N P O]
time 13417ms: Process I started using the CPU for 179ms burst [Q H D G M K B F N P O]
time 13483ms: Process A completed I/O; added to ready queue [Q H D G M K B F N P O A]
time 13545ms: Time slice expired; process I preempted with 51ms to go [Q H D G M K B F N P O A]
time 13549ms: Process H started using the CPU with 56ms burst remaining [Q D G M K B F N P O A I]
time 13595ms: Process E completed I/O; added to ready queue [Q D G M K B F N P O A I E]
time 13605ms: Process H completed a CPU burst; 72 bursts to go [Q D G M K B F N P O A I E]
time 13605ms: Process H switching out of CPU; will block on I/O until time 13633ms [Q D G M K B F N P O A I E]
time 13609ms: Process D started using the CPU for 24ms burst [Q G M K B F N P O A I E]
time 13633ms: Process D completed a CPU burst; 1 burst to go [Q G M K B F N P O A I E]
time 13633ms: Process D switching out of CPU; will block on I/O until time 13660ms [Q G M K B F N P O A I E]
time 13633ms: Process H completed I/O; added to ready queue [Q G M K B F N P O A I E H]
time 13637ms: Process G started using the CPU for 61ms burst [Q M K B F N P O A I E H]
time 13660ms: Process D completed I/O; added to ready queue [Q M K B F N P O A I E H D]
time 13698ms: Process G completed a CPU burst; 67 bursts to go [Q M K B F N P O A I E H D]
time 13698ms: Process G switching out of CPU; will block on I/O until time 13774ms [Q M K B F N P O A I E H D]
time 13702ms: Process M started using the CPU with 13ms burst remaining [Q K B F N P O A I E H D]
time 13715ms: Process M completed a CPU burst; 37 bursts to go [Q K B F N P O A I E H D]
time 13715ms: Process M switching out of CPU; will block on I/O until time 13739ms [Q K B F N P O A I E H D]
time 13719ms: Process K started using the CPU with 71ms burst remaining [Q B F N P O A I E H D]
time 13739ms: Process M completed I/O; added to ready queue [Q B F N P O A I E H D M]
time 13774ms: Process G completed I/O; added to ready queue [Q B F N P O A I E H D M G]
time 13790ms: Process K completed a CPU burst; 1 burst to go [Q B F N P O A I E H D M G]
time 13790ms: Process K switching out of CPU; will block on I/O until time 13857ms [Q B F N P O A I E H D M G]
time 13794ms: Process B started using the CPU for 67ms burst [Q F N P O A I E H D M G]
time 13857ms: Process K completed I/O; added to ready queue [Q F N P O A I E H D M G K]
time 13861ms: Process B completed a CPU burst; 11 bursts to go [Q F N P O A I E H D M G K]
time 13861ms: Process B switching out of CPU; will block on I/O until time 13870ms [Q F N P O A I E H D M G K]
time 13865ms: Process F started using the CPU for 102ms burst [Q N P O A I E H D M G K]
time 13870ms: Process B completed I/O; added to ready queue [Q N P O A I E H D M G K B]
time 13967ms: Process F completed a CPU burst; 23 bursts to go [Q N P O A I E H D M G K B]
time 13967ms: Process F switching out of CPU; will block on I/O until time 14104ms [Q N P O A I E H D M G K B]
time 13971ms: Process N started using the CPU for 148ms burst [Q P O A I E H D M G K B]
time 14099ms: Time slice expired; process N preempted with 20ms to go [Q P O A I E H D M G K B]
time 14103ms: Process P started using the CPU for 212ms burst [Q O A I E H D M G K B N]
time 14104ms: Process F completed I/O; added to ready queue [Q O A I E H D M G K B N F]
time 14231ms: Time slice expired; process P preempted with 84ms to go [Q O A I E H D M G K B N F]
time 14235ms: Process O started using the CPU with 59ms burst remaining [Q A I E H D M G K B N F P]
time 14294ms: Process O completed a CPU burst; 21 bursts to go [Q A I E H D M G K B N F P]
time 14294ms: Process O switching out of CPU; will block on I/O until time 14463ms [Q A I E H D M G K B N F P]
time 14298ms: Process A started using the CPU for 62ms burst [Q I E H D M G K B N F P]
time 14360ms: Process A completed a CPU burst; 2 bursts to go [Q I E H D M G K B N F P]
time 14360ms: Process A switching out of CPU; will block on I/O until time 14439ms [Q I E H D M G K B N F P]
time 14364ms: Process I started using the CPU with 51ms burst remaining [Q E H D M G K B N F P]
time 14415ms: Process I completed a CPU burst; 65 bursts to go [Q E H D M G K B N F P]
time 14415ms: Process I switching out of CPU; will block on I/O until time 14517ms [Q E H D M G K B N F P]
time 14419ms: Process E started using the CPU for 54ms burst [Q H D M G K B N F P]
time 14439ms: Process A completed I/O; added to ready queue [Q H D M G K B N F P A]
time 14463ms: Process O completed I/O; added to ready queue [Q H D M G K B N F P A O]
time 14473ms: Process E completed a CPU burst; 43 bursts to go [Q H D M G K B N F P A O]
time 14473ms: Process E switching out of CPU; will block on I/O until time 14570ms [Q H D M G K B N F P A O]
time 14477ms: Process H started using the CPU for 2ms burst [Q D M G K B N F P A O]
time 14479ms: Process H completed a CPU burst; 71 bursts to go [Q D M G K B N F P A O]
time 14479ms: Process H switching out of CPU; will block on I/O until time 14495ms [Q D M G K B N F P A O]
time 14483ms: Process D started using the CPU for 1ms burst [Q M G K B N F P A O]
time 14484ms: Process D terminated [Q M G K B N F P A O]
time 14488ms: Process M started using the CPU for 13ms burst [Q G K B N F P A O]
time 14495ms: Process H completed I/O; added to ready queue [Q G K B N F P A O H]
time 14501ms: Process M completed a CPU burst; 36 bursts to go [Q G K B N F P A O H]
time 14501ms: Process M switching out of CPU; will block on I/O until time 14515ms [Q G K B N F P A O H]
time 14505ms: Process G started using the CPU for 7ms burst [Q K B N F P A O H]
time 14512ms: Process G completed a CPU burst; 66 bursts to go [Q K B N F P A O H]
time 14512ms: Process G switching out of CPU; will block on I/O until time 14678ms [Q K B N F P A O H]
time 14515ms: Process M completed I/O; added to ready queue [Q B N F P A O H M]
time 14516ms: Process K started using the CPU for 47ms burst [Q B N F P A O H M]
time 14517ms: Process I completed I/O; added to ready queue [Q B N F P A O H M I]
time 14563ms: Process K terminated [Q B N F P A O H M I]
time 14567ms: Process B started using the CPU for 120ms burst [Q N F P A O H M I]
time 14570ms: Process E completed I/O; added to ready queue [Q N F P A O H M I E]
time 14678ms: Process G completed I/O; added to ready queue [Q N F P A O H M I E G]
time 14687ms: Process B completed a CPU burst; 10 bursts to go [Q N F P A O H M I E G]
time 14687ms: Process B switching out of CPU; will block on I/O until time 14702ms [Q N F P A O H M I E G]
time 14691ms: Process N started using the CPU with 20ms burst remaining [Q F P A O H M I E G]
time 14702ms: Process B completed I/O; added to ready queue [Q F P A O H M I E G B]
time 14711ms: Process N completed a CPU burst; 21 bursts to go [Q F P A O H M I E G B]
time 14711ms: Process N switching out of CPU; will block on I/O until time 14851ms [Q F P A O H M I E G B]
time 14715ms: Process F started using the CPU for 147ms burst [Q P A O H M I E G B]
time 14843ms: Time slice expired; process F preempted with 19ms to go [Q P A O H M I E G B]
time 14847ms: Process P started using the CPU with 84ms burst remaining [Q A O H M I E G B F]
time 14851ms: Process N completed I/O; added to ready queue [Q A O H M I E G B F N]
time 14931ms: Process P completed a CPU burst; 5 bursts to go [Q A O H M I E G B F N]
time 14931ms: Process P switching out of CPU; will block on I/O until time 15150ms [Q A O H M I E G B F N]
time 14935ms: Process A started using the CPU for 200ms burst [Q O H M I E G B F N]
time 15063ms: Time slice expired; process A preempted with 72ms to go [Q O H M I E G B F N]
time 15067ms: Process O started using the CPU for 89ms burst [Q H M I E G B F N A]
time 15150ms: Process P completed I/O; added to ready queue [Q H M I E G B F N A P]
time 15156ms: Process O completed a CPU burst; 20 bursts to go [Q H M I E G B F N A P]
time 15156ms: Process O switching out of CPU; will block on I/O until time 15298ms [Q H M I E G B F N A P]
time 15160ms: Process H started using the CPU for 29ms burst [Q M I E G B F N A P]
time 15189ms: Process H completed a CPU burst; 70 bursts to go [Q M I E G B F N A P]
time 15189ms: Process H switching out of CPU; will block on I/O until time 15413ms [Q M I E G B F N A P]
time 15193ms: Process M started using the CPU for 103ms burst [Q I E G B F N A P]
time 15296ms: Process M completed a CPU burst; 35 bursts to go [Q I E G B F N A P]
time 15296ms: Process M switching out of CPU; will block on I/O until time 15312ms [Q I E G B F N A P]
time 15298ms: Process O completed I/O; added to ready queue [Q I E G B F N A P O]
time 15300ms: Process I started using the CPU for 65ms burst [Q E G B F N A P O]
time 15312ms: Process M completed I/O; added to ready queue [Q E G B F N A P O M]
time 15365ms: Process I completed a CPU burst; 64 bursts to go [Q E G B F N A P O M]
time 15365ms: Process I switching out of CPU; will block on I/O until time 15399ms [Q E G B F N A P O M]
time 15369ms: Process E started using the CPU for 126ms burst [Q G B F N A P O M]
time 15399ms: Process I completed I/O; added to ready queue [Q G B F N A P O M I]
time 15413ms: Process H completed I/O; added to ready queue [Q G B F N A P O M I H]
time 15495ms: Process E completed a CPU burst; 42 bursts to go [Q G B F N A P O M I H]
time 15495ms: Process E switching out of CPU; will block on I/O until time 15695ms [Q G B F N A P O M I H]
time 15499ms: Process G started using the CPU for 2ms burst [Q B F N A P O M I H]
time 15501ms: Process G completed a CPU burst; 65 bursts to go [Q B F N A P O M I H]
time 15501ms: Process G switching out of CPU; will block on I/O until time 15514ms [Q B F N A P O M I H]
time 15505ms: Process B started using the CPU for 49ms burst [Q F N A P O M I H]
time 15514ms: Process G completed I/O; added to ready queue [Q F N A P O M I H G]
time 15554ms: Process B completed a CPU burst; 9 bursts to go [Q F N A P O M I H G]
time 15554ms: Process B switching out of CPU; will block on I/O until time 15598ms [Q F N A P O M I H G]
time 15558ms: Process F started using the CPU with 19ms burst remaining [Q N A P O M I H G]
time 15577ms: Process F completed a CPU burst; 22 bursts to go [Q N A P O M I H G]
time 15577ms: Process F switching out of CPU; will block on I/O until time 15584ms [Q N A P O M I H G]
time 15581ms: Process N started using the CPU for 32ms burst [Q A P O M I H G]
time 15584ms: Process F completed I/O; added to ready queue [Q A P O M I H G F]
time 15598ms: Process B completed I/O; added to ready queue [Q A P O M I H G F B]
time 15613ms: Process N completed a CPU burst; 20 bursts to go [Q A P O M I H G F B]
time 15613ms: Process N switching out of CPU; will block on I/O until time 15773ms [Q A P O M I H G F B]
time 15617ms: Process A started using the CPU with 72ms burst remaining [Q P O M I H G F B]
time 15689ms: Process A completed a CPU burst; 1 burst to go [Q P O M I H G F B]
time 15689ms: Process A switching out of CPU; will block on I/O until time 15702ms [Q P O M I H G F B]
time 15693ms: Process P started using the CPU for 83ms burst [Q O M I H G F B]
time 15695ms: Process E completed I/O; added to ready queue [Q O M I H G F B E]
time 15702ms: Process A completed I/O; added to ready queue [Q O M I H G F B E A]
time 15773ms: Process N completed I/O; added to ready queue [Q O M I H G F B E A N]
time 15776ms: Process P completed a CPU burst; 4 bursts to go [Q O M I H G F B E A N]
time 15776ms: Process P switching out of CPU; will block on I/O until time 15805ms [Q O M I H G F B E A N]
time 15780ms: Process O started using the CPU for 45ms burst [Q M I H G F B E A N]
time 15805ms: Process P completed I/O; added to ready queue [Q M I H G F B E A N P]
time 15825ms: Process O completed a CPU burst; 19 bursts to go [Q M I H G F B E A N P]
time 15825ms: Process O switching out of CPU; will block on I/O until time 15873ms [Q M I H G F B E A N P]
time 15829ms: Process M started using the CPU for 15ms burst [Q I H G F B E A N P]
time 15844ms: Process M completed a CPU burst; 34 bursts to go [Q I H G F B E A N P]
time 15844ms: Process M switching out of CPU; will block on I/O until time 15957ms [Q I H G F B E A N P]
time 15848ms: Process I started using the CPU for 58ms burst [Q H G F B E A N P]
time 15873ms: Process O completed I/O; added to ready queue [Q H G F B E A N P O]
time 15906ms: Process I completed a CPU burst; 63 bursts to go [Q H G F B E A N P O]
time 15906ms: Process I switching out of CPU; will block on I/O until time 16082ms [Q H G F B E A N P O]
time 15910ms: Process H started using the CPU for 76ms burst [Q G F B E A N P O]
time 15957ms: Process M completed I/O; added to ready queue [Q G F B E A N P O M]
time 15986ms: Process H completed a CPU burst; 69 bursts to go [Q G F B E A N P O M]
time 15986ms: Process H switching out of CPU; will block on I/O until time 16200ms [Q G F B E A N P O M]
time 15990ms: Process G started using the CPU for 209ms burst [Q F B E A N P O M]
time 16082ms: Process I completed I/O; added to ready queue [Q F B E A N P O M I]
time 16118ms: Time slice expired; process G preempted with 81ms to go [Q F B E A N P O M I]
time 16122ms: Process F started using the CPU for 97ms burst [Q B E A N P O M I G]
time 16200ms: Process H completed I/O; added to ready queue [Q B E A N P O M I G H]
time 16219ms: Process F completed a CPU burst; 21 bursts to go [Q B E A N P O M I G H]
time 16219ms: Process F switching out of CPU; will block on I/O until time 16225ms [Q B E A N P O M I G H]
time 16223ms: Process B started using the CPU for 134ms burst [Q E A N P O M I G H]
time 16225ms: Process F completed I/O; added to ready queue [Q E A N P O M I G H F]
time 16351ms: Time slice expired; process B preempted with 6ms to go [Q E A N P O M I G H F]
time 16355ms: Process E started using the CPU for 168ms burst [Q A N P O M I G H F B]
time 16483ms: Time slice expired; process E preempted with 40ms to go [Q A N P O M I G H F B]
time 16487ms: Process A started using the CPU for 197ms burst [Q N P O M I G H F B E]
time 16615ms: Time slice expired; process A preempted with 69ms to go [Q N P O M I G H F B E]
time 16619ms: Process N started using the CPU for 97ms burst [Q P O M I G H F B E A]
time 16716ms: Process N completed a CPU burst; 19 bursts to go [Q P O M I G H F B E A]
time 16716ms: Process N switching out of CPU; will block on I/O until time 16809ms [Q P O M I G H F B E A]
time 16720ms: Process P started using the CPU for 75ms burst [Q O M I G H F B E A]
time 16795ms: Process P completed a CPU burst; 3 bursts to go [Q O M I G H F B E A]
time 16795ms: Process P switching out of CPU; will block on I/O until time 16815ms [Q O M I G H F B E A]
time 16799ms: Process O started using the CPU for 50ms burst [Q M I G H F B E A]
time 16809ms: Process N completed I/O; added to ready queue [Q M I G H F B E A N]
time 16815ms: Process P completed I/O; added to ready queue [Q M I G H F B E A N P]
time 16849ms: Process O completed a CPU burst; 18 bursts to go [Q M I G H F B E A N P]
time 16849ms: Process O switching out of CPU; will block on I/O until time 16962ms [Q M I G H F B E A N P]
time 16853ms: Process M started using the CPU for 26ms burst [Q I G H F B E A N P]
time 16879ms: Process M completed a CPU burst; 33 bursts to go [Q I G H F B E A N P]
time 16879ms: Process M switching out of CPU; will block on I/O until time 16941ms [Q I G H F B E A N P]
time 16883ms: Process I started using the CPU for 95ms burst [Q G H F B E A N P]
time 16941ms: Process M completed I/O; added to ready queue [Q G H F B E A N P M]
time 16962ms: Process O completed I/O; added to ready queue [Q G H F B E A N P M O]
time 16978ms: Process I completed a CPU burst; 62 bursts to go [Q G H F B E A N P M O]
time 16978ms: Process I switching out of CPU; will block on I/O until time 17122ms [Q G H F B E A N P M O]
time 16982ms: Process G started using the CPU with 81ms burst remaining [Q H F B E A N P M O]
time 17063ms: Process G completed a CPU burst; 64 bursts to go [Q H F B E A N P M O]
time 17063ms: Process G switching out of CPU; will block on I/O until time 17113ms [Q H F B E A N P M O]
time 17067ms: Process H started using the CPU for 143ms burst [Q F B E A N P M O]
time 17113ms: Process G completed I/O; added to ready queue [Q F B E A N P M O G]
time 17122ms: Process I completed I/O; added to ready queue [Q F B E A N P M O G I]
time 17195ms: Time slice expired; process H preempted with 15ms to go [Q F B E A N P M O G I]
time 17199ms: Process F started using the CPU for 157ms burst [Q B E A N P M O G I H]
time 17327ms: Time slice expired; process F preempted with 29ms to go [Q B E A N P M O G I H]
time 17331ms: Process B started using the CPU with 6ms burst remaining [Q E A N P M O G I H F]
time 17337ms: Process B completed a CPU burst; 8 bursts to go [Q E A N P M O G I H F]
time 17337ms: Process B switching out of CPU; will block on I/O until time 17371ms [Q E A N P M O G I H F]
time 17341ms: Process E started using the CPU with 40ms burst remaining [Q A N P M O G I H F]
time 17371ms: Process B completed I/O; added to ready queue [Q A N P M O G I H F B]
time 17381ms: Process E completed a CPU burst; 41 bursts to go [Q A N P M O G I H F B]
time 17381ms: Process E switching out of CPU; will block on I/O until time 17433ms [Q A N P M O G I H F B]
time 17385ms: Process A started using the CPU with 69ms burst remaining [Q N P M O G I H F B]
time 17433ms: Process E completed I/O; added to ready queue [Q N P M O G I H F B E]
time 17454ms: Process A terminated [Q N P M O G I H F B E]
time 17458ms: Process N started using the CPU for 39ms burst [Q P M O G I H F B E]
time 17497ms: Process N completed a CPU burst; 18 bursts to go [Q P M O G I H F B E]
time 17497ms: Process N switching out of CPU; will block on I/O until time 17500ms [Q P M O G I H F B E]
time 17500ms: Process N completed I/O; added to ready queue [Q M O G I H F B E N]
time 17501ms: Process P started using the CPU for 1ms burst [Q M O G I H F B E N]
time 17502ms: Process P completed a CPU burst; 2 bursts to go [Q M O G I H F B E N]
time 17502ms: Process P switching out of CPU; will block on I/O until time 17522ms [Q M O G I H F B E N]
time 17506ms: Process M started using the CPU for 74ms burst [Q O G I H F B E N]
time 17522ms: Process P completed I/O; added to ready queue [Q O G I H F B E N P]
time 17580ms: Process M completed a CPU burst; 32 bursts to go [Q O G I H F B E N P]
time 17580ms: Process M switching out of CPU; will block on I/O until time 17703ms [Q O G I H F B E N P]
time 17584ms: Process O started using the CPU for 133ms burst [Q G I H F B E N P]
time 17703ms: Process M completed I/O; added to ready queue [Q G I H F B E N P M]
time 17712ms: Time slice expired; process O preempted with 5ms to go [Q G I H F B E N P M]
time 17716ms: Process G started using the CPU for 6ms burst [Q I H F B E N P M O]
time 17722ms: Process G completed a CPU burst; 63 bursts to go [Q I H F B E N P M O]
time 17722ms: Process G switching out of CPU; will block on I/O until time 17872ms [Q I H F B E N P M O]
time 17726ms: Process I started using the CPU for 78ms burst [Q H F B E N P M O]
time 17804ms: Process I completed a CPU burst; 61 bursts to go [Q H F B E N P M O]
time 17804ms: Process I switching out of CPU; will block on I/O until time 17883ms [Q H F B E N P M O]
time 17808ms: Process H started using the CPU with 15ms burst remaining [Q F B E N P M O]
time 17823ms: Process H completed a CPU burst; 68 bursts to go [Q F B E N P M O]
time 17823ms: Process H switching out of CPU; will block on I/O until time 18009ms [Q F B E N P M O]
time 17827ms: Process F started using the CPU with 29ms burst remaining [Q B E N P M O]
time 17856ms: Process F completed a CPU burst; 20 bursts to go [Q B E N P M O]
time 17856ms: Process F switching out of CPU; will block on I/O until time 17868ms [Q B E N P M O]
time 17860ms: Process B started using the CPU for 144ms burst [Q E N P M O]
time 17868ms: Process F completed I/O; added to ready queue [Q E N P M O F]
time 17872ms: Process G completed I/O; added to ready queue [Q E N P M O F G]
time 17883ms: Process I completed I/O; added to ready queue [Q E N P M O F G I]
time 17988ms: Time slice expired; process B preempted with 16ms to go [Q E N P M O F G I]
time 17992ms: Process E started using the CPU for 23ms burst [Q N P M O F G I B]
time 18009ms: Process H completed I/O; added to ready queue [Q N P M O F G I B H]
time 18015ms: Process E completed a CPU burst; 40 bursts to go [Q N P M O F G I B H]
time 18015ms: Process E switching out of CPU; will block on I/O until time 18026ms [Q N P M O F G I B H]
time 18019ms: Process N started using the CPU for 137ms burst [Q P M O F G I B H]
time 18026ms: Process E completed I/O; added to ready queue [Q P M O F G I B H E]
time 18147ms: Time slice expired; process N preempted with 9ms to go [Q P M O F G I B H E]
time 18151ms: Process P started using the CPU for 131ms burst [Q M O F G I B H E N]
time 18279ms: Time slice expired; process P preempted with 3ms to go [Q M O F G I B H E N]
time 18283ms: Process M started using the CPU for 6ms burst [Q O F G I B H E N P]
time 18289ms: Process M completed a CPU burst; 31 bursts to go [Q O F G I B H E N P]
time 18289ms: Process M switching out of CPU; will block on I/O until time 18395ms [Q O F G I B H E N P]
time 18293ms: Process O started using the CPU with 5ms burst remaining [Q F G I B H E N P]
time 18298ms: Process O completed a CPU burst; 17 bursts to go [Q F G I B H E N P]
time 18298ms: Process O switching out of CPU; will block on I/O until time 18428ms [Q F G I B H E N P]
time 18302ms: Process F started using the CPU for 24ms burst [Q G I B H E N P]
time 18326ms: Process F completed a CPU burst; 19 bursts to go [Q G I B H E N P]
time 18326ms: Process F switching out of CPU; will block on I/O until time 18425ms [Q G I B H E N P]
time 18330ms: Process G started using the CPU for 37ms burst [Q I B H E N P]
time 18367ms: Process G completed a CPU burst; 62 bursts to go [Q I B H E N P]
time 18367ms: Process G switching out of CPU; will block on I/O until time 18500ms [Q I B H E N P]
time 18371ms: Process I started using the CPU for 31ms burst [Q B H E N P]
time 18395ms: Process M completed I/O; added to ready queue [Q B H E N P M]
time 18402ms: Process I completed a CPU burst; 60 bursts to go [Q B H E N P M]
time 18402ms: Process I switching out of CPU; will block on I/O until time 18513ms [Q B H E N P M]
time 18406ms: Process B started using the CPU with 16ms burst remaining [Q H E N P M]
time 18422ms: Process B completed a CPU burst; 7 bursts to go [Q H E N P M]
time 18422ms: Process B switching out of CPU; will block on I/O until time 18503ms [Q H E N P M]
time 18425ms: Process F completed I/O; added to ready queue [Q E N P M F]
time 18426ms: Process H started using the CPU for 32ms burst [Q E N P M F]
time 18428ms: Process O completed I/O; added to ready queue [Q E N P M F O]
time 18458ms: Process H completed a CPU burst; 67 bursts to go [Q E N P M F O]
time 18458ms: Process H switching out of CPU; will block on I/O until time 18542ms [Q E N P M F O]
time 18462ms: Process E started using the CPU for 68ms burst [Q N P M F O]
time 18500ms: Process G completed I/O; added to ready queue [Q N P M F O G]
time 18503ms: Process B completed I/O; added to ready queue [Q N P M F O G B]
time 18513ms: Process I completed I/O; added to ready queue [Q N P M F O G B I]
time 18530ms: Process E completed a CPU burst; 39 bursts to go [Q N P M F O G B I]
time 18530ms: Process E switching out of CPU; will block on I/O until time 18590ms [Q N P M F O G B I]
time 18534ms: Process N started using the CPU with 9ms burst remaining [Q P M F O G B I]
time 18542ms: Process H completed I/O; added to ready queue [Q P M F O G B I H]
time 18543ms: Process N completed a CPU burst; 17 bursts to go [Q P M F O G B I H]
time 18543ms: Process N switching out of CPU; will block on I/O until time 18564ms [Q P M F O G B I H]
time 18547ms: Process P started using the CPU with 3ms burst remaining [Q M F O G B I H]
time 18550ms: Process P completed a CPU burst; 1 burst to go [Q M F O G B I H]
time 18550ms: Process P switching out of CPU; will block on I/O until time 18597ms [Q M F O G B I H]
time 18554ms: Process M started using the CPU for 216ms burst [Q F O G B I H]
time 18564ms: Process N completed I/O; added to ready queue [Q F O G B I H N]
time 18590ms: Process E completed I/O; added to ready queue [Q F O G B I H N E]
time 18597ms: Process P completed I/O; added to ready queue [Q F O G B I H N E P]
time 18682ms: Time slice expired; process M preempted with 88ms to go [Q F O G B I H N E P]
time 18686ms: Process F started using the CPU for 31ms burst [Q O G B I H N E P M]
time 18717ms: Process F completed a CPU burst; 18 bursts to go [Q O G B I H N E P M]
time 18717ms: Process F switching out of CPU; will block on I/O until time 18740ms [Q O G B I H N E P M]
time 18721ms: Process O started using the CPU for 74ms burst [Q G B I H N E P M]
time 18740ms: Process F completed I/O; added to ready queue [Q G B I H N E P M F]
time 18795ms: Process O completed a CPU burst; 16 bursts to go [Q G B I H N E P M F]
time 18795ms: Process O switching out of CPU; will block on I/O until time 18886ms [Q G B I H N E P M F]
time 18799ms: Process G started using the CPU for 15ms burst [Q B I H N E P M F]
time 18814ms: Process G completed a CPU burst; 61 bursts to go [Q B I H N E P M F]
time 18814ms: Process G switching out of CPU; will block on I/O until time 18838ms [Q B I H N E P M F]
time 18818ms: Process B started using the CPU for 183ms burst [Q I H N E P M F]
time 18838ms: Process G completed I/O; added to ready queue [Q I H N E P M F G]
time 18886ms: Process O completed I/O; added to ready queue [Q I H N E P M F G O]
time 18946ms: Time slice expired; process B preempted with 55ms to go [Q I H N E P M F G O]
time 18950ms: Process I started using the CPU for 97ms burst [Q H N E P M F G O B]
time 19047ms: Process I completed a CPU burst; 59 bursts to go [Q H N E P M F G O B]
time 19047ms: Process I switching out of CPU; will block on I/O until time 19067ms [Q H N E P M F G O B]
time 19051ms: Process H started using the CPU for 78ms burst [Q N E P M F G O B]
time 19067ms: Process I completed I/O; added to ready queue [Q N E P M F G O B I]
time 19129ms: Process H completed a CPU burst; 66 bursts to go [Q N E P M F G O B I]
time 19129ms: Process H switching out of CPU; will block on I/O until time 19137ms [Q N E P M F G O B I]
time 19133ms: Process N started using the CPU for 189ms burst [Q E P M F G O B I]
time 19137ms: Process H completed I/O; added to ready queue [Q E P M F G O B I H]
time 19261ms: Time slice expired; process N preempted with 61ms to go [Q E P M F G O B I H]
time 19265ms: Process E started using the CPU for 41ms burst [Q P M F G O B I H N]
time 19306ms: Process E completed a CPU burst; 38 bursts to go [Q P M F G O B I H N]
time 19306ms: Process E switching out of CPU; will block on I/O until time 19328ms [Q P M F G O B I H N]
time 19310ms: Process P started using the CPU for 9ms burst [Q M F G O B I H N]
time 19319ms: Process P terminated [Q M F G O B I H N]
time 19323ms: Process M started using the CPU with 88ms burst remaining [Q F G O B I H N]
time 19328ms: Process E completed I/O; added to ready queue [Q F G O B I H N E]
time 19411ms: Process M completed a CPU burst; 30 bursts to go [Q F G O B I H N E]
time 19411ms: Process M switching out of CPU; will block on I/O until time 19533ms [Q F G O B I H N E]
time 19415ms: Process F started using the CPU for 24ms burst [Q G O B I H N E]
time 19439ms: Process F completed a CPU burst; 17 bursts to go [Q G O B I H N E]
time 19439ms: Process F switching out of CPU; will block on I/O until time 19500ms [Q G O B I H N E]
time 19443ms: Process G started using the CPU for 47ms burst [Q O B I H N E]
time 19490ms: Process G completed a CPU burst; 60 bursts to go [Q O B I H N E]
time 19490ms: Process G switching out of CPU; will block on I/O until time 19568ms [Q O B I H N E]
time 19494ms: Process O started using the CPU for 41ms burst [Q B I H N E]
time 19500ms: Process F completed I/O; added to ready queue [Q B I H N E F]
time 19533ms: Process M completed I/O; added to ready queue [Q B I H N E F M]
time 19535ms: Process O completed a CPU burst; 15 bursts to go [Q B I H N E F M]
time 19535ms: Process O switching out of CPU; will block on I/O until time 19594ms [Q B I H N E F M]
time 19539ms: Process B started using the CPU with 55ms burst remaining [Q I H N E F M]
time 19568ms: Process G completed I/O; added to ready queue [Q I H N E F M G]
time 19594ms: Process B completed a CPU burst; 6 bursts to go [Q I H N E F M G]
time 19594ms: Process B switching out of CPU; will block on I/O until time 19602ms [Q I H N E F M G]
time 19594ms: Process O completed I/O; added to ready queue [Q I H N E F M G O]
time 19598ms: Process I started using the CPU for 103ms burst [Q H N E F M G O]
time 19602ms: Process B completed I/O; added to ready queue [Q H N E F M G O B]
time 19701ms: Process I completed a CPU burst; 58 bursts to go [Q H N E F M G O B]
time 19701ms: Process I switching out of CPU; will block on I/O until time 19790ms [Q H N E F M G O B]
time 19705ms: Process H started using the CPU for 16ms burst [Q N E F M G O B]
time 19721ms: Process H completed a CPU burst; 65 bursts to go [Q N E F M G O B]
time 19721ms: Process H switching out of CPU; will block on I/O until time 19778ms [Q N E F M G O B]
time 19725ms: Process N started using the CPU with 61ms burst remaining [Q E F M G O B]
time 19778ms: Process H completed I/O; added to ready queue [Q E F M G O B H]
time 19786ms: Process N completed a CPU burst; 16 bursts to go [Q E F M G O B H]
time 19786ms: Process N switching out of CPU; will block on I/O until time 19951ms [Q E F M G O B H]
time 19790ms: Process E started using the CPU for 44ms burst [Q F M G O B H]
time 19790ms: Process I completed I/O; added to ready queue [Q F M G O B H I]
time 19834ms: Process E completed a CPU burst; 37 bursts to go [Q F M G O B H I]
time 19834ms: Process E switching out of CPU; will block on I/O until time 19897ms [Q F M G O B H I]
time 19838ms: Process F started using the CPU for 135ms burst [Q M G O B H I]
time 19897ms: Process E completed I/O; added to ready queue [Q M G O B H I E]
time 19951ms: Process N completed I/O; added to ready queue [Q M G O B H I E N]
time 19966ms: Time slice expired; process F preempted with 7ms to go [Q M G O B H I E N]
time 19970ms: Process M started using the CPU for 3ms burst [Q G O B H I E N F]
time 19973ms: Process M completed a CPU burst; 29 bursts to go [Q G O B H I E N F]
time 19973ms: Process M switching out of CPU; will block on I/O until time 20000ms [Q G O B H I E N F]
time 19977ms: Process G started using the CPU for 82ms burst [Q O B H I E N F]
time 20000ms: Process M completed I/O; added to ready queue [Q O B H I E N F M]
time 20059ms: Process G completed a CPU burst; 59 bursts to go [Q O B H I E N F M]
time 20059ms: Process G switching out of CPU; will block on I/O until time 20064ms [Q O B H I E N F M]
time 20063ms: Process O started using the CPU for 57ms burst [Q B H I E N F M]
time 20064ms: Process G completed I/O; added to ready queue [Q B H I E N F M G]
time 20120ms: Process O completed a CPU burst; 14 bursts to go [Q B H I E N F M G]
time 20120ms: Process O switching out of CPU; will block on I/O until time 20150ms [Q B H I E N F M G]
time 20124ms: Process B started using the CPU for 219ms burst [Q H I E N F M G]
time 20150ms: Process O completed I/O; added to ready queue [Q H I E N F M G O]
