Process A [NEW] (arrival time 102 ms) 85 CPU bursts 
Process B [NEW] (arrival time 365 ms) 6 CPU bursts 
Process C [NEW] (arrival time 246 ms) 95 CPU bursts 
Process D [NEW] (arrival time 388 ms) 57 CPU bursts 
Process E [NEW] (arrival time 1515 ms) 83 CPU bursts 
Process F [NEW] (arrival time 1684 ms) 97 CPU bursts 
Process G [NEW] (arrival time 669 ms) 1 CPU bursts 
Process H [NEW] (arrival time 376 ms) 49 CPU bursts 
time 0ms: Simulator started for RR [Q <empty>]
time 102ms: Process A arrived; added to ready queue [Q A]
time 104ms: Process A started using the CPU for 1031ms burst [Q <empty>]
time 246ms: Process C arrived; added to ready queue [Q C]
time 365ms: Process B arrived; added to ready queue [Q C B]
time 376ms: Process H arrived; added to ready queue [Q C B H]
time 388ms: Process D arrived; added to ready queue [Q C B H D]
time 669ms: Process G arrived; added to ready queue [Q C B H D G]
time 1135ms: Process A completed a CPU burst; 84 bursts to go [Q C B H D G]
time 1135ms: Process A switching out of CPU; will block on I/O until time 1547ms [Q C B H D G]
time 1139ms: Process C started using the CPU for 3274ms burst [Q B H D G]
time 1515ms: Process E arrived; added to ready queue [Q B H D G E]
time 1547ms: Process A completed I/O; added to ready queue [Q B H D G E A]
time 1684ms: Process F arrived; added to ready queue [Q B H D G E A F]
time 3187ms: Time slice expired; process C preempted with 1226ms to go [Q B H D G E A F]
time 3191ms: Process B started using the CPU for 848ms burst [Q H D G E A F C]
time 4039ms: Process B completed a CPU burst; 5 bursts to go [Q H D G E A F C]
time 4039ms: Process B switching out of CPU; will block on I/O until time 4987ms [Q H D G E A F C]
time 4043ms: Process H started using the CPU for 340ms burst [Q D G E A F C]
time 4383ms: Process H completed a CPU burst; 48 bursts to go [Q D G E A F C]
time 4383ms: Process H switching out of CPU; will block on I/O until time 5001ms [Q D G E A F C]
time 4387ms: Process D started using the CPU for 722ms burst [Q G E A F C]
time 4987ms: Process B completed I/O; added to ready queue [Q G E A F C B]
time 5001ms: Process H completed I/O; added to ready queue [Q G E A F C B H]
time 5109ms: Process D completed a CPU burst; 56 bursts to go [Q G E A F C B H]
time 5109ms: Process D switching out of CPU; will block on I/O until time 6199ms [Q G E A F C B H]
time 5113ms: Process G started using the CPU for 543ms burst [Q E A F C B H]
time 5656ms: Process G terminated [Q E A F C B H]
time 5660ms: Process E started using the CPU for 391ms burst [Q A F C B H]
time 6051ms: Process E completed a CPU burst; 82 bursts to go [Q A F C B H]
time 6051ms: Process E switching out of CPU; will block on I/O until time 6614ms [Q A F C B H]
time 6055ms: Process A started using the CPU for 197ms burst [Q F C B H]
time 6199ms: Process D completed I/O; added to ready queue [Q F C B H D]
time 6252ms: Process A completed a CPU burst; 83 bursts to go [Q F C B H D]
time 6252ms: Process A switching out of CPU; will block on I/O until time 6753ms [Q F C B H D]
time 6256ms: Process F started using the CPU for 18ms burst [Q C B H D]
time 6274ms: Process F completed a CPU burst; 96 bursts to go [Q C B H D]
time 6274ms: Process F switching out of CPU; will block on I/O until time 7836ms [Q C B H D]
time 6278ms: Process C started using the CPU with 1226ms burst remaining [Q B H D]
time 6614ms: Process E completed I/O; added to ready queue [Q B H D E]
time 6753ms: Process A completed I/O; added to ready queue [Q B H D E A]
time 7504ms: Process C completed a CPU burst; 94 bursts to go [Q B H D E A]
time 7504ms: Process C switching out of CPU; will block on I/O until time 7596ms [Q B H D E A]
time 7508ms: Process B started using the CPU for 859ms burst [Q H D E A]
time 7596ms: Process C completed I/O; added to ready queue [Q H D E A C]
time 7836ms: Process F completed I/O; added to ready queue [Q H D E A C F]
time 8367ms: Process B completed a CPU burst; 4 bursts to go [Q H D E A C F]
time 8367ms: Process B switching out of CPU; will block on I/O until time 9041ms [Q H D E A C F]
time 8371ms: Process H started using the CPU for 264ms burst [Q D E A C F]
time 8635ms: Process H completed a CPU burst; 47 bursts to go [Q D E A C F]
time 8635ms: Process H switching out of CPU; will block on I/O until time 8774ms [Q D E A C F]
time 8639ms: Process D started using the CPU for 293ms burst [Q E A C F]
time 8774ms: Process H completed I/O; added to ready queue [Q E A C F H]
time 8932ms: Process D completed a CPU burst; 55 bursts to go [Q E A C F H]
time 8932ms: Process D switching out of CPU; will block on I/O until time 9247ms [Q E A C F H]
time 8936ms: Process E started using the CPU for 1198ms burst [Q A C F H]
time 9041ms: Process B completed I/O; added to ready queue [Q A C F H B]
time 9247ms: Process D completed I/O; added to ready queue [Q A C F H B D]
time 10134ms: Process E completed a CPU burst; 81 bursts to go [Q A C F H B D]
time 10134ms: Process E switching out of CPU; will block on I/O until time 13307ms [Q A C F H B D]
time 10138ms: Process A started using the CPU for 923ms burst [Q C F H B D]
time 11061ms: Process A completed a CPU burst; 82 bursts to go [Q C F H B D]
time 11061ms: Process A switching out of CPU; will block on I/O until time 12925ms [Q C F H B D]
time 11065ms: Process C started using the CPU for 633ms burst [Q F H B D]
time 11698ms: Process C completed a CPU burst; 93 bursts to go [Q F H B D]
time 11698ms: Process C switching out of CPU; will block on I/O until time 11744ms [Q F H B D]
time 11702ms: Process F started using the CPU for 1494ms burst [Q H B D]
time 11744ms: Process C completed I/O; added to ready queue [Q H B D C]
time 12925ms: Process A completed I/O; added to ready queue [Q H B D C A]
time 13196ms: Process F completed a CPU burst; 95 bursts to go [Q H B D C A]
time 13196ms: Process F switching out of CPU; will block on I/O until time 13321ms [Q H B D C A]
time 13200ms: Process H started using the CPU for 1555ms burst [Q B D C A]
time 13307ms: Process E completed I/O; added to ready queue [Q B D C A E]
time 13321ms: Process F completed I/O; added to ready queue [Q B D C A E F]
time 14755ms: Process H completed a CPU burst; 46 bursts to go [Q B D C A E F]
time 14755ms: Process H switching out of CPU; will block on I/O until time 15221ms [Q B D C A E F]
time 14759ms: Process B started using the CPU for 2199ms burst [Q D C A E F]
time 15221ms: Process H completed I/O; added to ready queue [Q D C A E F H]
time 16807ms: Time slice expired; process B preempted with 151ms to go [Q D C A E F H]
time 16811ms: Process D started using the CPU for 375ms burst [Q C A E F H B]
time 17186ms: Process D completed a CPU burst; 54 bursts to go [Q C A E F H B]
time 17186ms: Process D switching out of CPU; will block on I/O until time 18015ms [Q C A E F H B]
time 17190ms: Process C started using the CPU for 512ms burst [Q A E F H B]
time 17702ms: Process C completed a CPU burst; 92 bursts to go [Q A E F H B]
time 17702ms: Process C switching out of CPU; will block on I/O until time 19296ms [Q A E F H B]
time 17706ms: Process A started using the CPU for 25ms burst [Q E F H B]
time 17731ms: Process A completed a CPU burst; 81 bursts to go [Q E F H B]
time 17731ms: Process A switching out of CPU; will block on I/O until time 18426ms [Q E F H B]
time 17735ms: Process E started using the CPU for 1339ms burst [Q F H B]
time 18015ms: Process D completed I/O; added to ready queue [Q F H B D]
time 18426ms: Process A completed I/O; added to ready queue [Q F H B D A]
time 19074ms: Process E completed a CPU burst; 80 bursts to go [Q F H B D A]
time 19074ms: Process E switching out of CPU; will block on I/O until time 20146ms [Q F H B D A]
time 19078ms: Process F started using the CPU for 315ms burst [Q H B D A]
time 19296ms: Process C completed I/O; added to ready queue [Q H B D A C]
time 19393ms: Process F completed a CPU burst; 94 bursts to go [Q H B D A C]
time 19393ms: Process F switching out of CPU; will block on I/O until time 19862ms [Q H B D A C]
time 19397ms: Process H started using the CPU for 2705ms burst [Q B D A C]
time 19862ms: Process F completed I/O; added to ready queue [Q B D A C F]
time 20146ms: Process E completed I/O; added to ready queue [Q B D A C F E]
time 21445ms: Time slice expired; process H preempted with 657ms to go [Q B D A C F E]
time 21449ms: Process B started using the CPU with 151ms burst remaining [Q D A C F E H]
time 21600ms: Process B completed a CPU burst; 3 bursts to go [Q D A C F E H]
time 21600ms: Process B switching out of CPU; will block on I/O until time 21989ms [Q D A C F E H]
time 21604ms: Process D started using the CPU for 245ms burst [Q A C F E H]
time 21849ms: Process D completed a CPU burst; 53 bursts to go [Q A C F E H]
time 21849ms: Process D switching out of CPU; will block on I/O until time 22155ms [Q A C F E H]
time 21853ms: Process A started using the CPU for 977ms burst [Q C F E H]
time 21989ms: Process B completed I/O; added to ready queue [Q C F E H B]
time 22155ms: Process D completed I/O; added to ready queue [Q C F E H B D]
time 22830ms: Process A completed a CPU burst; 80 bursts to go [Q C F E H B D]
time 22830ms: Process A switching out of CPU; will block on I/O until time 23726ms [Q C F E H B D]
time 22834ms: Process C started using the CPU for 102ms burst [Q F E H B D]
time 22936ms: Process C completed a CPU burst; 91 bursts to go [Q F E H B D]
time 22936ms: Process C switching out of CPU; will block on I/O until time 23077ms [Q F E H B D]
time 22940ms: Process F started using the CPU for 890ms burst [Q E H B D]
time 23077ms: Process C completed I/O; added to ready queue [Q E H B D C]
time 23726ms: Process A completed I/O; added to ready queue [Q E H B D C A]
time 23830ms: Process F completed a CPU burst; 93 bursts to go [Q E H B D C A]
time 23830ms: Process F switching out of CPU; will block on I/O until time 24214ms [Q E H B D C A]
time 23834ms: Process E started using the CPU for 136ms burst [Q H B D C A]
time 23970ms: Process E completed a CPU burst; 79 bursts to go [Q H B D C A]
time 23970ms: Process E switching out of CPU; will block on I/O until time 25137ms [Q H B D C A]
time 23974ms: Process H started using the CPU with 657ms burst remaining [Q B D C A]
time 24214ms: Process F completed I/O; added to ready queue [Q B D C A F]
time 24631ms: Process H completed a CPU burst; 45 bursts to go [Q B D C A F]
time 24631ms: Process H switching out of CPU; will block on I/O until time 25034ms [Q B D C A F]
time 24635ms: Process B started using the CPU for 21ms burst [Q D C A F]
time 24656ms: Process B completed a CPU burst; 2 bursts to go [Q D C A F]
time 24656ms: Process B switching out of CPU; will block on I/O until time 24845ms [Q D C A F]
time 24660ms: Process D started using the CPU for 855ms burst [Q C A F]
time 24845ms: Process B completed I/O; added to ready queue [Q C A F B]
time 25034ms: Process H completed I/O; added to ready queue [Q C A F B H]
time 25137ms: Process E completed I/O; added to ready queue [Q C A F B H E]
time 25515ms: Process D completed a CPU burst; 52 bursts to go [Q C A F B H E]
time 25515ms: Process D switching out of CPU; will block on I/O until time 27857ms [Q C A F B H E]
time 25519ms: Process C started using the CPU for 346ms burst [Q A F B H E]
time 25865ms: Process C completed a CPU burst; 90 bursts to go [Q A F B H E]
time 25865ms: Process C switching out of CPU; will block on I/O until time 26894ms [Q A F B H E]
time 25869ms: Process A started using the CPU for 1095ms burst [Q F B H E]
time 26894ms: Process C completed I/O; added to ready queue [Q F B H E C]
time 26964ms: Process A completed a CPU burst; 79 bursts to go [Q F B H E C]
time 26964ms: Process A switching out of CPU; will block on I/O until time 27305ms [Q F B H E C]
time 26968ms: Process F started using the CPU for 3843ms burst [Q B H E C]
time 27305ms: Process A completed I/O; added to ready queue [Q B H E C A]
time 27857ms: Process D completed I/O; added to ready queue [Q B H E C A D]
time 29016ms: Time slice expired; process F preempted with 1795ms to go [Q B H E C A D]
time 29020ms: Process B started using the CPU for 909ms burst [Q H E C A D F]
time 29929ms: Process B completed a CPU burst; 1 burst to go [Q H E C A D F]
time 29929ms: Process B switching out of CPU; will block on I/O until time 32318ms [Q H E C A D F]
time 29933ms: Process H started using the CPU for 1716ms burst [Q E C A D F]
time 31649ms: Process H completed a CPU burst; 44 bursts to go [Q E C A D F]
time 31649ms: Process H switching out of CPU; will block on I/O until time 32096ms [Q E C A D F]
time 31653ms: Process E started using the CPU for 2127ms burst [Q C A D F]
time 32096ms: Process H completed I/O; added to ready queue [Q C A D F H]
time 32318ms: Process B completed I/O; added to ready queue [Q C A D F H B]
time 33701ms: Time slice expired; process E preempted with 79ms to go [Q C A D F H B]
time 33705ms: Process C started using the CPU for 81ms burst [Q A D F H B E]
time 33786ms: Process C completed a CPU burst; 89 bursts to go [Q A D F H B E]
time 33786ms: Process C switching out of CPU; will block on I/O until time 35034ms [Q A D F H B E]
time 33790ms: Process A started using the CPU for 117ms burst [Q D F H B E]
time 33907ms: Process A completed a CPU burst; 78 bursts to go [Q D F H B E]
time 33907ms: Process A switching out of CPU; will block on I/O until time 35622ms [Q D F H B E]
time 33911ms: Process D started using the CPU for 1730ms burst [Q F H B E]
time 35034ms: Process C completed I/O; added to ready queue [Q F H B E C]
time 35622ms: Process A completed I/O; added to ready queue [Q F H B E C A]
time 35641ms: Process D completed a CPU burst; 51 bursts to go [Q F H B E C A]
time 35641ms: Process D switching out of CPU; will block on I/O until time 36497ms [Q F H B E C A]
time 35645ms: Process F started using the CPU with 1795ms burst remaining [Q H B E C A]
time 36497ms: Process D completed I/O; added to ready queue [Q H B E C A D]
time 37440ms: Process F completed a CPU burst; 92 bursts to go [Q H B E C A D]
time 37440ms: Process F switching out of CPU; will block on I/O until time 39532ms [Q H B E C A D]
time 37444ms: Process H started using the CPU for 615ms burst [Q B E C A D]
time 38059ms: Process H completed a CPU burst; 43 bursts to go [Q B E C A D]
time 38059ms: Process H switching out of CPU; will block on I/O until time 38236ms [Q B E C A D]
time 38063ms: Process B started using the CPU for 70ms burst [Q E C A D]
time 38133ms: Process B terminated [Q E C A D]
time 38137ms: Process E started using the CPU with 79ms burst remaining [Q C A D]
time 38216ms: Process E completed a CPU burst; 78 bursts to go [Q C A D]
time 38216ms: Process E switching out of CPU; will block on I/O until time 39276ms [Q C A D]
time 38220ms: Process C started using the CPU for 1562ms burst [Q A D]
time 38236ms: Process H completed I/O; added to ready queue [Q A D H]
time 39276ms: Process E completed I/O; added to ready queue [Q A D H E]
time 39532ms: Process F completed I/O; added to ready queue [Q A D H E F]
time 39782ms: Process C completed a CPU burst; 88 bursts to go [Q A D H E F]
time 39782ms: Process C switching out of CPU; will block on I/O until time 40273ms [Q A D H E F]
time 39786ms: Process A started using the CPU for 533ms burst [Q D H E F]
time 40273ms: Process C completed I/O; added to ready queue [Q D H E F C]
time 40319ms: Process A completed a CPU burst; 77 bursts to go [Q D H E F C]
time 40319ms: Process A switching out of CPU; will block on I/O until time 40943ms [Q D H E F C]
time 40323ms: Process D started using the CPU for 601ms burst [Q H E F C]
time 40924ms: Process D completed a CPU burst; 50 bursts to go [Q H E F C]
time 40924ms: Process D switching out of CPU; will block on I/O until time 41162ms [Q H E F C]
time 40928ms: Process H started using the CPU for 828ms burst [Q E F C]
time 40943ms: Process A completed I/O; added to ready queue [Q E F C A]
time 41162ms: Process D completed I/O; added to ready queue [Q E F C A D]
time 41756ms: Process H completed a CPU burst; 42 bursts to go [Q E F C A D]
time 41756ms: Process H switching out of CPU; will block on I/O until time 43597ms [Q E F C A D]
time 41760ms: Process E started using the CPU for 351ms burst [Q F C A D]
time 42111ms: Process E completed a CPU burst; 77 bursts to go [Q F C A D]
time 42111ms: Process E switching out of CPU; will block on I/O until time 42210ms [Q F C A D]
time 42115ms: Process F started using the CPU for 2701ms burst [Q C A D]
time 42210ms: Process E completed I/O; added to ready queue [Q C A D E]
time 43597ms: Process H completed I/O; added to ready queue [Q C A D E H]
time 44163ms: Time slice expired; process F preempted with 653ms to go [Q C A D E H]
time 44167ms: Process C started using the CPU for 280ms burst [Q A D E H F]
time 44447ms: Process C completed a CPU burst; 87 bursts to go [Q A D E H F]
time 44447ms: Process C switching out of CPU; will block on I/O until time 44459ms [Q A D E H F]
time 44451ms: Process A started using the CPU for 274ms burst [Q D E H F]
time 44459ms: Process C completed I/O; added to ready queue [Q D E H F C]
time 44725ms: Process A completed a CPU burst; 76 bursts to go [Q D E H F C]
time 44725ms: Process A switching out of CPU; will block on I/O until time 47084ms [Q D E H F C]
time 44729ms: Process D started using the CPU for 2089ms burst [Q E H F C]
time 46777ms: Time slice expired; process D preempted with 41ms to go [Q E H F C]
time 46781ms: Process E started using the CPU for 2531ms burst [Q H F C D]
time 47084ms: Process A completed I/O; added to ready queue [Q H F C D A]
time 48829ms: Time slice expired; process E preempted with 483ms to go [Q H F C D A]
time 48833ms: Process H started using the CPU for 863ms burst [Q F C D A E]
time 49696ms: Process H completed a CPU burst; 41 bursts to go [Q F C D A E]
time 49696ms: Process H switching out of CPU; will block on I/O until time 50365ms [Q F C D A E]
time 49700ms: Process F started using the CPU with 653ms burst remaining [Q C D A E]
time 50353ms: Process F completed a CPU burst; 91 bursts to go [Q C D A E]
time 50353ms: Process F switching out of CPU; will block on I/O until time 53966ms [Q C D A E]
time 50357ms: Process C started using the CPU for 348ms burst [Q D A E]
time 50365ms: Process H completed I/O; added to ready queue [Q D A E H]
time 50705ms: Process C completed a CPU burst; 86 bursts to go [Q D A E H]
time 50705ms: Process C switching out of CPU; will block on I/O until time 51663ms [Q D A E H]
time 50709ms: Process D started using the CPU with 41ms burst remaining [Q A E H]
time 50750ms: Process D completed a CPU burst; 49 bursts to go [Q A E H]
time 50750ms: Process D switching out of CPU; will block on I/O until time 50974ms [Q A E H]
time 50754ms: Process A started using the CPU for 562ms burst [Q E H]
time 50974ms: Process D completed I/O; added to ready queue [Q E H D]
time 51316ms: Process A completed a CPU burst; 75 bursts to go [Q E H D]
time 51316ms: Process A switching out of CPU; will block on I/O until time 53955ms [Q E H D]
time 51320ms: Process E started using the CPU with 483ms burst remaining [Q H D]
time 51663ms: Process C completed I/O; added to ready queue [Q H D C]
time 51803ms: Process E completed a CPU burst; 76 bursts to go [Q H D C]
time 51803ms: Process E switching out of CPU; will block on I/O until time 52856ms [Q H D C]
time 51807ms: Process H started using the CPU for 64ms burst [Q D C]
time 51871ms: Process H completed a CPU burst; 40 bursts to go [Q D C]
time 51871ms: Process H switching out of CPU; will block on I/O until time 52572ms [Q D C]
time 51875ms: Process D started using the CPU for 432ms burst [Q C]
time 52307ms: Process D completed a CPU burst; 48 bursts to go [Q C]
time 52307ms: Process D switching out of CPU; will block on I/O until time 53352ms [Q C]
time 52311ms: Process C started using the CPU for 849ms burst [Q <empty>]
time 52572ms: Process H completed I/O; added to ready queue [Q H]
time 52856ms: Process E completed I/O; added to ready queue [Q H E]
time 53160ms: Process C completed a CPU burst; 85 bursts to go [Q H E]
time 53160ms: Process C switching out of CPU; will block on I/O until time 53175ms [Q H E]
time 53164ms: Process H started using the CPU for 1329ms burst [Q E]
time 53175ms: Process C completed I/O; added to ready queue [Q E C]
time 53352ms: Process D completed I/O; added to ready queue [Q E C D]
time 53955ms: Process A completed I/O; added to ready queue [Q E C D A]
time 53966ms: Process F completed I/O; added to ready queue [Q E C D A F]
time 54493ms: Process H completed a CPU burst; 39 bursts to go [Q E C D A F]
time 54493ms: Process H switching out of CPU; will block on I/O until time 54936ms [Q E C D A F]
time 54497ms: Process E started using the CPU for 2079ms burst [Q C D A F]
time 54936ms: Process H completed I/O; added to ready queue [Q C D A F H]
time 56545ms: Time slice expired; process E preempted with 31ms to go [Q C D A F H]
time 56549ms: Process C started using the CPU for 238ms burst [Q D A F H E]
time 56787ms: Process C completed a CPU burst; 84 bursts to go [Q D A F H E]
time 56787ms: Process C switching out of CPU; will block on I/O until time 57124ms [Q D A F H E]
time 56791ms: Process D started using the CPU for 812ms burst [Q A F H E]
time 57124ms: Process C completed I/O; added to ready queue [Q A F H E C]
time 57603ms: Process D completed a CPU burst; 47 bursts to go [Q A F H E C]
time 57603ms: Process D switching out of CPU; will block on I/O until time 58001ms [Q A F H E C]
time 57607ms: Process A started using the CPU for 2553ms burst [Q F H E C]
time 58001ms: Process D completed I/O; added to ready queue [Q F H E C D]
time 59655ms: Time slice expired; process A preempted with 505ms to go [Q F H E C D]
time 59659ms: Process F started using the CPU for 259ms burst [Q H E C D A]
time 59918ms: Process F completed a CPU burst; 90 bursts to go [Q H E C D A]
time 59918ms: Process F switching out of CPU; will block on I/O until time 60684ms [Q H E C D A]
time 59922ms: Process H started using the CPU for 2061ms burst [Q E C D A]
time 60684ms: Process F completed I/O; added to ready queue [Q E C D A F]
time 61970ms: Time slice expired; process H preempted with 13ms to go [Q E C D A F]
time 61974ms: Process E started using the CPU with 31ms burst remaining [Q C D A F H]
time 62005ms: Process E completed a CPU burst; 75 bursts to go [Q C D A F H]
time 62005ms: Process E switching out of CPU; will block on I/O until time 63076ms [Q C D A F H]
time 62009ms: Process C started using the CPU for 1698ms burst [Q D A F H]
time 63076ms: Process E completed I/O; added to ready queue [Q D A F H E]
time 63707ms: Process C completed a CPU burst; 83 bursts to go [Q D A F H E]
time 63707ms: Process C switching out of CPU; will block on I/O until time 64506ms [Q D A F H E]
time 63711ms: Process D started using the CPU for 1501ms burst [Q A F H E]
time 64506ms: Process C completed I/O; added to ready queue [Q A F H E C]
time 65212ms: Process D completed a CPU burst; 46 bursts to go [Q A F H E C]
time 65212ms: Process D switching out of CPU; will block on I/O until time 66139ms [Q A F H E C]
time 65216ms: Process A started using the CPU with 505ms burst remaining [Q F H E C]
time 65721ms: Process A completed a CPU burst; 74 bursts to go [Q F H E C]
time 65721ms: Process A switching out of CPU; will block on I/O until time 65863ms [Q F H E C]
time 65725ms: Process F started using the CPU for 588ms burst [Q H E C]
time 65863ms: Process A completed I/O; added to ready queue [Q H E C A]
time 66139ms: Process D completed I/O; added to ready queue [Q H E C A D]
time 66313ms: Process F completed a CPU burst; 89 bursts to go [Q H E C A D]
time 66313ms: Process F switching out of CPU; will block on I/O until time 67388ms [Q H E C A D]
time 66317ms: Process H started using the CPU with 13ms burst remaining [Q E C A D]
time 66330ms: Process H completed a CPU burst; 38 bursts to go [Q E C A D]
time 66330ms: Process H switching out of CPU; will block on I/O until time 66673ms [Q E C A D]
time 66334ms: Process E started using the CPU for 466ms burst [Q C A D]
time 66673ms: Process H completed I/O; added to ready queue [Q C A D H]
time 66800ms: Process E completed a CPU burst; 74 bursts to go [Q C A D H]
time 66800ms: Process E switching out of CPU; will block on I/O until time 68102ms [Q C A D H]
time 66804ms: Process C started using the CPU for 1563ms burst [Q A D H]
time 67388ms: Process F completed I/O; added to ready queue [Q A D H F]
time 68102ms: Process E completed I/O; added to ready queue [Q A D H F E]
time 68367ms: Process C completed a CPU burst; 82 bursts to go [Q A D H F E]
time 68367ms: Process C switching out of CPU; will block on I/O until time 68707ms [Q A D H F E]
time 68371ms: Process A started using the CPU for 1023ms burst [Q D H F E]
time 68707ms: Process C completed I/O; added to ready queue [Q D H F E C]
time 69394ms: Process A completed a CPU burst; 73 bursts to go [Q D H F E C]
time 69394ms: Process A switching out of CPU; will block on I/O until time 70410ms [Q D H F E C]
time 69398ms: Process D started using the CPU for 1717ms burst [Q H F E C]
time 70410ms: Process A completed I/O; added to ready queue [Q H F E C A]
time 71115ms: Process D completed a CPU burst; 45 bursts to go [Q H F E C A]
time 71115ms: Process D switching out of CPU; will block on I/O until time 71299ms [Q H F E C A]
time 71119ms: Process H started using the CPU for 1088ms burst [Q F E C A]
time 71299ms: Process D completed I/O; added to ready queue [Q F E C A D]
time 72207ms: Process H completed a CPU burst; 37 bursts to go [Q F E C A D]
time 72207ms: Process H switching out of CPU; will block on I/O until time 72236ms [Q F E C A D]
time 72211ms: Process F started using the CPU for 1774ms burst [Q E C A D]
time 72236ms: Process H completed I/O; added to ready queue [Q E C A D H]
time 73985ms: Process F completed a CPU burst; 88 bursts to go [Q E C A D H]
time 73985ms: Process F switching out of CPU; will block on I/O until time 74024ms [Q E C A D H]
time 73989ms: Process E started using the CPU for 564ms burst [Q C A D H]
time 74024ms: Process F completed I/O; added to ready queue [Q C A D H F]
time 74553ms: Process E completed a CPU burst; 73 bursts to go [Q C A D H F]
time 74553ms: Process E switching out of CPU; will block on I/O until time 76197ms [Q C A D H F]
time 74557ms: Process C started using the CPU for 1428ms burst [Q A D H F]
time 75985ms: Process C completed a CPU burst; 81 bursts to go [Q A D H F]
time 75985ms: Process C switching out of CPU; will block on I/O until time 77672ms [Q A D H F]
time 75989ms: Process A started using the CPU for 319ms burst [Q D H F]
time 76197ms: Process E completed I/O; added to ready queue [Q D H F E]
time 76308ms: Process A completed a CPU burst; 72 bursts to go [Q D H F E]
time 76308ms: Process A switching out of CPU; will block on I/O until time 76548ms [Q D H F E]
time 76312ms: Process D started using the CPU for 1319ms burst [Q H F E]
time 76548ms: Process A completed I/O; added to ready queue [Q H F E A]
time 77631ms: Process D completed a CPU burst; 44 bursts to go [Q H F E A]
time 77631ms: Process D switching out of CPU; will block on I/O until time 77992ms [Q H F E A]
time 77635ms: Process H started using the CPU for 92ms burst [Q F E A]
time 77672ms: Process C completed I/O; added to ready queue [Q F E A C]
time 77727ms: Process H completed a CPU burst; 36 bursts to go [Q F E A C]
time 77727ms: Process H switching out of CPU; will block on I/O until time 79109ms [Q F E A C]
time 77731ms: Process F started using the CPU for 902ms burst [Q E A C]
time 77992ms: Process D completed I/O; added to ready queue [Q E A C D]
time 78633ms: Process F completed a CPU burst; 87 bursts to go [Q E A C D]
time 78633ms: Process F switching out of CPU; will block on I/O until time 78925ms [Q E A C D]
time 78637ms: Process E started using the CPU for 1518ms burst [Q A C D]
time 78925ms: Process F completed I/O; added to ready queue [Q A C D F]
time 79109ms: Process H completed I/O; added to ready queue [Q A C D F H]
time 80155ms: Process E completed a CPU burst; 72 bursts to go [Q A C D F H]
time 80155ms: Process E switching out of CPU; will block on I/O until time 80821ms [Q A C D F H]
time 80159ms: Process A started using the CPU for 1872ms burst [Q C D F H]
time 80821ms: Process E completed I/O; added to ready queue [Q C D F H E]
time 82031ms: Process A completed a CPU burst; 71 bursts to go [Q C D F H E]
time 82031ms: Process A switching out of CPU; will block on I/O until time 83374ms [Q C D F H E]
time 82035ms: Process C started using the CPU for 1761ms burst [Q D F H E]
time 83374ms: Process A completed I/O; added to ready queue [Q D F H E A]
time 83796ms: Process C completed a CPU burst; 80 bursts to go [Q D F H E A]
time 83796ms: Process C switching out of CPU; will block on I/O until time 84575ms [Q D F H E A]
time 83800ms: Process D started using the CPU for 2816ms burst [Q F H E A]
time 84575ms: Process C completed I/O; added to ready queue [Q F H E A C]
time 85848ms: Time slice expired; process D preempted with 768ms to go [Q F H E A C]
time 85852ms: Process F started using the CPU for 806ms burst [Q H E A C D]
time 86658ms: Process F completed a CPU burst; 86 bursts to go [Q H E A C D]
time 86658ms: Process F switching out of CPU; will block on I/O until time 86889ms [Q H E A C D]
time 86662ms: Process H started using the CPU for 769ms burst [Q E A C D]
time 86889ms: Process F completed I/O; added to ready queue [Q E A C D F]
time 87431ms: Process H completed a CPU burst; 35 bursts to go [Q E A C D F]
time 87431ms: Process H switching out of CPU; will block on I/O until time 88425ms [Q E A C D F]
time 87435ms: Process E started using the CPU for 740ms burst [Q A C D F]
time 88175ms: Process E completed a CPU burst; 71 bursts to go [Q A C D F]
time 88175ms: Process E switching out of CPU; will block on I/O until time 88876ms [Q A C D F]
time 88179ms: Process A started using the CPU for 1788ms burst [Q C D F]
time 88425ms: Process H completed I/O; added to ready queue [Q C D F H]
time 88876ms: Process E completed I/O; added to ready queue [Q C D F H E]
time 89967ms: Process A completed a CPU burst; 70 bursts to go [Q C D F H E]
time 89967ms: Process A switching out of CPU; will block on I/O until time 90119ms [Q C D F H E]
time 89971ms: Process C started using the CPU for 1852ms burst [Q D F H E]
time 90119ms: Process A completed I/O; added to ready queue [Q D F H E A]
time 91823ms: Process C completed a CPU burst; 79 bursts to go [Q D F H E A]
time 91823ms: Process C switching out of CPU; will block on I/O until time 92230ms [Q D F H E A]
time 91827ms: Process D started using the CPU with 768ms burst remaining [Q F H E A]
time 92230ms: Process C completed I/O; added to ready queue [Q F H E A C]
time 92595ms: Process D completed a CPU burst; 43 bursts to go [Q F H E A C]
time 92595ms: Process D switching out of CPU; will block on I/O until time 93916ms [Q F H E A C]
time 92599ms: Process F started using the CPU for 21ms burst [Q H E A C]
time 92620ms: Process F completed a CPU burst; 85 bursts to go [Q H E A C]
time 92620ms: Process F switching out of CPU; will block on I/O until time 93746ms [Q H E A C]
time 92624ms: Process H started using the CPU for 2270ms burst [Q E A C]
time 93746ms: Process F completed I/O; added to ready queue [Q E A C F]
time 93916ms: Process D completed I/O; added to ready queue [Q E A C F D]
time 94672ms: Time slice expired; process H preempted with 222ms to go [Q E A C F D]
time 94676ms: Process E started using the CPU for 420ms burst [Q A C F D H]
time 95096ms: Process E completed a CPU burst; 70 bursts to go [Q A C F D H]
time 95096ms: Process E switching out of CPU; will block on I/O until time 95418ms [Q A C F D H]
time 95100ms: Process A started using the CPU for 313ms burst [Q C F D H]
time 95413ms: Process A completed a CPU burst; 69 bursts to go [Q C F D H]
time 95413ms: Process A switching out of CPU; will block on I/O until time 95496ms [Q C F D H]
time 95417ms: Process C started using the CPU for 230ms burst [Q F D H]
time 95418ms: Process E completed I/O; added to ready queue [Q F D H E]
time 95496ms: Process A completed I/O; added to ready queue [Q F D H E A]
time 95647ms: Process C completed a CPU burst; 78 bursts to go [Q F D H E A]
time 95647ms: Process C switching out of CPU; will block on I/O until time 96432ms [Q F D H E A]
time 95651ms: Process F started using the CPU for 1401ms burst [Q D H E A]
time 96432ms: Process C completed I/O; added to ready queue [Q D H E A C]
time 97052ms: Process F completed a CPU burst; 84 bursts to go [Q D H E A C]
time 97052ms: Process F switching out of CPU; will block on I/O until time 98085ms [Q D H E A C]
time 97056ms: Process D started using the CPU for 2717ms burst [Q H E A C]
time 98085ms: Process F completed I/O; added to ready queue [Q H E A C F]
time 99104ms: Time slice expired; process D preempted with 669ms to go [Q H E A C F]
time 99108ms: Process H started using the CPU with 222ms burst remaining [Q E A C F D]
time 99330ms: Process H completed a CPU burst; 34 bursts to go [Q E A C F D]
time 99330ms: Process H switching out of CPU; will block on I/O until time 99820ms [Q E A C F D]
time 99334ms: Process E started using the CPU for 1497ms burst [Q A C F D]
time 99820ms: Process H completed I/O; added to ready queue [Q A C F D H]
time 100831ms: Process E completed a CPU burst; 69 bursts to go [Q A C F D H]
time 100831ms: Process E switching out of CPU; will block on I/O until time 101324ms [Q A C F D H]
time 100835ms: Process A started using the CPU for 1135ms burst [Q C F D H]
time 101324ms: Process E completed I/O; added to ready queue [Q C F D H E]
time 101970ms: Process A completed a CPU burst; 68 bursts to go [Q C F D H E]
time 101970ms: Process A switching out of CPU; will block on I/O until time 102122ms [Q C F D H E]
time 101974ms: Process C started using the CPU for 768ms burst [Q F D H E]
time 102122ms: Process A completed I/O; added to ready queue [Q F D H E A]
time 102742ms: Process C completed a CPU burst; 77 bursts to go [Q F D H E A]
time 102742ms: Process C switching out of CPU; will block on I/O until time 102937ms [Q F D H E A]
time 102746ms: Process F started using the CPU for 215ms burst [Q D H E A]
time 102937ms: Process C completed I/O; added to ready queue [Q D H E A C]
time 102961ms: Process F completed a CPU burst; 83 bursts to go [Q D H E A C]
time 102961ms: Process F switching out of CPU; will block on I/O until time 103162ms [Q D H E A C]
time 102965ms: Process D started using the CPU with 669ms burst remaining [Q H E A C]
time 103162ms: Process F completed I/O; added to ready queue [Q H E A C F]
time 103634ms: Process D completed a CPU burst; 42 bursts to go [Q H E A C F]
time 103634ms: Process D switching out of CPU; will block on I/O until time 104248ms [Q H E A C F]
time 103638ms: Process H started using the CPU for 2381ms burst [Q E A C F]
time 104248ms: Process D completed I/O; added to ready queue [Q E A C F D]
time 105686ms: Time slice expired; process H preempted with 333ms to go [Q E A C F D]
time 105690ms: Process E started using the CPU for 985ms burst [Q A C F D H]
time 106675ms: Process E completed a CPU burst; 68 bursts to go [Q A C F D H]
time 106675ms: Process E switching out of CPU; will block on I/O until time 106787ms [Q A C F D H]
time 106679ms: Process A started using the CPU for 1068ms burst [Q C F D H]
time 106787ms: Process E completed I/O; added to ready queue [Q C F D H E]
time 107747ms: Process A completed a CPU burst; 67 bursts to go [Q C F D H E]
time 107747ms: Process A switching out of CPU; will block on I/O until time 107826ms [Q C F D H E]
time 107751ms: Process C started using the CPU for 106ms burst [Q F D H E]
time 107826ms: Process A completed I/O; added to ready queue [Q F D H E A]
time 107857ms: Process C completed a CPU burst; 76 bursts to go [Q F D H E A]
time 107857ms: Process C switching out of CPU; will block on I/O until time 108428ms [Q F D H E A]
time 107861ms: Process F started using the CPU for 531ms burst [Q D H E A]
time 108392ms: Process F completed a CPU burst; 82 bursts to go [Q D H E A]
time 108392ms: Process F switching out of CPU; will block on I/O until time 109125ms [Q D H E A]
time 108396ms: Process D started using the CPU for 508ms burst [Q H E A]
time 108428ms: Process C completed I/O; added to ready queue [Q H E A C]
time 108904ms: Process D completed a CPU burst; 41 bursts to go [Q H E A C]
time 108904ms: Process D switching out of CPU; will block on I/O until time 110151ms [Q H E A C]
time 108908ms: Process H started using the CPU with 333ms burst remaining [Q E A C]
time 109125ms: Process F completed I/O; added to ready queue [Q E A C F]
time 109241ms: Process H completed a CPU burst; 33 bursts to go [Q E A C F]
time 109241ms: Process H switching out of CPU; will block on I/O until time 110723ms [Q E A C F]
time 109245ms: Process E started using the CPU for 1145ms burst [Q A C F]
time 110151ms: Process D completed I/O; added to ready queue [Q A C F D]
time 110390ms: Process E completed a CPU burst; 67 bursts to go [Q A C F D]
time 110390ms: Process E switching out of CPU; will block on I/O until time 111327ms [Q A C F D]
time 110394ms: Process A started using the CPU for 447ms burst [Q C F D]
time 110723ms: Process H completed I/O; added to ready queue [Q C F D H]
time 110841ms: Process A completed a CPU burst; 66 bursts to go [Q C F D H]
time 110841ms: Process A switching out of CPU; will block on I/O until time 110892ms [Q C F D H]
time 110845ms: Process C started using the CPU for 1544ms burst [Q F D H]
time 110892ms: Process A completed I/O; added to ready queue [Q F D H A]
time 111327ms: Process E completed I/O; added to ready queue [Q F D H A E]
time 112389ms: Process C completed a CPU burst; 75 bursts to go [Q F D H A E]
time 112389ms: Process C switching out of CPU; will block on I/O until time 113910ms [Q F D H A E]
time 112393ms: Process F started using the CPU for 198ms burst [Q D H A E]
time 112591ms: Process F completed a CPU burst; 81 bursts to go [Q D H A E]
time 112591ms: Process F switching out of CPU; will block on I/O until time 116258ms [Q D H A E]
time 112595ms: Process D started using the CPU for 205ms burst [Q H A E]
time 112800ms: Process D completed a CPU burst; 40 bursts to go [Q H A E]
time 112800ms: Process D switching out of CPU; will block on I/O until time 113510ms [Q H A E]
time 112804ms: Process H started using the CPU for 49ms burst [Q A E]
time 112853ms: Process H completed a CPU burst; 32 bursts to go [Q A E]
time 112853ms: Process H switching out of CPU; will block on I/O until time 113197ms [Q A E]
time 112857ms: Process A started using the CPU for 200ms burst [Q E]
time 113057ms: Process A completed a CPU burst; 65 bursts to go [Q E]
time 113057ms: Process A switching out of CPU; will block on I/O until time 114174ms [Q E]
time 113061ms: Process E started using the CPU for 593ms burst [Q <empty>]
time 113197ms: Process H completed I/O; added to ready queue [Q H]
time 113510ms: Process D completed I/O; added to ready queue [Q H D]
time 113654ms: Process E completed a CPU burst; 66 bursts to go [Q H D]
time 113654ms: Process E switching out of CPU; will block on I/O until time 114202ms [Q H D]
time 113658ms: Process H started using the CPU for 1969ms burst [Q D]
time 113910ms: Process C completed I/O; added to ready queue [Q D C]
time 114174ms: Process A completed I/O; added to ready queue [Q D C A]
time 114202ms: Process E completed I/O; added to ready queue [Q D C A E]
time 115627ms: Process H completed a CPU burst; 31 bursts to go [Q D C A E]
time 115627ms: Process H switching out of CPU; will block on I/O until time 117309ms [Q D C A E]
time 115631ms: Process D started using the CPU for 1404ms burst [Q C A E]
time 116258ms: Process F completed I/O; added to ready queue [Q C A E F]
time 117035ms: Process D completed a CPU burst; 39 bursts to go [Q C A E F]
time 117035ms: Process D switching out of CPU; will block on I/O until time 118226ms [Q C A E F]
time 117039ms: Process C started using the CPU for 147ms burst [Q A E F]
time 117186ms: Process C completed a CPU burst; 74 bursts to go [Q A E F]
time 117186ms: Process C switching out of CPU; will block on I/O until time 117307ms [Q A E F]
time 117190ms: Process A started using the CPU for 722ms burst [Q E F]
time 117307ms: Process C completed I/O; added to ready queue [Q E F C]
time 117309ms: Process H completed I/O; added to ready queue [Q E F C H]
time 117912ms: Process A completed a CPU burst; 64 bursts to go [Q E F C H]
time 117912ms: Process A switching out of CPU; will block on I/O until time 118719ms [Q E F C H]
time 117916ms: Process E started using the CPU for 1078ms burst [Q F C H]
time 118226ms: Process D completed I/O; added to ready queue [Q F C H D]
time 118719ms: Process A completed I/O; added to ready queue [Q F C H D A]
time 118994ms: Process E completed a CPU burst; 65 bursts to go [Q F C H D A]
time 118994ms: Process E switching out of CPU; will block on I/O until time 119393ms [Q F C H D A]
time 118998ms: Process F started using the CPU for 218ms burst [Q C H D A]
time 119216ms: Process F completed a CPU burst; 80 bursts to go [Q C H D A]
time 119216ms: Process F switching out of CPU; will block on I/O until time 121226ms [Q C H D A]
time 119220ms: Process C started using the CPU for 2148ms burst [Q H D A]
time 119393ms: Process E completed I/O; added to ready queue [Q H D A E]
time 121226ms: Process F completed I/O; added to ready queue [Q H D A E F]
time 121268ms: Time slice expired; process C preempted with 100ms to go [Q H D A E F]
time 121272ms: Process H started using the CPU for 622ms burst [Q D A E F C]
time 121894ms: Process H completed a CPU burst; 30 bursts to go [Q D A E F C]
time 121894ms: Process H switching out of CPU; will block on I/O until time 122896ms [Q D A E F C]
time 121898ms: Process D started using the CPU for 3202ms burst [Q A E F C]
time 122896ms: Process H completed I/O; added to ready queue [Q A E F C H]
time 123946ms: Time slice expired; process D preempted with 1154ms to go [Q A E F C H]
time 123950ms: Process A started using the CPU for 196ms burst [Q E F C H D]
time 124146ms: Process A completed a CPU burst; 63 bursts to go [Q E F C H D]
time 124146ms: Process A switching out of CPU; will block on I/O until time 124896ms [Q E F C H D]
time 124150ms: Process E started using the CPU for 1045ms burst [Q F C H D]
time 124896ms: Process A completed I/O; added to ready queue [Q F C H D A]
time 125195ms: Process E completed a CPU burst; 64 bursts to go [Q F C H D A]
time 125195ms: Process E switching out of CPU; will block on I/O until time 125837ms [Q F C H D A]
time 125199ms: Process F started using the CPU for 914ms burst [Q C H D A]
time 125837ms: Process E completed I/O; added to ready queue [Q C H D A E]
time 126113ms: Process F completed a CPU burst; 79 bursts to go [Q C H D A E]
time 126113ms: Process F switching out of CPU; will block on I/O until time 127678ms [Q C H D A E]
time 126117ms: Process C started using the CPU with 100ms burst remaining [Q H D A E]
time 126217ms: Process C completed a CPU burst; 73 bursts to go [Q H D A E]
time 126217ms: Process C switching out of CPU; will block on I/O until time 127761ms [Q H D A E]
time 126221ms: Process H started using the CPU for 2420ms burst [Q D A E]
time 127678ms: Process F completed I/O; added to ready queue [Q D A E F]
time 127761ms: Process C completed I/O; added to ready queue [Q D A E F C]
time 128269ms: Time slice expired; process H preempted with 372ms to go [Q D A E F C]
time 128273ms: Process D started using the CPU with 1154ms burst remaining [Q A E F C H]
time 129427ms: Process D completed a CPU burst; 38 bursts to go [Q A E F C H]
time 129427ms: Process D switching out of CPU; will block on I/O until time 130729ms [Q A E F C H]
time 129431ms: Process A started using the CPU for 3198ms burst [Q E F C H]
time 130729ms: Process D completed I/O; added to ready queue [Q E F C H D]
time 131479ms: Time slice expired; process A preempted with 1150ms to go [Q E F C H D]
time 131483ms: Process E started using the CPU for 910ms burst [Q F C H D A]
time 132393ms: Process E completed a CPU burst; 63 bursts to go [Q F C H D A]
time 132393ms: Process E switching out of CPU; will block on I/O until time 135342ms [Q F C H D A]
time 132397ms: Process F started using the CPU for 1276ms burst [Q C H D A]
time 133673ms: Process F completed a CPU burst; 78 bursts to go [Q C H D A]
time 133673ms: Process F switching out of CPU; will block on I/O until time 133748ms [Q C H D A]
time 133677ms: Process C started using the CPU for 1935ms burst [Q H D A]
time 133748ms: Process F completed I/O; added to ready queue [Q H D A F]
time 135342ms: Process E completed I/O; added to ready queue [Q H D A F E]
time 135612ms: Process C completed a CPU burst; 72 bursts to go [Q H D A F E]
time 135612ms: Process C switching out of CPU; will block on I/O until time 135751ms [Q H D A F E]
time 135616ms: Process H started using the CPU with 372ms burst remaining [Q D A F E]
time 135751ms: Process C completed I/O; added to ready queue [Q D A F E C]
time 135988ms: Process H completed a CPU burst; 29 bursts to go [Q D A F E C]
time 135988ms: Process H switching out of CPU; will block on I/O until time 136439ms [Q D A F E C]
time 135992ms: Process D started using the CPU for 521ms burst [Q A F E C]
time 136439ms: Process H completed I/O; added to ready queue [Q A F E C H]
time 136513ms: Process D completed a CPU burst; 37 bursts to go [Q A F E C H]
time 136513ms: Process D switching out of CPU; will block on I/O until time 139096ms [Q A F E C H]
time 136517ms: Process A started using the CPU with 1150ms burst remaining [Q F E C H]
time 137667ms: Process A completed a CPU burst; 62 bursts to go [Q F E C H]
time 137667ms: Process A switching out of CPU; will block on I/O until time 140027ms [Q F E C H]
time 137671ms: Process F started using the CPU for 907ms burst [Q E C H]
time 138578ms: Process F completed a CPU burst; 77 bursts to go [Q E C H]
time 138578ms: Process F switching out of CPU; will block on I/O until time 138986ms [Q E C H]
time 138582ms: Process E started using the CPU for 2671ms burst [Q C H]
time 138986ms: Process F completed I/O; added to ready queue [Q C H F]
time 139096ms: Process D completed I/O; added to ready queue [Q C H F D]
time 140027ms: Process A completed I/O; added to ready queue [Q C H F D A]
time 140630ms: Time slice expired; process E preempted with 623ms to go [Q C H F D A]
time 140634ms: Process C started using the CPU for 142ms burst [Q H F D A E]
time 140776ms: Process C completed a CPU burst; 71 bursts to go [Q H F D A E]
time 140776ms: Process C switching out of CPU; will block on I/O until time 142188ms [Q H F D A E]
time 140780ms: Process H started using the CPU for 1623ms burst [Q F D A E]
time 142188ms: Process C completed I/O; added to ready queue [Q F D A E C]
time 142403ms: Process H completed a CPU burst; 28 bursts to go [Q F D A E C]
time 142403ms: Process H switching out of CPU; will block on I/O until time 142762ms [Q F D A E C]
time 142407ms: Process F started using the CPU for 1623ms burst [Q D A E C]
time 142762ms: Process H completed I/O; added to ready queue [Q D A E C H]
time 144030ms: Process F completed a CPU burst; 76 bursts to go [Q D A E C H]
time 144030ms: Process F switching out of CPU; will block on I/O until time 147503ms [Q D A E C H]
time 144034ms: Process D started using the CPU for 713ms burst [Q A E C H]
time 144747ms: Process D completed a CPU burst; 36 bursts to go [Q A E C H]
time 144747ms: Process D switching out of CPU; will block on I/O until time 146003ms [Q A E C H]
time 144751ms: Process A started using the CPU for 687ms burst [Q E C H]
time 145438ms: Process A completed a CPU burst; 61 bursts to go [Q E C H]
time 145438ms: Process A switching out of CPU; will block on I/O until time 145763ms [Q E C H]
time 145442ms: Process E started using the CPU with 623ms burst remaining [Q C H]
time 145763ms: Process A completed I/O; added to ready queue [Q C H A]
time 146003ms: Process D completed I/O; added to ready queue [Q C H A D]
time 146065ms: Process E completed a CPU burst; 62 bursts to go [Q C H A D]
time 146065ms: Process E switching out of CPU; will block on I/O until time 146096ms [Q C H A D]
time 146069ms: Process C started using the CPU for 2295ms burst [Q H A D]
time 146096ms: Process E completed I/O; added to ready queue [Q H A D E]
time 147503ms: Process F completed I/O; added to ready queue [Q H A D E F]
time 148117ms: Time slice expired; process C preempted with 247ms to go [Q H A D E F]
time 148121ms: Process H started using the CPU for 202ms burst [Q A D E F C]
time 148323ms: Process H completed a CPU burst; 27 bursts to go [Q A D E F C]
time 148323ms: Process H switching out of CPU; will block on I/O until time 149286ms [Q A D E F C]
time 148327ms: Process A started using the CPU for 1663ms burst [Q D E F C]
time 149286ms: Process H completed I/O; added to ready queue [Q D E F C H]
time 149990ms: Process A completed a CPU burst; 60 bursts to go [Q D E F C H]
time 149990ms: Process A switching out of CPU; will block on I/O until time 150688ms [Q D E F C H]
time 149994ms: Process D started using the CPU for 152ms burst [Q E F C H]
time 150146ms: Process D completed a CPU burst; 35 bursts to go [Q E F C H]
time 150146ms: Process D switching out of CPU; will block on I/O until time 150766ms [Q E F C H]
time 150150ms: Process E started using the CPU for 734ms burst [Q F C H]
time 150688ms: Process A completed I/O; added to ready queue [Q F C H A]
time 150766ms: Process D completed I/O; added to ready queue [Q F C H A D]
time 150884ms: Process E completed a CPU burst; 61 bursts to go [Q F C H A D]
time 150884ms: Process E switching out of CPU; will block on I/O until time 151027ms [Q F C H A D]
time 150888ms: Process F started using the CPU for 766ms burst [Q C H A D]
time 151027ms: Process E completed I/O; added to ready queue [Q C H A D E]
time 151654ms: Process F completed a CPU burst; 75 bursts to go [Q C H A D E]
time 151654ms: Process F switching out of CPU; will block on I/O until time 152119ms [Q C H A D E]
time 151658ms: Process C started using the CPU with 247ms burst remaining [Q H A D E]
time 151905ms: Process C completed a CPU burst; 70 bursts to go [Q H A D E]
time 151905ms: Process C switching out of CPU; will block on I/O until time 152674ms [Q H A D E]
time 151909ms: Process H started using the CPU for 244ms burst [Q A D E]
time 152119ms: Process F completed I/O; added to ready queue [Q A D E F]
time 152153ms: Process H completed a CPU burst; 26 bursts to go [Q A D E F]
time 152153ms: Process H switching out of CPU; will block on I/O until time 153456ms [Q A D E F]
time 152157ms: Process A started using the CPU for 174ms burst [Q D E F]
time 152331ms: Process A completed a CPU burst; 59 bursts to go [Q D E F]
time 152331ms: Process A switching out of CPU; will block on I/O until time 152411ms [Q D E F]
time 152335ms: Process D started using the CPU for 666ms burst [Q E F]
time 152411ms: Process A completed I/O; added to ready queue [Q E F A]
time 152674ms: Process C completed I/O; added to ready queue [Q E F A C]
time 153001ms: Process D completed a CPU burst; 34 bursts to go [Q E F A C]
time 153001ms: Process D switching out of CPU; will block on I/O until time 153738ms [Q E F A C]
time 153005ms: Process E started using the CPU for 215ms burst [Q F A C]
time 153220ms: Process E completed a CPU burst; 60 bursts to go [Q F A C]
time 153220ms: Process E switching out of CPU; will block on I/O until time 153833ms [Q F A C]
time 153224ms: Process F started using the CPU for 2644ms burst [Q A C]
time 153456ms: Process H completed I/O; added to ready queue [Q A C H]
time 153738ms: Process D completed I/O; added to ready queue [Q A C H D]
time 153833ms: Process E completed I/O; added to ready queue [Q A C H D E]
time 155272ms: Time slice expired; process F preempted with 596ms to go [Q A C H D E]
time 155276ms: Process A started using the CPU for 2151ms burst [Q C H D E F]
time 157324ms: Time slice expired; process A preempted with 103ms to go [Q C H D E F]
time 157328ms: Process C started using the CPU for 43ms burst [Q H D E F A]
time 157371ms: Process C completed a CPU burst; 69 bursts to go [Q H D E F A]
time 157371ms: Process C switching out of CPU; will block on I/O until time 159072ms [Q H D E F A]
time 157375ms: Process H started using the CPU for 45ms burst [Q D E F A]
time 157420ms: Process H completed a CPU burst; 25 bursts to go [Q D E F A]
time 157420ms: Process H switching out of CPU; will block on I/O until time 159817ms [Q D E F A]
time 157424ms: Process D started using the CPU for 3886ms burst [Q E F A]
time 159072ms: Process C completed I/O; added to ready queue [Q E F A C]
time 159472ms: Time slice expired; process D preempted with 1838ms to go [Q E F A C]
time 159476ms: Process E started using the CPU for 1141ms burst [Q F A C D]
time 159817ms: Process H completed I/O; added to ready queue [Q F A C D H]
time 160617ms: Process E completed a CPU burst; 59 bursts to go [Q F A C D H]
time 160617ms: Process E switching out of CPU; will block on I/O until time 162582ms [Q F A C D H]
time 160621ms: Process F started using the CPU with 596ms burst remaining [Q A C D H]
time 161217ms: Process F completed a CPU burst; 74 bursts to go [Q A C D H]
time 161217ms: Process F switching out of CPU; will block on I/O until time 161551ms [Q A C D H]
time 161221ms: Process A started using the CPU with 103ms burst remaining [Q C D H]
time 161324ms: Process A completed a CPU burst; 58 bursts to go [Q C D H]
time 161324ms: Process A switching out of CPU; will block on I/O until time 161557ms [Q C D H]
time 161328ms: Process C started using the CPU for 1236ms burst [Q D H]
time 161551ms: Process F completed I/O; added to ready queue [Q D H F]
time 161557ms: Process A completed I/O; added to ready queue [Q D H F A]
time 162564ms: Process C completed a CPU burst; 68 bursts to go [Q D H F A]
time 162564ms: Process C switching out of CPU; will block on I/O until time 163773ms [Q D H F A]
time 162568ms: Process D started using the CPU with 1838ms burst remaining [Q H F A]
time 162582ms: Process E completed I/O; added to ready queue [Q H F A E]
time 163773ms: Process C completed I/O; added to ready queue [Q H F A E C]
time 164406ms: Process D completed a CPU burst; 33 bursts to go [Q H F A E C]
time 164406ms: Process D switching out of CPU; will block on I/O until time 165391ms [Q H F A E C]
time 164410ms: Process H started using the CPU for 1078ms burst [Q F A E C]
time 165391ms: Process D completed I/O; added to ready queue [Q F A E C D]
time 165488ms: Process H completed a CPU burst; 24 bursts to go [Q F A E C D]
time 165488ms: Process H switching out of CPU; will block on I/O until time 166738ms [Q F A E C D]
time 165492ms: Process F started using the CPU for 79ms burst [Q A E C D]
time 165571ms: Process F completed a CPU burst; 73 bursts to go [Q A E C D]
time 165571ms: Process F switching out of CPU; will block on I/O until time 167471ms [Q A E C D]
time 165575ms: Process A started using the CPU for 322ms burst [Q E C D]
time 165897ms: Process A completed a CPU burst; 57 bursts to go [Q E C D]
time 165897ms: Process A switching out of CPU; will block on I/O until time 166878ms [Q E C D]
time 165901ms: Process E started using the CPU for 197ms burst [Q C D]
time 166098ms: Process E completed a CPU burst; 58 bursts to go [Q C D]
time 166098ms: Process E switching out of CPU; will block on I/O until time 169809ms [Q C D]
time 166102ms: Process C started using the CPU for 41ms burst [Q D]
time 166143ms: Process C completed a CPU burst; 67 bursts to go [Q D]
time 166143ms: Process C switching out of CPU; will block on I/O until time 167438ms [Q D]
time 166147ms: Process D started using the CPU for 1149ms burst [Q <empty>]
time 166738ms: Process H completed I/O; added to ready queue [Q H]
time 166878ms: Process A completed I/O; added to ready queue [Q H A]
time 167296ms: Process D completed a CPU burst; 32 bursts to go [Q H A]
time 167296ms: Process D switching out of CPU; will block on I/O until time 167458ms [Q H A]
time 167300ms: Process H started using the CPU for 1191ms burst [Q A]
time 167438ms: Process C completed I/O; added to ready queue [Q A C]
time 167458ms: Process D completed I/O; added to ready queue [Q A C D]
time 167471ms: Process F completed I/O; added to ready queue [Q A C D F]
time 168491ms: Process H completed a CPU burst; 23 bursts to go [Q A C D F]
time 168491ms: Process H switching out of CPU; will block on I/O until time 170306ms [Q A C D F]
time 168495ms: Process A started using the CPU for 468ms burst [Q C D F]
time 168963ms: Process A completed a CPU burst; 56 bursts to go [Q C D F]
time 168963ms: Process A switching out of CPU; will block on I/O until time 169249ms [Q C D F]
time 168967ms: Process C started using the CPU for 626ms burst [Q D F]
time 169249ms: Process A completed I/O; added to ready queue [Q D F A]
time 169593ms: Process C completed a CPU burst; 66 bursts to go [Q D F A]
time 169593ms: Process C switching out of CPU; will block on I/O until time 170632ms [Q D F A]
time 169597ms: Process D started using the CPU for 1085ms burst [Q F A]
time 169809ms: Process E completed I/O; added to ready queue [Q F A E]
time 170306ms: Process H completed I/O; added to ready queue [Q F A E H]
time 170632ms: Process C completed I/O; added to ready queue [Q F A E H C]
time 170682ms: Process D completed a CPU burst; 31 bursts to go [Q F A E H C]
time 170682ms: Process D switching out of CPU; will block on I/O until time 171894ms [Q F A E H C]
time 170686ms: Process F started using the CPU for 23ms burst [Q A E H C]
time 170709ms: Process F completed a CPU burst; 72 bursts to go [Q A E H C]
time 170709ms: Process F switching out of CPU; will block on I/O until time 171095ms [Q A E H C]
time 170713ms: Process A started using the CPU for 2475ms burst [Q E H C]
time 171095ms: Process F completed I/O; added to ready queue [Q E H C F]
time 171894ms: Process D completed I/O; added to ready queue [Q E H C F D]
time 172761ms: Time slice expired; process A preempted with 427ms to go [Q E H C F D]
time 172765ms: Process E started using the CPU for 708ms burst [Q H C F D A]
time 173473ms: Process E completed a CPU burst; 57 bursts to go [Q H C F D A]
time 173473ms: Process E switching out of CPU; will block on I/O until time 174766ms [Q H C F D A]
time 173477ms: Process H started using the CPU for 118ms burst [Q C F D A]
time 173595ms: Process H completed a CPU burst; 22 bursts to go [Q C F D A]
time 173595ms: Process H switching out of CPU; will block on I/O until time 173697ms [Q C F D A]
time 173599ms: Process C started using the CPU for 378ms burst [Q F D A]
time 173697ms: Process H completed I/O; added to ready queue [Q F D A H]
time 173977ms: Process C completed a CPU burst; 65 bursts to go [Q F D A H]
time 173977ms: Process C switching out of CPU; will block on I/O until time 174240ms [Q F D A H]
time 173981ms: Process F started using the CPU for 1130ms burst [Q D A H]
time 174240ms: Process C completed I/O; added to ready queue [Q D A H C]
time 174766ms: Process E completed I/O; added to ready queue [Q D A H C E]
time 175111ms: Process F completed a CPU burst; 71 bursts to go [Q D A H C E]
time 175111ms: Process F switching out of CPU; will block on I/O until time 175998ms [Q D A H C E]
time 175115ms: Process D started using the CPU for 1095ms burst [Q A H C E]
time 175998ms: Process F completed I/O; added to ready queue [Q A H C E F]
time 176210ms: Process D completed a CPU burst; 30 bursts to go [Q A H C E F]
time 176210ms: Process D switching out of CPU; will block on I/O until time 178404ms [Q A H C E F]
time 176214ms: Process A started using the CPU with 427ms burst remaining [Q H C E F]
time 176641ms: Process A completed a CPU burst; 55 bursts to go [Q H C E F]
time 176641ms: Process A switching out of CPU; will block on I/O until time 176732ms [Q H C E F]
time 176645ms: Process H started using the CPU for 182ms burst [Q C E F]
time 176732ms: Process A completed I/O; added to ready queue [Q C E F A]
time 176827ms: Process H completed a CPU burst; 21 bursts to go [Q C E F A]
time 176827ms: Process H switching out of CPU; will block on I/O until time 177223ms [Q C E F A]
time 176831ms: Process C started using the CPU for 528ms burst [Q E F A]
time 177223ms: Process H completed I/O; added to ready queue [Q E F A H]
time 177359ms: Process C completed a CPU burst; 64 bursts to go [Q E F A H]
time 177359ms: Process C switching out of CPU; will block on I/O until time 178611ms [Q E F A H]
time 177363ms: Process E started using the CPU for 691ms burst [Q F A H]
time 178054ms: Process E completed a CPU burst; 56 bursts to go [Q F A H]
time 178054ms: Process E switching out of CPU; will block on I/O until time 178788ms [Q F A H]
time 178058ms: Process F started using the CPU for 80ms burst [Q A H]
time 178138ms: Process F completed a CPU burst; 70 bursts to go [Q A H]
time 178138ms: Process F switching out of CPU; will block on I/O until time 179389ms [Q A H]
time 178142ms: Process A started using the CPU for 639ms burst [Q H]
time 178404ms: Process D completed I/O; added to ready queue [Q H D]
time 178611ms: Process C completed I/O; added to ready queue [Q H D C]
time 178781ms: Process A completed a CPU burst; 54 bursts to go [Q H D C]
time 178781ms: Process A switching out of CPU; will block on I/O until time 179425ms [Q H D C]
time 178785ms: Process H started using the CPU for 1827ms burst [Q D C]
time 178788ms: Process E completed I/O; added to ready queue [Q D C E]
time 179389ms: Process F completed I/O; added to ready queue [Q D C E F]
time 179425ms: Process A completed I/O; added to ready queue [Q D C E F A]
time 180612ms: Process H completed a CPU burst; 20 bursts to go [Q D C E F A]
time 180612ms: Process H switching out of CPU; will block on I/O until time 181160ms [Q D C E F A]
time 180616ms: Process D started using the CPU for 24ms burst [Q C E F A]
time 180640ms: Process D completed a CPU burst; 29 bursts to go [Q C E F A]
time 180640ms: Process D switching out of CPU; will block on I/O until time 182652ms [Q C E F A]
time 180644ms: Process C started using the CPU for 3578ms burst [Q E F A]
time 181160ms: Process H completed I/O; added to ready queue [Q E F A H]
time 182652ms: Process D completed I/O; added to ready queue [Q E F A H D]
time 182692ms: Time slice expired; process C preempted with 1530ms to go [Q E F A H D]
time 182696ms: Process E started using the CPU for 98ms burst [Q F A H D C]
time 182794ms: Process E completed a CPU burst; 55 bursts to go [Q F A H D C]
time 182794ms: Process E switching out of CPU; will block on I/O until time 184105ms [Q F A H D C]
time 182798ms: Process F started using the CPU for 239ms burst [Q A H D C]
time 183037ms: Process F completed a CPU burst; 69 bursts to go [Q A H D C]
time 183037ms: Process F switching out of CPU; will block on I/O until time 183087ms [Q A H D C]
time 183041ms: Process A started using the CPU for 2457ms burst [Q H D C]
time 183087ms: Process F completed I/O; added to ready queue [Q H D C F]
time 184105ms: Process E completed I/O; added to ready queue [Q H D C F E]
time 185089ms: Time slice expired; process A preempted with 409ms to go [Q H D C F E]
time 185093ms: Process H started using the CPU for 2ms burst [Q D C F E A]
time 185095ms: Process H completed a CPU burst; 19 bursts to go [Q D C F E A]
time 185095ms: Process H switching out of CPU; will block on I/O until time 186390ms [Q D C F E A]
time 185099ms: Process D started using the CPU for 751ms burst [Q C F E A]
time 185850ms: Process D completed a CPU burst; 28 bursts to go [Q C F E A]
time 185850ms: Process D switching out of CPU; will block on I/O until time 186296ms [Q C F E A]
time 185854ms: Process C started using the CPU with 1530ms burst remaining [Q F E A]
time 186296ms: Process D completed I/O; added to ready queue [Q F E A D]
time 186390ms: Process H completed I/O; added to ready queue [Q F E A D H]
time 187384ms: Process C completed a CPU burst; 63 bursts to go [Q F E A D H]
time 187384ms: Process C switching out of CPU; will block on I/O until time 187586ms [Q F E A D H]
time 187388ms: Process F started using the CPU for 7ms burst [Q E A D H]
time 187395ms: Process F completed a CPU burst; 68 bursts to go [Q E A D H]
time 187395ms: Process F switching out of CPU; will block on I/O until time 187445ms [Q E A D H]
time 187399ms: Process E started using the CPU for 660ms burst [Q A D H]
time 187445ms: Process F completed I/O; added to ready queue [Q A D H F]
time 187586ms: Process C completed I/O; added to ready queue [Q A D H F C]
time 188059ms: Process E completed a CPU burst; 54 bursts to go [Q A D H F C]
time 188059ms: Process E switching out of CPU; will block on I/O until time 190422ms [Q A D H F C]
time 188063ms: Process A started using the CPU with 409ms burst remaining [Q D H F C]
time 188472ms: Process A completed a CPU burst; 53 bursts to go [Q D H F C]
time 188472ms: Process A switching out of CPU; will block on I/O until time 191136ms [Q D H F C]
time 188476ms: Process D started using the CPU for 824ms burst [Q H F C]
time 189300ms: Process D completed a CPU burst; 27 bursts to go [Q H F C]
time 189300ms: Process D switching out of CPU; will block on I/O until time 189326ms [Q H F C]
time 189304ms: Process H started using the CPU for 398ms burst [Q F C]
time 189326ms: Process D completed I/O; added to ready queue [Q F C D]
time 189702ms: Process H completed a CPU burst; 18 bursts to go [Q F C D]
time 189702ms: Process H switching out of CPU; will block on I/O until time 190613ms [Q F C D]
time 189706ms: Process F started using the CPU for 988ms burst [Q C D]
time 190422ms: Process E completed I/O; added to ready queue [Q C D E]
time 190613ms: Process H completed I/O; added to ready queue [Q C D E H]
time 190694ms: Process F completed a CPU burst; 67 bursts to go [Q C D E H]
time 190694ms: Process F switching out of CPU; will block on I/O until time 191034ms [Q C D E H]
time 190698ms: Process C started using the CPU for 551ms burst [Q D E H]
time 191034ms: Process F completed I/O; added to ready queue [Q D E H F]
time 191136ms: Process A completed I/O; added to ready queue [Q D E H F A]
time 191249ms: Process C completed a CPU burst; 62 bursts to go [Q D E H F A]
time 191249ms: Process C switching out of CPU; will block on I/O until time 195124ms [Q D E H F A]
time 191253ms: Process D started using the CPU for 135ms burst [Q E H F A]
time 191388ms: Process D completed a CPU burst; 26 bursts to go [Q E H F A]
time 191388ms: Process D switching out of CPU; will block on I/O until time 193829ms [Q E H F A]
time 191392ms: Process E started using the CPU for 445ms burst [Q H F A]
time 191837ms: Process E completed a CPU burst; 53 bursts to go [Q H F A]
time 191837ms: Process E switching out of CPU; will block on I/O until time 193675ms [Q H F A]
time 191841ms: Process H started using the CPU for 1096ms burst [Q F A]
time 192937ms: Process H completed a CPU burst; 17 bursts to go [Q F A]
time 192937ms: Process H switching out of CPU; will block on I/O until time 196042ms [Q F A]
time 192941ms: Process F started using the CPU for 700ms burst [Q A]
time 193641ms: Process F completed a CPU burst; 66 bursts to go [Q A]
time 193641ms: Process F switching out of CPU; will block on I/O until time 193828ms [Q A]
time 193645ms: Process A started using the CPU for 184ms burst [Q <empty>]
time 193675ms: Process E completed I/O; added to ready queue [Q E]
time 193828ms: Process F completed I/O; added to ready queue [Q E F]
time 193829ms: Process A completed a CPU burst; 52 bursts to go [Q E F]
time 193829ms: Process A switching out of CPU; will block on I/O until time 194579ms [Q E F]
time 193829ms: Process D completed I/O; added to ready queue [Q E F D]
time 193833ms: Process E started using the CPU for 458ms burst [Q F D]
time 194291ms: Process E completed a CPU burst; 52 bursts to go [Q F D]
time 194291ms: Process E switching out of CPU; will block on I/O until time 195852ms [Q F D]
time 194295ms: Process F started using the CPU for 409ms burst [Q D]
time 194579ms: Process A completed I/O; added to ready queue [Q D A]
time 194704ms: Process F completed a CPU burst; 65 bursts to go [Q D A]
time 194704ms: Process F switching out of CPU; will block on I/O until time 194966ms [Q D A]
time 194708ms: Process D started using the CPU for 760ms burst [Q A]
time 194966ms: Process F completed I/O; added to ready queue [Q A F]
time 195124ms: Process C completed I/O; added to ready queue [Q A F C]
time 195468ms: Process D completed a CPU burst; 25 bursts to go [Q A F C]
time 195468ms: Process D switching out of CPU; will block on I/O until time 195495ms [Q A F C]
time 195472ms: Process A started using the CPU for 141ms burst [Q F C]
time 195495ms: Process D completed I/O; added to ready queue [Q F C D]
time 195613ms: Process A completed a CPU burst; 51 bursts to go [Q F C D]
time 195613ms: Process A switching out of CPU; will block on I/O until time 195899ms [Q F C D]
time 195617ms: Process F started using the CPU for 1355ms burst [Q C D]
time 195852ms: Process E completed I/O; added to ready queue [Q C D E]
time 195899ms: Process A completed I/O; added to ready queue [Q C D E A]
time 196042ms: Process H completed I/O; added to ready queue [Q C D E A H]
time 196972ms: Process F completed a CPU burst; 64 bursts to go [Q C D E A H]
time 196972ms: Process F switching out of CPU; will block on I/O until time 197487ms [Q C D E A H]
time 196976ms: Process C started using the CPU for 34ms burst [Q D E A H]
time 197010ms: Process C completed a CPU burst; 61 bursts to go [Q D E A H]
time 197010ms: Process C switching out of CPU; will block on I/O until time 197088ms [Q D E A H]
time 197014ms: Process D started using the CPU for 1466ms burst [Q E A H]
time 197088ms: Process C completed I/O; added to ready queue [Q E A H C]
time 197487ms: Process F completed I/O; added to ready queue [Q E A H C F]
time 198480ms: Process D completed a CPU burst; 24 bursts to go [Q E A H C F]
time 198480ms: Process D switching out of CPU; will block on I/O until time 198538ms [Q E A H C F]
time 198484ms: Process E started using the CPU for 170ms burst [Q A H C F]
time 198538ms: Process D completed I/O; added to ready queue [Q A H C F D]
time 198654ms: Process E completed a CPU burst; 51 bursts to go [Q A H C F D]
time 198654ms: Process E switching out of CPU; will block on I/O until time 198906ms [Q A H C F D]
time 198658ms: Process A started using the CPU for 2915ms burst [Q H C F D]
time 198906ms: Process E completed I/O; added to ready queue [Q H C F D E]
time 200706ms: Time slice expired; process A preempted with 867ms to go [Q H C F D E]
time 200710ms: Process H started using the CPU for 286ms burst [Q C F D E A]
time 200996ms: Process H completed a CPU burst; 16 bursts to go [Q C F D E A]
time 200996ms: Process H switching out of CPU; will block on I/O until time 201137ms [Q C F D E A]
time 201000ms: Process C started using the CPU for 2618ms burst [Q F D E A]
time 201137ms: Process H completed I/O; added to ready queue [Q F D E A H]
time 203048ms: Time slice expired; process C preempted with 570ms to go [Q F D E A H]
time 203052ms: Process F started using the CPU for 196ms burst [Q D E A H C]
time 203248ms: Process F completed a CPU burst; 63 bursts to go [Q D E A H C]
time 203248ms: Process F switching out of CPU; will block on I/O until time 203445ms [Q D E A H C]
time 203252ms: Process D started using the CPU for 1071ms burst [Q E A H C]
time 203445ms: Process F completed I/O; added to ready queue [Q E A H C F]
time 204323ms: Process D completed a CPU burst; 23 bursts to go [Q E A H C F]
time 204323ms: Process D switching out of CPU; will block on I/O until time 205563ms [Q E A H C F]
time 204327ms: Process E started using the CPU for 774ms burst [Q A H C F]
time 205101ms: Process E completed a CPU burst; 50 bursts to go [Q A H C F]
time 205101ms: Process E switching out of CPU; will block on I/O until time 207236ms [Q A H C F]
time 205105ms: Process A started using the CPU with 867ms burst remaining [Q H C F]
time 205563ms: Process D completed I/O; added to ready queue [Q H C F D]
time 205972ms: Process A completed a CPU burst; 50 bursts to go [Q H C F D]
time 205972ms: Process A switching out of CPU; will block on I/O until time 206499ms [Q H C F D]
time 205976ms: Process H started using the CPU for 1908ms burst [Q C F D]
time 206499ms: Process A completed I/O; added to ready queue [Q C F D A]
time 207236ms: Process E completed I/O; added to ready queue [Q C F D A E]
time 207884ms: Process H completed a CPU burst; 15 bursts to go [Q C F D A E]
time 207884ms: Process H switching out of CPU; will block on I/O until time 209846ms [Q C F D A E]
time 207888ms: Process C started using the CPU with 570ms burst remaining [Q F D A E]
time 208458ms: Process C completed a CPU burst; 60 bursts to go [Q F D A E]
time 208458ms: Process C switching out of CPU; will block on I/O until time 209307ms [Q F D A E]
time 208462ms: Process F started using the CPU for 1736ms burst [Q D A E]
time 209307ms: Process C completed I/O; added to ready queue [Q D A E C]
time 209846ms: Process H completed I/O; added to ready queue [Q D A E C H]
time 210198ms: Process F completed a CPU burst; 62 bursts to go [Q D A E C H]
time 210198ms: Process F switching out of CPU; will block on I/O until time 211641ms [Q D A E C H]
time 210202ms: Process D started using the CPU for 75ms burst [Q A E C H]
time 210277ms: Process D completed a CPU burst; 22 bursts to go [Q A E C H]
time 210277ms: Process D switching out of CPU; will block on I/O until time 212685ms [Q A E C H]
time 210281ms: Process A started using the CPU for 541ms burst [Q E C H]
time 210822ms: Process A completed a CPU burst; 49 bursts to go [Q E C H]
time 210822ms: Process A switching out of CPU; will block on I/O until time 212317ms [Q E C H]
time 210826ms: Process E started using the CPU for 365ms burst [Q C H]
time 211191ms: Process E completed a CPU burst; 49 bursts to go [Q C H]
time 211191ms: Process E switching out of CPU; will block on I/O until time 212177ms [Q C H]
time 211195ms: Process C started using the CPU for 805ms burst [Q H]
time 211641ms: Process F completed I/O; added to ready queue [Q H F]
time 212000ms: Process C completed a CPU burst; 59 bursts to go [Q H F]
time 212000ms: Process C switching out of CPU; will block on I/O until time 213054ms [Q H F]
time 212004ms: Process H started using the CPU for 3276ms burst [Q F]
time 212177ms: Process E completed I/O; added to ready queue [Q F E]
time 212317ms: Process A completed I/O; added to ready queue [Q F E A]
time 212685ms: Process D completed I/O; added to ready queue [Q F E A D]
time 213054ms: Process C completed I/O; added to ready queue [Q F E A D C]
time 214052ms: Time slice expired; process H preempted with 1228ms to go [Q F E A D C]
time 214056ms: Process F started using the CPU for 114ms burst [Q E A D C H]
time 214170ms: Process F completed a CPU burst; 61 bursts to go [Q E A D C H]
time 214170ms: Process F switching out of CPU; will block on I/O until time 215064ms [Q E A D C H]
time 214174ms: Process E started using the CPU for 16ms burst [Q A D C H]
time 214190ms: Process E completed a CPU burst; 48 bursts to go [Q A D C H]
time 214190ms: Process E switching out of CPU; will block on I/O until time 214402ms [Q A D C H]
time 214194ms: Process A started using the CPU for 65ms burst [Q D C H]
time 214259ms: Process A completed a CPU burst; 48 bursts to go [Q D C H]
time 214259ms: Process A switching out of CPU; will block on I/O until time 215800ms [Q D C H]
time 214263ms: Process D started using the CPU for 492ms burst [Q C H]
time 214402ms: Process E completed I/O; added to ready queue [Q C H E]
time 214755ms: Process D completed a CPU burst; 21 bursts to go [Q C H E]
time 214755ms: Process D switching out of CPU; will block on I/O until time 217054ms [Q C H E]
time 214759ms: Process C started using the CPU for 648ms burst [Q H E]
time 215064ms: Process F completed I/O; added to ready queue [Q H E F]
time 215407ms: Process C completed a CPU burst; 58 bursts to go [Q H E F]
time 215407ms: Process C switching out of CPU; will block on I/O until time 215513ms [Q H E F]
time 215411ms: Process H started using the CPU with 1228ms burst remaining [Q E F]
time 215513ms: Process C completed I/O; added to ready queue [Q E F C]
time 215800ms: Process A completed I/O; added to ready queue [Q E F C A]
time 216639ms: Process H completed a CPU burst; 14 bursts to go [Q E F C A]
time 216639ms: Process H switching out of CPU; will block on I/O until time 216895ms [Q E F C A]
time 216643ms: Process E started using the CPU for 800ms burst [Q F C A]
time 216895ms: Process H completed I/O; added to ready queue [Q F C A H]
time 217054ms: Process D completed I/O; added to ready queue [Q F C A H D]
time 217443ms: Process E completed a CPU burst; 47 bursts to go [Q F C A H D]
time 217443ms: Process E switching out of CPU; will block on I/O until time 218093ms [Q F C A H D]
time 217447ms: Process F started using the CPU for 577ms burst [Q C A H D]
time 218024ms: Process F completed a CPU burst; 60 bursts to go [Q C A H D]
time 218024ms: Process F switching out of CPU; will block on I/O until time 219607ms [Q C A H D]
time 218028ms: Process C started using the CPU for 837ms burst [Q A H D]
time 218093ms: Process E completed I/O; added to ready queue [Q A H D E]
time 218865ms: Process C completed a CPU burst; 57 bursts to go [Q A H D E]
time 218865ms: Process C switching out of CPU; will block on I/O until time 219442ms [Q A H D E]
time 218869ms: Process A started using the CPU for 1213ms burst [Q H D E]
time 219442ms: Process C completed I/O; added to ready queue [Q H D E C]
time 219607ms: Process F completed I/O; added to ready queue [Q H D E C F]
time 220082ms: Process A completed a CPU burst; 47 bursts to go [Q H D E C F]
time 220082ms: Process A switching out of CPU; will block on I/O until time 221516ms [Q H D E C F]
time 220086ms: Process H started using the CPU for 1008ms burst [Q D E C F]
time 221094ms: Process H completed a CPU burst; 13 bursts to go [Q D E C F]
time 221094ms: Process H switching out of CPU; will block on I/O until time 221115ms [Q D E C F]
time 221098ms: Process D started using the CPU for 22ms burst [Q E C F]
time 221115ms: Process H completed I/O; added to ready queue [Q E C F H]
time 221120ms: Process D completed a CPU burst; 20 bursts to go [Q E C F H]
time 221120ms: Process D switching out of CPU; will block on I/O until time 221954ms [Q E C F H]
time 221124ms: Process E started using the CPU for 520ms burst [Q C F H]
time 221516ms: Process A completed I/O; added to ready queue [Q C F H A]
time 221644ms: Process E completed a CPU burst; 46 bursts to go [Q C F H A]
time 221644ms: Process E switching out of CPU; will block on I/O until time 223162ms [Q C F H A]
time 221648ms: Process C started using the CPU for 115ms burst [Q F H A]
time 221763ms: Process C completed a CPU burst; 56 bursts to go [Q F H A]
time 221763ms: Process C switching out of CPU; will block on I/O until time 221943ms [Q F H A]
time 221767ms: Process F started using the CPU for 986ms burst [Q H A]
time 221943ms: Process C completed I/O; added to ready queue [Q H A C]
time 221954ms: Process D completed I/O; added to ready queue [Q H A C D]
time 222753ms: Process F completed a CPU burst; 59 bursts to go [Q H A C D]
time 222753ms: Process F switching out of CPU; will block on I/O until time 223794ms [Q H A C D]
time 222757ms: Process H started using the CPU for 3004ms burst [Q A C D]
time 223162ms: Process E completed I/O; added to ready queue [Q A C D E]
time 223794ms: Process F completed I/O; added to ready queue [Q A C D E F]
time 224805ms: Time slice expired; process H preempted with 956ms to go [Q A C D E F]
time 224809ms: Process A started using the CPU for 676ms burst [Q C D E F H]
time 225485ms: Process A completed a CPU burst; 46 bursts to go [Q C D E F H]
time 225485ms: Process A switching out of CPU; will block on I/O until time 225536ms [Q C D E F H]
time 225489ms: Process C started using the CPU for 352ms burst [Q D E F H]
time 225536ms: Process A completed I/O; added to ready queue [Q D E F H A]
time 225841ms: Process C completed a CPU burst; 55 bursts to go [Q D E F H A]
time 225841ms: Process C switching out of CPU; will block on I/O until time 225935ms [Q D E F H A]
time 225845ms: Process D started using the CPU for 435ms burst [Q E F H A]
time 225935ms: Process C completed I/O; added to ready queue [Q E F H A C]
time 226280ms: Process D completed a CPU burst; 19 bursts to go [Q E F H A C]
time 226280ms: Process D switching out of CPU; will block on I/O until time 226379ms [Q E F H A C]
time 226284ms: Process E started using the CPU for 284ms burst [Q F H A C]
time 226379ms: Process D completed I/O; added to ready queue [Q F H A C D]
time 226568ms: Process E completed a CPU burst; 45 bursts to go [Q F H A C D]
time 226568ms: Process E switching out of CPU; will block on I/O until time 226828ms [Q F H A C D]
time 226572ms: Process F started using the CPU for 37ms burst [Q H A C D]
time 226609ms: Process F completed a CPU burst; 58 bursts to go [Q H A C D]
time 226609ms: Process F switching out of CPU; will block on I/O until time 227361ms [Q H A C D]
time 226613ms: Process H started using the CPU with 956ms burst remaining [Q A C D]
time 226828ms: Process E completed I/O; added to ready queue [Q A C D E]
time 227361ms: Process F completed I/O; added to ready queue [Q A C D E F]
time 227569ms: Process H completed a CPU burst; 12 bursts to go [Q A C D E F]
time 227569ms: Process H switching out of CPU; will block on I/O until time 227759ms [Q A C D E F]
time 227573ms: Process A started using the CPU for 1128ms burst [Q C D E F]
time 227759ms: Process H completed I/O; added to ready queue [Q C D E F H]
time 228701ms: Process A completed a CPU burst; 45 bursts to go [Q C D E F H]
time 228701ms: Process A switching out of CPU; will block on I/O until time 228880ms [Q C D E F H]
time 228705ms: Process C started using the CPU for 2564ms burst [Q D E F H]
time 228880ms: Process A completed I/O; added to ready queue [Q D E F H A]
time 230753ms: Time slice expired; process C preempted with 516ms to go [Q D E F H A]
time 230757ms: Process D started using the CPU for 2552ms burst [Q E F H A C]
time 232805ms: Time slice expired; process D preempted with 504ms to go [Q E F H A C]
time 232809ms: Process E started using the CPU for 2021ms burst [Q F H A C D]
time 234830ms: Process E completed a CPU burst; 44 bursts to go [Q F H A C D]
time 234830ms: Process E switching out of CPU; will block on I/O until time 237945ms [Q F H A C D]
time 234834ms: Process F started using the CPU for 174ms burst [Q H A C D]
time 235008ms: Process F completed a CPU burst; 57 bursts to go [Q H A C D]
time 235008ms: Process F switching out of CPU; will block on I/O until time 235528ms [Q H A C D]
time 235012ms: Process H started using the CPU for 1207ms burst [Q A C D]
time 235528ms: Process F completed I/O; added to ready queue [Q A C D F]
time 236219ms: Process H completed a CPU burst; 11 bursts to go [Q A C D F]
time 236219ms: Process H switching out of CPU; will block on I/O until time 237311ms [Q A C D F]
time 236223ms: Process A started using the CPU for 229ms burst [Q C D F]
time 236452ms: Process A completed a CPU burst; 44 bursts to go [Q C D F]
time 236452ms: Process A switching out of CPU; will block on I/O until time 236466ms [Q C D F]
time 236456ms: Process C started using the CPU with 516ms burst remaining [Q D F]
time 236466ms: Process A completed I/O; added to ready queue [Q D F A]
time 236972ms: Process C completed a CPU burst; 54 bursts to go [Q D F A]
time 236972ms: Process C switching out of CPU; will block on I/O until time 237016ms [Q D F A]
time 236976ms: Process D started using the CPU with 504ms burst remaining [Q F A]
time 237016ms: Process C completed I/O; added to ready queue [Q F A C]
time 237311ms: Process H completed I/O; added to ready queue [Q F A C H]
time 237480ms: Process D completed a CPU burst; 18 bursts to go [Q F A C H]
time 237480ms: Process D switching out of CPU; will block on I/O until time 238052ms [Q F A C H]
time 237484ms: Process F started using the CPU for 77ms burst [Q A C H]
time 237561ms: Process F completed a CPU burst; 56 bursts to go [Q A C H]
time 237561ms: Process F switching out of CPU; will block on I/O until time 239649ms [Q A C H]
time 237565ms: Process A started using the CPU for 390ms burst [Q C H]
time 237945ms: Process E completed I/O; added to ready queue [Q C H E]
time 237955ms: Process A completed a CPU burst; 43 bursts to go [Q C H E]
time 237955ms: Process A switching out of CPU; will block on I/O until time 239825ms [Q C H E]
time 237959ms: Process C started using the CPU for 1370ms burst [Q H E]
time 238052ms: Process D completed I/O; added to ready queue [Q H E D]
time 239329ms: Process C completed a CPU burst; 53 bursts to go [Q H E D]
time 239329ms: Process C switching out of CPU; will block on I/O until time 239396ms [Q H E D]
time 239333ms: Process H started using the CPU for 424ms burst [Q E D]
time 239396ms: Process C completed I/O; added to ready queue [Q E D C]
time 239649ms: Process F completed I/O; added to ready queue [Q E D C F]
time 239757ms: Process H completed a CPU burst; 10 bursts to go [Q E D C F]
time 239757ms: Process H switching out of CPU; will block on I/O until time 240114ms [Q E D C F]
time 239761ms: Process E started using the CPU for 329ms burst [Q D C F]
time 239825ms: Process A completed I/O; added to ready queue [Q D C F A]
time 240090ms: Process E completed a CPU burst; 43 bursts to go [Q D C F A]
time 240090ms: Process E switching out of CPU; will block on I/O until time 240281ms [Q D C F A]
time 240094ms: Process D started using the CPU for 851ms burst [Q C F A]
time 240114ms: Process H completed I/O; added to ready queue [Q C F A H]
time 240281ms: Process E completed I/O; added to ready queue [Q C F A H E]
time 240945ms: Process D completed a CPU burst; 17 bursts to go [Q C F A H E]
time 240945ms: Process D switching out of CPU; will block on I/O until time 241257ms [Q C F A H E]
time 240949ms: Process C started using the CPU for 204ms burst [Q F A H E]
time 241153ms: Process C completed a CPU burst; 52 bursts to go [Q F A H E]
time 241153ms: Process C switching out of CPU; will block on I/O until time 241586ms [Q F A H E]
time 241157ms: Process F started using the CPU for 2081ms burst [Q A H E]
time 241257ms: Process D completed I/O; added to ready queue [Q A H E D]
time 241586ms: Process C completed I/O; added to ready queue [Q A H E D C]
time 243205ms: Time slice expired; process F preempted with 33ms to go [Q A H E D C]
time 243209ms: Process A started using the CPU for 905ms burst [Q H E D C F]
time 244114ms: Process A completed a CPU burst; 42 bursts to go [Q H E D C F]
time 244114ms: Process A switching out of CPU; will block on I/O until time 244502ms [Q H E D C F]
time 244118ms: Process H started using the CPU for 1359ms burst [Q E D C F]
time 244502ms: Process A completed I/O; added to ready queue [Q E D C F A]
time 245477ms: Process H completed a CPU burst; 9 bursts to go [Q E D C F A]
time 245477ms: Process H switching out of CPU; will block on I/O until time 245748ms [Q E D C F A]
time 245481ms: Process E started using the CPU for 654ms burst [Q D C F A]
time 245748ms: Process H completed I/O; added to ready queue [Q D C F A H]
time 246135ms: Process E completed a CPU burst; 42 bursts to go [Q D C F A H]
time 246135ms: Process E switching out of CPU; will block on I/O until time 247021ms [Q D C F A H]
time 246139ms: Process D started using the CPU for 742ms burst [Q C F A H]
time 246881ms: Process D completed a CPU burst; 16 bursts to go [Q C F A H]
time 246881ms: Process D switching out of CPU; will block on I/O until time 247137ms [Q C F A H]
time 246885ms: Process C started using the CPU for 190ms burst [Q F A H]
time 247021ms: Process E completed I/O; added to ready queue [Q F A H E]
time 247075ms: Process C completed a CPU burst; 51 bursts to go [Q F A H E]
time 247075ms: Process C switching out of CPU; will block on I/O until time 247578ms [Q F A H E]
time 247079ms: Process F started using the CPU with 33ms burst remaining [Q A H E]
time 247112ms: Process F completed a CPU burst; 55 bursts to go [Q A H E]
time 247112ms: Process F switching out of CPU; will block on I/O until time 248067ms [Q A H E]
time 247116ms: Process A started using the CPU for 118ms burst [Q H E]
time 247137ms: Process D completed I/O; added to ready queue [Q H E D]
time 247234ms: Process A completed a CPU burst; 41 bursts to go [Q H E D]
time 247234ms: Process A switching out of CPU; will block on I/O until time 247302ms [Q H E D]
time 247238ms: Process H started using the CPU for 1357ms burst [Q E D]
time 247302ms: Process A completed I/O; added to ready queue [Q E D A]
time 247578ms: Process C completed I/O; added to ready queue [Q E D A C]
time 248067ms: Process F completed I/O; added to ready queue [Q E D A C F]
time 248595ms: Process H completed a CPU burst; 8 bursts to go [Q E D A C F]
time 248595ms: Process H switching out of CPU; will block on I/O until time 248655ms [Q E D A C F]
time 248599ms: Process E started using the CPU for 539ms burst [Q D A C F]
time 248655ms: Process H completed I/O; added to ready queue [Q D A C F H]
time 249138ms: Process E completed a CPU burst; 41 bursts to go [Q D A C F H]
time 249138ms: Process E switching out of CPU; will block on I/O until time 250697ms [Q D A C F H]
time 249142ms: Process D started using the CPU for 2764ms burst [Q A C F H]
time 250697ms: Process E completed I/O; added to ready queue [Q A C F H E]
time 251190ms: Time slice expired; process D preempted with 716ms to go [Q A C F H E]
time 251194ms: Process A started using the CPU for 179ms burst [Q C F H E D]
time 251373ms: Process A completed a CPU burst; 40 bursts to go [Q C F H E D]
time 251373ms: Process A switching out of CPU; will block on I/O until time 253565ms [Q C F H E D]
time 251377ms: Process C started using the CPU for 306ms burst [Q F H E D]
time 251683ms: Process C completed a CPU burst; 50 bursts to go [Q F H E D]
time 251683ms: Process C switching out of CPU; will block on I/O until time 253154ms [Q F H E D]
time 251687ms: Process F started using the CPU for 745ms burst [Q H E D]
time 252432ms: Process F completed a CPU burst; 54 bursts to go [Q H E D]
time 252432ms: Process F switching out of CPU; will block on I/O until time 252493ms [Q H E D]
time 252436ms: Process H started using the CPU for 144ms burst [Q E D]
time 252493ms: Process F completed I/O; added to ready queue [Q E D F]
time 252580ms: Process H completed a CPU burst; 7 bursts to go [Q E D F]
time 252580ms: Process H switching out of CPU; will block on I/O until time 252664ms [Q E D F]
time 252584ms: Process E started using the CPU for 1801ms burst [Q D F]
time 252664ms: Process H completed I/O; added to ready queue [Q D F H]
time 253154ms: Process C completed I/O; added to ready queue [Q D F H C]
time 253565ms: Process A completed I/O; added to ready queue [Q D F H C A]
time 254385ms: Process E completed a CPU burst; 40 bursts to go [Q D F H C A]
time 254385ms: Process E switching out of CPU; will block on I/O until time 257007ms [Q D F H C A]
time 254389ms: Process D started using the CPU with 716ms burst remaining [Q F H C A]
time 255105ms: Process D completed a CPU burst; 15 bursts to go [Q F H C A]
time 255105ms: Process D switching out of CPU; will block on I/O until time 256652ms [Q F H C A]
time 255109ms: Process F started using the CPU for 1011ms burst [Q H C A]
time 256120ms: Process F completed a CPU burst; 53 bursts to go [Q H C A]
time 256120ms: Process F switching out of CPU; will block on I/O until time 256464ms [Q H C A]
time 256124ms: Process H started using the CPU for 2541ms burst [Q C A]
time 256464ms: Process F completed I/O; added to ready queue [Q C A F]
time 256652ms: Process D completed I/O; added to ready queue [Q C A F D]
time 257007ms: Process E completed I/O; added to ready queue [Q C A F D E]
time 258172ms: Time slice expired; process H preempted with 493ms to go [Q C A F D E]
time 258176ms: Process C started using the CPU for 7ms burst [Q A F D E H]
time 258183ms: Process C completed a CPU burst; 49 bursts to go [Q A F D E H]
time 258183ms: Process C switching out of CPU; will block on I/O until time 258245ms [Q A F D E H]
time 258187ms: Process A started using the CPU for 513ms burst [Q F D E H]
time 258245ms: Process C completed I/O; added to ready queue [Q F D E H C]
time 258700ms: Process A completed a CPU burst; 39 bursts to go [Q F D E H C]
time 258700ms: Process A switching out of CPU; will block on I/O until time 259015ms [Q F D E H C]
time 258704ms: Process F started using the CPU for 1577ms burst [Q D E H C]
time 259015ms: Process A completed I/O; added to ready queue [Q D E H C A]
time 260281ms: Process F completed a CPU burst; 52 bursts to go [Q D E H C A]
time 260281ms: Process F switching out of CPU; will block on I/O until time 260583ms [Q D E H C A]
time 260285ms: Process D started using the CPU for 4ms burst [Q E H C A]
time 260289ms: Process D completed a CPU burst; 14 bursts to go [Q E H C A]
time 260289ms: Process D switching out of CPU; will block on I/O until time 261348ms [Q E H C A]
time 260293ms: Process E started using the CPU for 343ms burst [Q H C A]
time 260583ms: Process F completed I/O; added to ready queue [Q H C A F]
time 260636ms: Process E completed a CPU burst; 39 bursts to go [Q H C A F]
time 260636ms: Process E switching out of CPU; will block on I/O until time 260949ms [Q H C A F]
time 260640ms: Process H started using the CPU with 493ms burst remaining [Q C A F]
time 260949ms: Process E completed I/O; added to ready queue [Q C A F E]
time 261133ms: Process H completed a CPU burst; 6 bursts to go [Q C A F E]
time 261133ms: Process H switching out of CPU; will block on I/O until time 261990ms [Q C A F E]
time 261137ms: Process C started using the CPU for 37ms burst [Q A F E]
time 261174ms: Process C completed a CPU burst; 48 bursts to go [Q A F E]
time 261174ms: Process C switching out of CPU; will block on I/O until time 262822ms [Q A F E]
time 261178ms: Process A started using the CPU for 469ms burst [Q F E]
time 261348ms: Process D completed I/O; added to ready queue [Q F E D]
time 261647ms: Process A completed a CPU burst; 38 bursts to go [Q F E D]
time 261647ms: Process A switching out of CPU; will block on I/O until time 261865ms [Q F E D]
time 261651ms: Process F started using the CPU for 70ms burst [Q E D]
time 261721ms: Process F completed a CPU burst; 51 bursts to go [Q E D]
time 261721ms: Process F switching out of CPU; will block on I/O until time 262203ms [Q E D]
time 261725ms: Process E started using the CPU for 141ms burst [Q D]
time 261865ms: Process A completed I/O; added to ready queue [Q D A]
time 261866ms: Process E completed a CPU burst; 38 bursts to go [Q D A]
time 261866ms: Process E switching out of CPU; will block on I/O until time 264189ms [Q D A]
time 261870ms: Process D started using the CPU for 1008ms burst [Q A]
time 261990ms: Process H completed I/O; added to ready queue [Q A H]
time 262203ms: Process F completed I/O; added to ready queue [Q A H F]
time 262822ms: Process C completed I/O; added to ready queue [Q A H F C]
time 262878ms: Process D completed a CPU burst; 13 bursts to go [Q A H F C]
time 262878ms: Process D switching out of CPU; will block on I/O until time 263028ms [Q A H F C]
time 262882ms: Process A started using the CPU for 2254ms burst [Q H F C]
time 263028ms: Process D completed I/O; added to ready queue [Q H F C D]
time 264189ms: Process E completed I/O; added to ready queue [Q H F C D E]
time 264930ms: Time slice expired; process A preempted with 206ms to go [Q H F C D E]
time 264934ms: Process H started using the CPU for 6ms burst [Q F C D E A]
time 264940ms: Process H completed a CPU burst; 5 bursts to go [Q F C D E A]
time 264940ms: Process H switching out of CPU; will block on I/O until time 265557ms [Q F C D E A]
time 264944ms: Process F started using the CPU for 755ms burst [Q C D E A]
time 265557ms: Process H completed I/O; added to ready queue [Q C D E A H]
time 265699ms: Process F completed a CPU burst; 50 bursts to go [Q C D E A H]
time 265699ms: Process F switching out of CPU; will block on I/O until time 265999ms [Q C D E A H]
time 265703ms: Process C started using the CPU for 311ms burst [Q D E A H]
time 265999ms: Process F completed I/O; added to ready queue [Q D E A H F]
time 266014ms: Process C completed a CPU burst; 47 bursts to go [Q D E A H F]
time 266014ms: Process C switching out of CPU; will block on I/O until time 266661ms [Q D E A H F]
time 266018ms: Process D started using the CPU for 802ms burst [Q E A H F]
time 266661ms: Process C completed I/O; added to ready queue [Q E A H F C]
time 266820ms: Process D completed a CPU burst; 12 bursts to go [Q E A H F C]
time 266820ms: Process D switching out of CPU; will block on I/O until time 267577ms [Q E A H F C]
time 266824ms: Process E started using the CPU for 616ms burst [Q A H F C]
time 267440ms: Process E completed a CPU burst; 37 bursts to go [Q A H F C]
time 267440ms: Process E switching out of CPU; will block on I/O until time 267883ms [Q A H F C]
time 267444ms: Process A started using the CPU with 206ms burst remaining [Q H F C]
time 267577ms: Process D completed I/O; added to ready queue [Q H F C D]
time 267650ms: Process A completed a CPU burst; 37 bursts to go [Q H F C D]
time 267650ms: Process A switching out of CPU; will block on I/O until time 269114ms [Q H F C D]
time 267654ms: Process H started using the CPU for 44ms burst [Q F C D]
time 267698ms: Process H completed a CPU burst; 4 bursts to go [Q F C D]
time 267698ms: Process H switching out of CPU; will block on I/O until time 268276ms [Q F C D]
time 267702ms: Process F started using the CPU for 3504ms burst [Q C D]
time 267883ms: Process E completed I/O; added to ready queue [Q C D E]
time 268276ms: Process H completed I/O; added to ready queue [Q C D E H]
time 269114ms: Process A completed I/O; added to ready queue [Q C D E H A]
time 269750ms: Time slice expired; process F preempted with 1456ms to go [Q C D E H A]
time 269754ms: Process C started using the CPU for 601ms burst [Q D E H A F]
time 270355ms: Process C completed a CPU burst; 46 bursts to go [Q D E H A F]
